<?xml version="1.0" encoding="utf-8"?>
<!-- =================================================================================== -->
<!-- |    This document was autogenerated by xacro from shell_robot.urdf.xacro         | -->
<!-- |    EDITING THIS FILE BY HAND IS NOT RECOMMENDED                                 | -->
<!-- =================================================================================== -->
<robot name="shell_robot">
  <!-- **************************************************************************************************************************************** -->
  <!-- ******* ADAPTIVE CONSTANTS ******* -->
  <!-- **************************************************************************************************************************************** -->
  <!-- **************************************************************************************************************************************** -->
  <!-- ******* phisics proprieties ******* -->
  <!--inertia-->
  <!-- **************************************************************************************************************************************** -->
  <!-- ******* DH proprieties ******* -->
  <!-- **************************************************************************************************************************************** -->
  <leg prefix="prefix leg_B"/>
  <!-- **************************************************************************************************************************************** -->
  <!-- ******* ADAPTIVE CONSTANTS ******* -->
  <!-- **************************************************************************************************************************************** -->
  <!-- **************************************************************************************************************************************** -->
  <!-- ******* phisics proprieties ******* -->
  <!--inertia-->
  <leg prefix="prefix leg_U"/>
  <!-- **************************************************************************************************************************************** -->
  <!-- ******* ADAPTIVE CONSTANTS ******* -->
  <!-- **************************************************************************************************************************************** -->
  <!-- **************************************************************************************************************************************** -->
  <!-- ******* phisics proprieties ******* -->
  <!--inertia-->
  <!-- **************************************************************************************************************************************** -->
  <!-- ******* BASE LINK AND JOINTS ******* -->
  <!-- **************************************************************************************************************************************** -->
  <!--***fixed joints***-->
  <!--world joint
    <joint name="world_joint" type="fixed">
    <parent link="world"/>
    <child link="base_link"/>
    <origin rpy="0.0 0.0 0.0" xyz="0.0 0.0 0.0"/>
  </joint>  -->
  <!--from map to robot-->
  <joint name="to_robot" type="fixed">
    <parent link="map"/>
    <child link="base_link"/>
    <origin rpy="0 0 0" xyz="0 0 0.14"/>
    <dynamics damping="7.0" friction="1000"/>
  </joint>
  <!--base to bottom joint-->
  <joint name="bottom_joint" type="fixed">
    <parent link="base_link"/>
    <child link="bottom_chassis"/>
    <origin rpy="0 0 0" xyz="0 0 -0.06"/>
    <dynamics damping="7.0" friction="1000"/>
    <!--limit effort="0" velocity="0.0" upper="0.0001" lower ="-0.0001" /-->
  </joint>
  <!--base to upper joint-->
  <joint name="upper_joint" type="fixed">
    <parent link="base_link"/>
    <child link="upper_chassis"/>
    <origin rpy="0 0 0" xyz="0 0 0.06"/>
    <dynamics damping="7.0" friction="1000"/>
    <!--limit effort="0" velocity="0.0" upper="0.0001" lower ="-0.0001" /-->
  </joint>
  <!--MAP LINK-->
  <link name="map">
    <selfCollide>1</selfCollide>
    <surface>
      <contact>
        <poissons_ratio>0.347</poissons_ratio>
        <elastic_modulus>8.8e+09</elastic_modulus>
        <ode>
          <soft_cfm>0.01</soft_cfm>
          <soft_erp>0.3</soft_erp>
          <kp>1000</kp>
          <kp>1000</kp>
          <kd>10</kd>
          <max_vel>10.0</max_vel>
          <min_depth>0.1</min_depth>
        </ode>
      </contact>
    </surface>
  </link>
  <!--BASE LINKS-->
  <link name="base_link">
    <pose>0 0 0 0 0 0</pose>
    <selfCollide>1</selfCollide>
    <inertial>
      <mass value="0.8"/>
      <origin rpy="0 0 0" xyz="0 0 0"/>
      <inertia ixx="0.0200016666667" ixy="0.01" ixz="0.01" iyy="0.0200016666667" iyz="0.01" izz="0.0200016666667"/>
    </inertial>
    <collision name="base_link">
      <geometry>
        <cylinder length="0.005" radius="0.1"/>
      </geometry>
      <surface>
        <contact>
          <poissons_ratio>0.347</poissons_ratio>
          <elastic_modulus>8.8e+09</elastic_modulus>
          <ode>
            <soft_cfm>0.0001</soft_cfm>
            <soft_erp>0.3</soft_erp>
            <kp>1000</kp>
            <kp>1000</kp>
            <kd>10</kd>
            <max_vel>10.0</max_vel>
            <min_depth>0.1</min_depth>
          </ode>
        </contact>
      </surface>
    </collision>
    <visual>
      <origin rpy="0 0 0" xyz="0 0 0"/>
      <geometry>
        <cylinder length="0.005" radius="0.1"/>
      </geometry>
    </visual>
  </link>
  <!--chassis robot upper link-->
  <link name="upper_chassis">
    <pose>0 0 0 0 0 0</pose>
    <selfCollide>1</selfCollide>
    <inertial>
      <mass value="0.8"/>
      <origin rpy="0 0 0" xyz="0 0 0"/>
      <inertia ixx="0.0200016666667" ixy="0.01" ixz="0.01" iyy="0.0200016666667" iyz="0.01" izz="0.0200016666667"/>
    </inertial>
    <collision name="upper_chassis">
      <geometry>
        <cylinder length="0.005" radius="0.1"/>
      </geometry>
      <surface>
        <contact>
          <poissons_ratio>0.347</poissons_ratio>
          <elastic_modulus>8.8e+09</elastic_modulus>
          <ode>
            <soft_cfm>0.001</soft_cfm>
            <soft_erp>0.3</soft_erp>
            <kp>1000</kp>
            <kp>1000</kp>
            <kd>10</kd>
            <max_vel>10.0</max_vel>
            <min_depth>0.1</min_depth>
          </ode>
        </contact>
      </surface>
    </collision>
    <visual>
      <origin rpy="0 0 0" xyz="0 0 0"/>
      <geometry>
        <cylinder length="0.005" radius="0.1"/>
      </geometry>
    </visual>
  </link>
  <!--chassis robot bottom link-->
  <link name="bottom_chassis">
    <pose>0 0 0 0 0 0</pose>
    <selfCollide>1</selfCollide>
    <inertial>
      <mass value="0.8"/>
      <origin rpy="0 0 0" xyz="0 0 0"/>
      <inertia ixx="0.0200016666667" ixy="0.01" ixz="0.01" iyy="0.0200016666667" iyz="0.01" izz="0.0200016666667"/>
    </inertial>
    <collision name="bottom_chassis">
      <geometry>
        <cylinder length="0.005" radius="0.1"/>
      </geometry>
      <surface>
        <contact>
          <poissons_ratio>0.347</poissons_ratio>
          <elastic_modulus>8.8e+09</elastic_modulus>
          <ode>
            <soft_cfm>0.001</soft_cfm>
            <soft_erp>0.3</soft_erp>
            <kp>1000</kp>
            <kp>1000</kp>
            <kd>10</kd>
            <max_vel>10.0</max_vel>
            <min_depth>0.1</min_depth>
          </ode>
        </contact>
      </surface>
    </collision>
    <visual>
      <origin rpy="0 0 0" xyz="0 0 0"/>
      <geometry>
        <cylinder length="0.005" radius="0.1"/>
      </geometry>
    </visual>
  </link>
  <!--mimik base-->
  <joint name="q_c" type="revolute">
    <parent link="base_link"/>
    <child link="support_c"/>
    <origin rpy="0.0 0.0 0.0" xyz="0.0 0.0 0.0"/>
    <limit effort="1.4709975" lower="0" upper="3.14159" velocity="6.178465545"/>
    <dynamics damping="2.0" friction="0.0"/>
    <axis xyz="0 0 1"/>
  </joint>
  <link name="support_c">
    <pose>0 0 0 0 0 0</pose>
    <selfCollide>1</selfCollide>
    <inertial>
      <mass value="0.001"/>
      <origin rpy="0 0 0" xyz="0 0 0"/>
      <inertia ixx="0.001" ixy="0.001" ixz="0.001" iyy="0.001" iyz="0.001" izz="0.001"/>
    </inertial>
    <collision name="support_c">
      <geometry>
        <cylinder length="0.001" radius="0.001"/>
      </geometry>
      <surface>
        <contact>
          <poissons_ratio>0.347</poissons_ratio>
          <elastic_modulus>8.8e+09</elastic_modulus>
          <ode>
            <soft_cfm>0.001</soft_cfm>
            <soft_erp>0.3</soft_erp>
            <kp>1000</kp>
            <kp>1000</kp>
            <kd>10</kd>
            <max_vel>10.0</max_vel>
            <min_depth>0.1</min_depth>
          </ode>
        </contact>
      </surface>
    </collision>
  </link>
  <transmission name="tran_1_q_c">
    <type>transmission_interface/SimpleTransmission</type>
    <joint name="q_c">
      <hardwareInterface>hardware_interface/PositionJointInterface</hardwareInterface>
    </joint>
    <actuator name="motor_q_c">
      <hardwareInterface>hardware_interface/PositionJointInterface</hardwareInterface>
      <mechanicalReduction>1</mechanicalReduction>
    </actuator>
  </transmission>
  <gazebo reference="support_c">
    <selfCollide>1</selfCollide>
    <implicitSpringDamper>True</implicitSpringDamper>
  </gazebo>
  <gazebo reference="bottom_chassis">
    <selfCollide>1</selfCollide>
    <implicitSpringDamper>True</implicitSpringDamper>
  </gazebo>
  <gazebo reference="map">
    <selfCollide>1</selfCollide>
    <implicitSpringDamper>True</implicitSpringDamper>
  </gazebo>
  <gazebo reference="upper_chassis">
    <implicitSpringDamper>True</implicitSpringDamper>
    <selfCollide>1</selfCollide>
    <implicitSpringDamper>True</implicitSpringDamper>
  </gazebo>
  <gazebo reference="base_link">
    <implicitSpringDamper>True</implicitSpringDamper>
    <selfCollide>1</selfCollide>
  </gazebo>
  <!-- **************************************************************************************************************************************** -->
  <!-- ******* ADAPTIVE CONSTANTS ******* -->
  <!-- **************************************************************************************************************************************** -->
  <!-- **************************************************************************************************************************************** -->
  <!-- ******* phisics proprieties ******* -->
  <!--inertia-->
  <!-- **************************************************************************************************************************************** -->
  <!-- ******* KINEMATIC PROPRIETIS (JOINTS) ******* -->
  <!-- **************************************************************************************************************************************** -->
  <!--base to folding fan bottom joint-->
  <joint name="folding_fan_joint_1" type="fixed">
    <parent link="base_link"/>
    <child link="folding_fan_link_1"/>
    <origin rpy="0 0 1.04719" xyz="0 0 -0.03"/>
    <!--limit effort="0" velocity="0.0" upper="0.0001" lower ="-0.0001" /-->
    <dynamics damping="20.0" friction="1000"/>
    <axis xyz="0 0 1"/>
  </joint>
  <!--q_1_1_0 FIXED-->
  <joint name="q_1_1_0_FIXED" type="fixed">
    <parent link="folding_fan_link_1"/>
    <child link="leg_B_1_1"/>
    <origin rpy="0 0 0" xyz="0.055 0 0"/>
    <dynamics damping="20.0" friction="1000"/>
    <!--limit effort="0" velocity="0.0" upper="0.0001" lower ="-0.0001" /-->
    <axis xyz="0 0 1"/>
  </joint>
  <!--q_1_i_1-->
  <joint name="q_1_1_1" type="revolute">
    <parent link="leg_B_1_1"/>
    <child link="leg_B_1_2"/>
    <origin rpy="0 0 0" xyz="0 0 0"/>
    <limit effort="1.4709975" lower="0" upper="3.14159" velocity="6.178465545"/>
    <dynamics damping="7.0" friction="0.1"/>
    <!--mimic joint="q_c" multiplier="1" offset="0" /-->
    <axis xyz="0 0 1"/>
  </joint>
  <!--q_1_i_2-->
  <joint name="q_1_1_2" type="revolute">
    <parent link="leg_B_1_2"/>
    <child link="leg_B_1_3"/>
    <origin rpy="0 0 0" xyz="0.08 0 0"/>
    <limit effort="1.4709975" lower="-1.570795" upper="1.570795" velocity="6.178465545"/>
    <dynamics damping="0.7" friction="1000"/>
    <axis xyz="0 0 1"/>
  </joint>
  <!--q_1_i_3-->
  <joint name="q_1_1_3" type="revolute">
    <parent link="leg_B_1_3"/>
    <child link="leg_B_1_4"/>
    <origin rpy="0 1.570795 0" xyz="0.06 0 0"/>
    <limit effort="1.765197" lower="-1.570795" upper="1.570795" velocity="6.178465545"/>
    <dynamics damping="7.0" friction="0.10"/>
    <axis xyz="0 1 0"/>
  </joint>
  <!--q_1_i_4-->
  <joint name="q_1_1_4" type="revolute">
    <parent link="leg_B_1_4"/>
    <child link="leg_B_1_5"/>
    <origin rpy="-1.570795 0 0" xyz="0.08 0 0"/>
    <limit effort="1.765197" lower="-1.570795" upper="1.570795" velocity="6.178465545"/>
    <dynamics damping="7.0" friction="0.1"/>
    <axis xyz="0 0 1"/>
  </joint>
  <!-- **************************************************************************************************************************************** -->
  <!-- ******* INERTIAL PROPRIETIS (LINKS) ******* -->
  <!-- **************************************************************************************************************************************** -->
  <!--folding fan robot bottom link-->
  <link name="folding_fan_link_1">
    <pose>0 0 0 0 0 0</pose>
    <selfCollide>1</selfCollide>
    <inertial>
      <mass value="0.8"/>
      <origin rpy="0 0 0" xyz="0 0 0"/>
      <inertia ixx="0.000344066666667" ixy="0.01" ixz="0.01" iyy="0.000344066666667" iyz="0.01" izz="0.00802406666667"/>
    </inertial>
    <visual>
      <origin rpy="0 0 0" xyz="0 0 0"/>
      <geometry>
        <cylinder length="0.019" radius="0.04"/>
      </geometry>
    </visual>
  </link>
  <!--folding fan robot bottom link-->
  <link name="leg_B_1_1">
    <pose>0 0 0 0 0 0</pose>
    <selfCollide>1</selfCollide>
    <inertial>
      <mass value="0.8"/>
      <origin rpy="0 0 0" xyz="0 0 0"/>
      <inertia ixx="6.90666666667e-05" ixy="0.01" ixz="0.01" iyy="6.90666666667e-05" iyz="0.01" izz="0.00302406666667"/>
    </inertial>
    <collision name="leg_B_1_1">
      <origin rpy="0 0 0" xyz="0 0 0"/>
      <geometry>
        <cylinder length="0.0038" radius="0.003"/>
      </geometry>
      <surface>
        <contact>
          <poissons_ratio>0.347</poissons_ratio>
          <elastic_modulus>8.8e+09</elastic_modulus>
          <ode>
            <soft_cfm>0.01</soft_cfm>
            <soft_erp>0.3</soft_erp>
            <kp>1000</kp>
            <kd>10</kd>
            <max_vel>100.0</max_vel>
            <min_depth>0.001</min_depth>
          </ode>
        </contact>
      </surface>
    </collision>
  </link>
  <!--leg_B_i_2 link-->
  <link name="leg_B_1_2">
    <pose>0 0 0 0 0 0</pose>
    <selfCollide>1</selfCollide>
    <inertial>
      <mass value="0.06"/>
      <origin rpy="0 1.570795 0" xyz="0.04 0 0"/>
      <inertia ixx="0.0004" ixy="0.01" ixz="0.01" iyy="0.01" iyz="0.01" izz="0.0004"/>
    </inertial>
    <collision name="leg_B_1_2">
      <origin rpy="0 1.570795 0" xyz="0.04 0 0"/>
      <geometry>
        <cylinder length="0.024" radius="0.003"/>
      </geometry>
      <surface>
        <contact>
          <poissons_ratio>0.347</poissons_ratio>
          <elastic_modulus>8.8e+09</elastic_modulus>
          <ode>
            <soft_cfm>0.01</soft_cfm>
            <soft_erp>0.3</soft_erp>
            <kp>1000</kp>
            <kd>10</kd>
            <max_vel>100.0</max_vel>
            <min_depth>0.001</min_depth>
          </ode>
        </contact>
      </surface>
    </collision>
    <visual>
      <origin rpy="0 1.570795 0" xyz="0.04 0 0"/>
      <geometry>
        <cylinder length="0.08" radius="0.005"/>
      </geometry>
    </visual>
  </link>
  <!--leg_B_i_3 link-->
  <link name="leg_B_1_3">
    <pose>0 0 0 0 0 0</pose>
    <selfCollide>1</selfCollide>
    <inertial>
      <mass value="0.06"/>
      <origin rpy="0 1.570795 0" xyz="0.03 0 0"/>
      <inertia ixx="0.0003" ixy="0.01" ixz="0.01" iyy="0.01" iyz="0.01" izz="0.0003"/>
    </inertial>
    <collision name="leg_B_1_3">
      <origin rpy="0 1.570795 0" xyz="0.03 0 0"/>
      <geometry>
        <cylinder length="0.036" radius="0.003"/>
      </geometry>
      <surface>
        <contact>
          <poissons_ratio>0.347</poissons_ratio>
          <elastic_modulus>8.8e+09</elastic_modulus>
          <ode>
            <soft_cfm>0.01</soft_cfm>
            <soft_erp>0.3</soft_erp>
            <kp>1000</kp>
            <kd>10</kd>
            <max_vel>100.0</max_vel>
            <min_depth>0.001</min_depth>
          </ode>
        </contact>
      </surface>
    </collision>
    <visual>
      <origin rpy="0 1.570795 0" xyz="0.03 0 0"/>
      <geometry>
        <cylinder length="0.06" radius="0.005"/>
      </geometry>
    </visual>
  </link>
  <!--leg_B_i_4 link-->
  <link name="leg_B_1_4">
    <pose>0 0 0 0 0 0</pose>
    <selfCollide>1</selfCollide>
    <inertial>
      <mass value="0.06"/>
      <origin rpy="0 -1.570795 0" xyz="0.04 0 0"/>
      <inertia ixx="0.0004" ixy="0.01" ixz="0.01" iyy="0.01" iyz="0.01" izz="0.0004"/>
    </inertial>
    <collision name="leg_B_1_4">
      <origin rpy="0 -1.570795 0" xyz="0.04 0 0"/>
      <geometry>
        <cylinder length="0.048" radius="0.003"/>
      </geometry>
    </collision>
    <surface>
      <contact>
        <poissons_ratio>0.347</poissons_ratio>
        <elastic_modulus>8.8e+09</elastic_modulus>
        <ode>
          <soft_cfm>0.01</soft_cfm>
          <soft_erp>0.3</soft_erp>
          <kp>1000</kp>
          <kd>10</kd>
          <max_vel>100.0</max_vel>
          <min_depth>0.001</min_depth>
        </ode>
      </contact>
    </surface>
    <visual>
      <origin rpy="0.0 -1.570795 0" xyz="0.04 0 0"/>
      <geometry>
        <cylinder length="0.08" radius="0.005"/>
      </geometry>
    </visual>
  </link>
  <!--leg_B_i_5 link-->
  <link name="leg_B_1_5">
    <pose>0 0 0 0 0 0</pose>
    <selfCollide>1</selfCollide>
    <inertial>
      <mass value="0.06"/>
      <origin rpy="0 1.570795 0" xyz="0.03 0 0"/>
      <inertia ixx="0.0003" ixy="0.01" ixz="0.01" iyy="0.01" iyz="0.01" izz="0.0003"/>
    </inertial>
    <collision name="leg_B_1_5">
      <origin rpy="0 1.570795 0" xyz="0.03 0 0"/>
      <geometry>
        <cylinder length="0.036" radius="0.003"/>
      </geometry>
      <surface>
        <contact>
          <poissons_ratio>0.347</poissons_ratio>
          <elastic_modulus>8.8e+09</elastic_modulus>
          <ode>
            <soft_cfm>0.01</soft_cfm>
            <soft_erp>0.3</soft_erp>
            <kp>1000</kp>
            <kd>10</kd>
            <max_vel>100.0</max_vel>
            <min_depth>0.001</min_depth>
          </ode>
        </contact>
      </surface>
    </collision>
    <visual>
      <origin rpy="0 1.570795 0" xyz="0.03 0 0"/>
      <geometry>
        <cylinder length="0.06" radius="0.005"/>
      </geometry>
    </visual>
  </link>
  <gazebo reference="folding_fan_link_1">
    <implicitSpringDamper>True</implicitSpringDamper>
    <selfCollide>1</selfCollide>
  </gazebo>
  <gazebo reference="folding_fan_link_1">
    <implicitSpringDamper>True</implicitSpringDamper>
    <selfCollide>1</selfCollide>
  </gazebo>
  <gazebo reference="leg_B_1_0">
    <implicitSpringDamper>True</implicitSpringDamper>
    <selfCollide>1</selfCollide>
  </gazebo>
  <gazebo reference="leg_B_1_1">
    <implicitSpringDamper>True</implicitSpringDamper>
    <selfCollide>1</selfCollide>
  </gazebo>
  <gazebo reference="leg_B_1_2">
    <implicitSpringDamper>True</implicitSpringDamper>
    <selfCollide>1</selfCollide>
  </gazebo>
  <gazebo reference="leg_B_1_3">
    <implicitSpringDamper>True</implicitSpringDamper>
    <selfCollide>1</selfCollide>
  </gazebo>
  <gazebo reference="leg_B_1_4">
    <implicitSpringDamper>True</implicitSpringDamper>
    <selfCollide>1</selfCollide>
  </gazebo>
  <gazebo reference="leg_B_1_5">
    <implicitSpringDamper>True</implicitSpringDamper>
    <selfCollide>1</selfCollide>
  </gazebo>
  <transmission name="tran_1_1_1">
    <type>transmission_interface/SimpleTransmission</type>
    <joint name="q_1_1_1">
      <hardwareInterface>hardware_interface/PositionJointInterface</hardwareInterface>
    </joint>
    <actuator name="motor_1_1_1">
      <hardwareInterface>hardware_interface/PositionJointInterface</hardwareInterface>
      <mechanicalReduction>1</mechanicalReduction>
    </actuator>
  </transmission>
  <transmission name="tran_1_1_2">
    <type>transmission_interface/SimpleTransmission</type>
    <joint name="q_1_1_2">
      <hardwareInterface>hardware_interface/PositionJointInterface</hardwareInterface>
    </joint>
    <actuator name="motor_1_1_2">
      <hardwareInterface>hardware_interface/PositionJointInterface</hardwareInterface>
      <mechanicalReduction>1</mechanicalReduction>
    </actuator>
  </transmission>
  <transmission name="tran_1_1_3">
    <type>transmission_interface/SimpleTransmission</type>
    <joint name="q_1_1_3">
      <hardwareInterface>hardware_interface/PositionJointInterface</hardwareInterface>
    </joint>
    <actuator name="motor_1_1_3">
      <hardwareInterface>hardware_interface/PositionJointInterface</hardwareInterface>
      <mechanicalReduction>1</mechanicalReduction>
    </actuator>
  </transmission>
  <transmission name="tran_1_1_4">
    <type>transmission_interface/SimpleTransmission</type>
    <joint name="q_1_1_4">
      <hardwareInterface>hardware_interface/PositionJointInterface</hardwareInterface>
    </joint>
    <actuator name="motor_1_1_4_">
      <hardwareInterface>hardware_interface/PositionJointInterface</hardwareInterface>
      <mechanicalReduction>1</mechanicalReduction>
    </actuator>
  </transmission>
  <!-- **************************************************************************************************************************************** -->
  <!-- ******* KINEMATIC PROPRIETIS (JOINTS) ******* -->
  <!-- **************************************************************************************************************************************** -->
  <!--base to folding fan bottom joint-->
  <joint name="folding_fan_joint_2" type="fixed">
    <parent link="base_link"/>
    <child link="folding_fan_link_2"/>
    <origin rpy="0 0 2.09438" xyz="0 0 -0.03"/>
    <!--limit effort="0" velocity="0.0" upper="0.0001" lower ="-0.0001" /-->
    <dynamics damping="20.0" friction="1000"/>
    <axis xyz="0 0 1"/>
  </joint>
  <!--q_1_1_0 FIXED-->
  <joint name="q_1_2_0_FIXED" type="fixed">
    <parent link="folding_fan_link_2"/>
    <child link="leg_B_2_1"/>
    <origin rpy="0 0 0" xyz="0.055 0 0"/>
    <dynamics damping="20.0" friction="1000"/>
    <!--limit effort="0" velocity="0.0" upper="0.0001" lower ="-0.0001" /-->
    <axis xyz="0 0 1"/>
  </joint>
  <!--q_1_i_1-->
  <joint name="q_1_2_1" type="revolute">
    <parent link="leg_B_2_1"/>
    <child link="leg_B_2_2"/>
    <origin rpy="0 0 0" xyz="0 0 0"/>
    <limit effort="1.4709975" lower="0" upper="3.14159" velocity="6.178465545"/>
    <dynamics damping="7.0" friction="0.1"/>
    <!--mimic joint="q_c" multiplier="1" offset="0" /-->
    <axis xyz="0 0 1"/>
  </joint>
  <!--q_1_i_2-->
  <joint name="q_1_2_2" type="revolute">
    <parent link="leg_B_2_2"/>
    <child link="leg_B_2_3"/>
    <origin rpy="0 0 0" xyz="0.08 0 0"/>
    <limit effort="1.4709975" lower="-1.570795" upper="1.570795" velocity="6.178465545"/>
    <dynamics damping="0.7" friction="1000"/>
    <axis xyz="0 0 1"/>
  </joint>
  <!--q_1_i_3-->
  <joint name="q_1_2_3" type="revolute">
    <parent link="leg_B_2_3"/>
    <child link="leg_B_2_4"/>
    <origin rpy="0 1.570795 0" xyz="0.06 0 0"/>
    <limit effort="1.765197" lower="-1.570795" upper="1.570795" velocity="6.178465545"/>
    <dynamics damping="7.0" friction="0.10"/>
    <axis xyz="0 1 0"/>
  </joint>
  <!--q_1_i_4-->
  <joint name="q_1_2_4" type="revolute">
    <parent link="leg_B_2_4"/>
    <child link="leg_B_2_5"/>
    <origin rpy="-1.570795 0 0" xyz="0.08 0 0"/>
    <limit effort="1.765197" lower="-1.570795" upper="1.570795" velocity="6.178465545"/>
    <dynamics damping="7.0" friction="0.1"/>
    <axis xyz="0 0 1"/>
  </joint>
  <!-- **************************************************************************************************************************************** -->
  <!-- ******* INERTIAL PROPRIETIS (LINKS) ******* -->
  <!-- **************************************************************************************************************************************** -->
  <!--folding fan robot bottom link-->
  <link name="folding_fan_link_2">
    <pose>0 0 0 0 0 0</pose>
    <selfCollide>1</selfCollide>
    <inertial>
      <mass value="0.8"/>
      <origin rpy="0 0 0" xyz="0 0 0"/>
      <inertia ixx="0.000344066666667" ixy="0.01" ixz="0.01" iyy="0.000344066666667" iyz="0.01" izz="0.00802406666667"/>
    </inertial>
    <visual>
      <origin rpy="0 0 0" xyz="0 0 0"/>
      <geometry>
        <cylinder length="0.019" radius="0.04"/>
      </geometry>
    </visual>
  </link>
  <!--folding fan robot bottom link-->
  <link name="leg_B_2_1">
    <pose>0 0 0 0 0 0</pose>
    <selfCollide>1</selfCollide>
    <inertial>
      <mass value="0.8"/>
      <origin rpy="0 0 0" xyz="0 0 0"/>
      <inertia ixx="6.90666666667e-05" ixy="0.01" ixz="0.01" iyy="6.90666666667e-05" iyz="0.01" izz="0.00302406666667"/>
    </inertial>
    <collision name="leg_B_2_1">
      <origin rpy="0 0 0" xyz="0 0 0"/>
      <geometry>
        <cylinder length="0.0038" radius="0.003"/>
      </geometry>
      <surface>
        <contact>
          <poissons_ratio>0.347</poissons_ratio>
          <elastic_modulus>8.8e+09</elastic_modulus>
          <ode>
            <soft_cfm>0.01</soft_cfm>
            <soft_erp>0.3</soft_erp>
            <kp>1000</kp>
            <kd>10</kd>
            <max_vel>100.0</max_vel>
            <min_depth>0.001</min_depth>
          </ode>
        </contact>
      </surface>
    </collision>
  </link>
  <!--leg_B_i_2 link-->
  <link name="leg_B_2_2">
    <pose>0 0 0 0 0 0</pose>
    <selfCollide>1</selfCollide>
    <inertial>
      <mass value="0.06"/>
      <origin rpy="0 1.570795 0" xyz="0.04 0 0"/>
      <inertia ixx="0.0004" ixy="0.01" ixz="0.01" iyy="0.01" iyz="0.01" izz="0.0004"/>
    </inertial>
    <collision name="leg_B_2_2">
      <origin rpy="0 1.570795 0" xyz="0.04 0 0"/>
      <geometry>
        <cylinder length="0.024" radius="0.003"/>
      </geometry>
      <surface>
        <contact>
          <poissons_ratio>0.347</poissons_ratio>
          <elastic_modulus>8.8e+09</elastic_modulus>
          <ode>
            <soft_cfm>0.01</soft_cfm>
            <soft_erp>0.3</soft_erp>
            <kp>1000</kp>
            <kd>10</kd>
            <max_vel>100.0</max_vel>
            <min_depth>0.001</min_depth>
          </ode>
        </contact>
      </surface>
    </collision>
    <visual>
      <origin rpy="0 1.570795 0" xyz="0.04 0 0"/>
      <geometry>
        <cylinder length="0.08" radius="0.005"/>
      </geometry>
    </visual>
  </link>
  <!--leg_B_i_3 link-->
  <link name="leg_B_2_3">
    <pose>0 0 0 0 0 0</pose>
    <selfCollide>1</selfCollide>
    <inertial>
      <mass value="0.06"/>
      <origin rpy="0 1.570795 0" xyz="0.03 0 0"/>
      <inertia ixx="0.0003" ixy="0.01" ixz="0.01" iyy="0.01" iyz="0.01" izz="0.0003"/>
    </inertial>
    <collision name="leg_B_2_3">
      <origin rpy="0 1.570795 0" xyz="0.03 0 0"/>
      <geometry>
        <cylinder length="0.036" radius="0.003"/>
      </geometry>
      <surface>
        <contact>
          <poissons_ratio>0.347</poissons_ratio>
          <elastic_modulus>8.8e+09</elastic_modulus>
          <ode>
            <soft_cfm>0.01</soft_cfm>
            <soft_erp>0.3</soft_erp>
            <kp>1000</kp>
            <kd>10</kd>
            <max_vel>100.0</max_vel>
            <min_depth>0.001</min_depth>
          </ode>
        </contact>
      </surface>
    </collision>
    <visual>
      <origin rpy="0 1.570795 0" xyz="0.03 0 0"/>
      <geometry>
        <cylinder length="0.06" radius="0.005"/>
      </geometry>
    </visual>
  </link>
  <!--leg_B_i_4 link-->
  <link name="leg_B_2_4">
    <pose>0 0 0 0 0 0</pose>
    <selfCollide>1</selfCollide>
    <inertial>
      <mass value="0.06"/>
      <origin rpy="0 -1.570795 0" xyz="0.04 0 0"/>
      <inertia ixx="0.0004" ixy="0.01" ixz="0.01" iyy="0.01" iyz="0.01" izz="0.0004"/>
    </inertial>
    <collision name="leg_B_2_4">
      <origin rpy="0 -1.570795 0" xyz="0.04 0 0"/>
      <geometry>
        <cylinder length="0.048" radius="0.003"/>
      </geometry>
    </collision>
    <surface>
      <contact>
        <poissons_ratio>0.347</poissons_ratio>
        <elastic_modulus>8.8e+09</elastic_modulus>
        <ode>
          <soft_cfm>0.01</soft_cfm>
          <soft_erp>0.3</soft_erp>
          <kp>1000</kp>
          <kd>10</kd>
          <max_vel>100.0</max_vel>
          <min_depth>0.001</min_depth>
        </ode>
      </contact>
    </surface>
    <visual>
      <origin rpy="0.0 -1.570795 0" xyz="0.04 0 0"/>
      <geometry>
        <cylinder length="0.08" radius="0.005"/>
      </geometry>
    </visual>
  </link>
  <!--leg_B_i_5 link-->
  <link name="leg_B_2_5">
    <pose>0 0 0 0 0 0</pose>
    <selfCollide>1</selfCollide>
    <inertial>
      <mass value="0.06"/>
      <origin rpy="0 1.570795 0" xyz="0.03 0 0"/>
      <inertia ixx="0.0003" ixy="0.01" ixz="0.01" iyy="0.01" iyz="0.01" izz="0.0003"/>
    </inertial>
    <collision name="leg_B_2_5">
      <origin rpy="0 1.570795 0" xyz="0.03 0 0"/>
      <geometry>
        <cylinder length="0.036" radius="0.003"/>
      </geometry>
      <surface>
        <contact>
          <poissons_ratio>0.347</poissons_ratio>
          <elastic_modulus>8.8e+09</elastic_modulus>
          <ode>
            <soft_cfm>0.01</soft_cfm>
            <soft_erp>0.3</soft_erp>
            <kp>1000</kp>
            <kd>10</kd>
            <max_vel>100.0</max_vel>
            <min_depth>0.001</min_depth>
          </ode>
        </contact>
      </surface>
    </collision>
    <visual>
      <origin rpy="0 1.570795 0" xyz="0.03 0 0"/>
      <geometry>
        <cylinder length="0.06" radius="0.005"/>
      </geometry>
    </visual>
  </link>
  <gazebo reference="folding_fan_link_2">
    <implicitSpringDamper>True</implicitSpringDamper>
    <selfCollide>1</selfCollide>
  </gazebo>
  <gazebo reference="folding_fan_link_2">
    <implicitSpringDamper>True</implicitSpringDamper>
    <selfCollide>1</selfCollide>
  </gazebo>
  <gazebo reference="leg_B_2_0">
    <implicitSpringDamper>True</implicitSpringDamper>
    <selfCollide>1</selfCollide>
  </gazebo>
  <gazebo reference="leg_B_2_1">
    <implicitSpringDamper>True</implicitSpringDamper>
    <selfCollide>1</selfCollide>
  </gazebo>
  <gazebo reference="leg_B_2_2">
    <implicitSpringDamper>True</implicitSpringDamper>
    <selfCollide>1</selfCollide>
  </gazebo>
  <gazebo reference="leg_B_2_3">
    <implicitSpringDamper>True</implicitSpringDamper>
    <selfCollide>1</selfCollide>
  </gazebo>
  <gazebo reference="leg_B_2_4">
    <implicitSpringDamper>True</implicitSpringDamper>
    <selfCollide>1</selfCollide>
  </gazebo>
  <gazebo reference="leg_B_2_5">
    <implicitSpringDamper>True</implicitSpringDamper>
    <selfCollide>1</selfCollide>
  </gazebo>
  <transmission name="tran_1_2_1">
    <type>transmission_interface/SimpleTransmission</type>
    <joint name="q_1_2_1">
      <hardwareInterface>hardware_interface/PositionJointInterface</hardwareInterface>
    </joint>
    <actuator name="motor_1_2_1">
      <hardwareInterface>hardware_interface/PositionJointInterface</hardwareInterface>
      <mechanicalReduction>1</mechanicalReduction>
    </actuator>
  </transmission>
  <transmission name="tran_1_2_2">
    <type>transmission_interface/SimpleTransmission</type>
    <joint name="q_1_2_2">
      <hardwareInterface>hardware_interface/PositionJointInterface</hardwareInterface>
    </joint>
    <actuator name="motor_1_2_2">
      <hardwareInterface>hardware_interface/PositionJointInterface</hardwareInterface>
      <mechanicalReduction>1</mechanicalReduction>
    </actuator>
  </transmission>
  <transmission name="tran_1_2_3">
    <type>transmission_interface/SimpleTransmission</type>
    <joint name="q_1_2_3">
      <hardwareInterface>hardware_interface/PositionJointInterface</hardwareInterface>
    </joint>
    <actuator name="motor_1_2_3">
      <hardwareInterface>hardware_interface/PositionJointInterface</hardwareInterface>
      <mechanicalReduction>1</mechanicalReduction>
    </actuator>
  </transmission>
  <transmission name="tran_1_2_4">
    <type>transmission_interface/SimpleTransmission</type>
    <joint name="q_1_2_4">
      <hardwareInterface>hardware_interface/PositionJointInterface</hardwareInterface>
    </joint>
    <actuator name="motor_1_2_4_">
      <hardwareInterface>hardware_interface/PositionJointInterface</hardwareInterface>
      <mechanicalReduction>1</mechanicalReduction>
    </actuator>
  </transmission>
  <!-- **************************************************************************************************************************************** -->
  <!-- ******* KINEMATIC PROPRIETIS (JOINTS) ******* -->
  <!-- **************************************************************************************************************************************** -->
  <!--base to folding fan bottom joint-->
  <joint name="folding_fan_joint_3" type="fixed">
    <parent link="base_link"/>
    <child link="folding_fan_link_3"/>
    <origin rpy="0 0 3.14157" xyz="0 0 -0.03"/>
    <!--limit effort="0" velocity="0.0" upper="0.0001" lower ="-0.0001" /-->
    <dynamics damping="20.0" friction="1000"/>
    <axis xyz="0 0 1"/>
  </joint>
  <!--q_1_1_0 FIXED-->
  <joint name="q_1_3_0_FIXED" type="fixed">
    <parent link="folding_fan_link_3"/>
    <child link="leg_B_3_1"/>
    <origin rpy="0 0 0" xyz="0.055 0 0"/>
    <dynamics damping="20.0" friction="1000"/>
    <!--limit effort="0" velocity="0.0" upper="0.0001" lower ="-0.0001" /-->
    <axis xyz="0 0 1"/>
  </joint>
  <!--q_1_i_1-->
  <joint name="q_1_3_1" type="revolute">
    <parent link="leg_B_3_1"/>
    <child link="leg_B_3_2"/>
    <origin rpy="0 0 0" xyz="0 0 0"/>
    <limit effort="1.4709975" lower="0" upper="3.14159" velocity="6.178465545"/>
    <dynamics damping="7.0" friction="0.1"/>
    <!--mimic joint="q_c" multiplier="1" offset="0" /-->
    <axis xyz="0 0 1"/>
  </joint>
  <!--q_1_i_2-->
  <joint name="q_1_3_2" type="revolute">
    <parent link="leg_B_3_2"/>
    <child link="leg_B_3_3"/>
    <origin rpy="0 0 0" xyz="0.08 0 0"/>
    <limit effort="1.4709975" lower="-1.570795" upper="1.570795" velocity="6.178465545"/>
    <dynamics damping="0.7" friction="1000"/>
    <axis xyz="0 0 1"/>
  </joint>
  <!--q_1_i_3-->
  <joint name="q_1_3_3" type="revolute">
    <parent link="leg_B_3_3"/>
    <child link="leg_B_3_4"/>
    <origin rpy="0 1.570795 0" xyz="0.06 0 0"/>
    <limit effort="1.765197" lower="-1.570795" upper="1.570795" velocity="6.178465545"/>
    <dynamics damping="7.0" friction="0.10"/>
    <axis xyz="0 1 0"/>
  </joint>
  <!--q_1_i_4-->
  <joint name="q_1_3_4" type="revolute">
    <parent link="leg_B_3_4"/>
    <child link="leg_B_3_5"/>
    <origin rpy="-1.570795 0 0" xyz="0.08 0 0"/>
    <limit effort="1.765197" lower="-1.570795" upper="1.570795" velocity="6.178465545"/>
    <dynamics damping="7.0" friction="0.1"/>
    <axis xyz="0 0 1"/>
  </joint>
  <!-- **************************************************************************************************************************************** -->
  <!-- ******* INERTIAL PROPRIETIS (LINKS) ******* -->
  <!-- **************************************************************************************************************************************** -->
  <!--folding fan robot bottom link-->
  <link name="folding_fan_link_3">
    <pose>0 0 0 0 0 0</pose>
    <selfCollide>1</selfCollide>
    <inertial>
      <mass value="0.8"/>
      <origin rpy="0 0 0" xyz="0 0 0"/>
      <inertia ixx="0.000344066666667" ixy="0.01" ixz="0.01" iyy="0.000344066666667" iyz="0.01" izz="0.00802406666667"/>
    </inertial>
    <visual>
      <origin rpy="0 0 0" xyz="0 0 0"/>
      <geometry>
        <cylinder length="0.019" radius="0.04"/>
      </geometry>
    </visual>
  </link>
  <!--folding fan robot bottom link-->
  <link name="leg_B_3_1">
    <pose>0 0 0 0 0 0</pose>
    <selfCollide>1</selfCollide>
    <inertial>
      <mass value="0.8"/>
      <origin rpy="0 0 0" xyz="0 0 0"/>
      <inertia ixx="6.90666666667e-05" ixy="0.01" ixz="0.01" iyy="6.90666666667e-05" iyz="0.01" izz="0.00302406666667"/>
    </inertial>
    <collision name="leg_B_3_1">
      <origin rpy="0 0 0" xyz="0 0 0"/>
      <geometry>
        <cylinder length="0.0038" radius="0.003"/>
      </geometry>
      <surface>
        <contact>
          <poissons_ratio>0.347</poissons_ratio>
          <elastic_modulus>8.8e+09</elastic_modulus>
          <ode>
            <soft_cfm>0.01</soft_cfm>
            <soft_erp>0.3</soft_erp>
            <kp>1000</kp>
            <kd>10</kd>
            <max_vel>100.0</max_vel>
            <min_depth>0.001</min_depth>
          </ode>
        </contact>
      </surface>
    </collision>
  </link>
  <!--leg_B_i_2 link-->
  <link name="leg_B_3_2">
    <pose>0 0 0 0 0 0</pose>
    <selfCollide>1</selfCollide>
    <inertial>
      <mass value="0.06"/>
      <origin rpy="0 1.570795 0" xyz="0.04 0 0"/>
      <inertia ixx="0.0004" ixy="0.01" ixz="0.01" iyy="0.01" iyz="0.01" izz="0.0004"/>
    </inertial>
    <collision name="leg_B_3_2">
      <origin rpy="0 1.570795 0" xyz="0.04 0 0"/>
      <geometry>
        <cylinder length="0.024" radius="0.003"/>
      </geometry>
      <surface>
        <contact>
          <poissons_ratio>0.347</poissons_ratio>
          <elastic_modulus>8.8e+09</elastic_modulus>
          <ode>
            <soft_cfm>0.01</soft_cfm>
            <soft_erp>0.3</soft_erp>
            <kp>1000</kp>
            <kd>10</kd>
            <max_vel>100.0</max_vel>
            <min_depth>0.001</min_depth>
          </ode>
        </contact>
      </surface>
    </collision>
    <visual>
      <origin rpy="0 1.570795 0" xyz="0.04 0 0"/>
      <geometry>
        <cylinder length="0.08" radius="0.005"/>
      </geometry>
    </visual>
  </link>
  <!--leg_B_i_3 link-->
  <link name="leg_B_3_3">
    <pose>0 0 0 0 0 0</pose>
    <selfCollide>1</selfCollide>
    <inertial>
      <mass value="0.06"/>
      <origin rpy="0 1.570795 0" xyz="0.03 0 0"/>
      <inertia ixx="0.0003" ixy="0.01" ixz="0.01" iyy="0.01" iyz="0.01" izz="0.0003"/>
    </inertial>
    <collision name="leg_B_3_3">
      <origin rpy="0 1.570795 0" xyz="0.03 0 0"/>
      <geometry>
        <cylinder length="0.036" radius="0.003"/>
      </geometry>
      <surface>
        <contact>
          <poissons_ratio>0.347</poissons_ratio>
          <elastic_modulus>8.8e+09</elastic_modulus>
          <ode>
            <soft_cfm>0.01</soft_cfm>
            <soft_erp>0.3</soft_erp>
            <kp>1000</kp>
            <kd>10</kd>
            <max_vel>100.0</max_vel>
            <min_depth>0.001</min_depth>
          </ode>
        </contact>
      </surface>
    </collision>
    <visual>
      <origin rpy="0 1.570795 0" xyz="0.03 0 0"/>
      <geometry>
        <cylinder length="0.06" radius="0.005"/>
      </geometry>
    </visual>
  </link>
  <!--leg_B_i_4 link-->
  <link name="leg_B_3_4">
    <pose>0 0 0 0 0 0</pose>
    <selfCollide>1</selfCollide>
    <inertial>
      <mass value="0.06"/>
      <origin rpy="0 -1.570795 0" xyz="0.04 0 0"/>
      <inertia ixx="0.0004" ixy="0.01" ixz="0.01" iyy="0.01" iyz="0.01" izz="0.0004"/>
    </inertial>
    <collision name="leg_B_3_4">
      <origin rpy="0 -1.570795 0" xyz="0.04 0 0"/>
      <geometry>
        <cylinder length="0.048" radius="0.003"/>
      </geometry>
    </collision>
    <surface>
      <contact>
        <poissons_ratio>0.347</poissons_ratio>
        <elastic_modulus>8.8e+09</elastic_modulus>
        <ode>
          <soft_cfm>0.01</soft_cfm>
          <soft_erp>0.3</soft_erp>
          <kp>1000</kp>
          <kd>10</kd>
          <max_vel>100.0</max_vel>
          <min_depth>0.001</min_depth>
        </ode>
      </contact>
    </surface>
    <visual>
      <origin rpy="0.0 -1.570795 0" xyz="0.04 0 0"/>
      <geometry>
        <cylinder length="0.08" radius="0.005"/>
      </geometry>
    </visual>
  </link>
  <!--leg_B_i_5 link-->
  <link name="leg_B_3_5">
    <pose>0 0 0 0 0 0</pose>
    <selfCollide>1</selfCollide>
    <inertial>
      <mass value="0.06"/>
      <origin rpy="0 1.570795 0" xyz="0.03 0 0"/>
      <inertia ixx="0.0003" ixy="0.01" ixz="0.01" iyy="0.01" iyz="0.01" izz="0.0003"/>
    </inertial>
    <collision name="leg_B_3_5">
      <origin rpy="0 1.570795 0" xyz="0.03 0 0"/>
      <geometry>
        <cylinder length="0.036" radius="0.003"/>
      </geometry>
      <surface>
        <contact>
          <poissons_ratio>0.347</poissons_ratio>
          <elastic_modulus>8.8e+09</elastic_modulus>
          <ode>
            <soft_cfm>0.01</soft_cfm>
            <soft_erp>0.3</soft_erp>
            <kp>1000</kp>
            <kd>10</kd>
            <max_vel>100.0</max_vel>
            <min_depth>0.001</min_depth>
          </ode>
        </contact>
      </surface>
    </collision>
    <visual>
      <origin rpy="0 1.570795 0" xyz="0.03 0 0"/>
      <geometry>
        <cylinder length="0.06" radius="0.005"/>
      </geometry>
    </visual>
  </link>
  <gazebo reference="folding_fan_link_3">
    <implicitSpringDamper>True</implicitSpringDamper>
    <selfCollide>1</selfCollide>
  </gazebo>
  <gazebo reference="folding_fan_link_3">
    <implicitSpringDamper>True</implicitSpringDamper>
    <selfCollide>1</selfCollide>
  </gazebo>
  <gazebo reference="leg_B_3_0">
    <implicitSpringDamper>True</implicitSpringDamper>
    <selfCollide>1</selfCollide>
  </gazebo>
  <gazebo reference="leg_B_3_1">
    <implicitSpringDamper>True</implicitSpringDamper>
    <selfCollide>1</selfCollide>
  </gazebo>
  <gazebo reference="leg_B_3_2">
    <implicitSpringDamper>True</implicitSpringDamper>
    <selfCollide>1</selfCollide>
  </gazebo>
  <gazebo reference="leg_B_3_3">
    <implicitSpringDamper>True</implicitSpringDamper>
    <selfCollide>1</selfCollide>
  </gazebo>
  <gazebo reference="leg_B_3_4">
    <implicitSpringDamper>True</implicitSpringDamper>
    <selfCollide>1</selfCollide>
  </gazebo>
  <gazebo reference="leg_B_3_5">
    <implicitSpringDamper>True</implicitSpringDamper>
    <selfCollide>1</selfCollide>
  </gazebo>
  <transmission name="tran_1_3_1">
    <type>transmission_interface/SimpleTransmission</type>
    <joint name="q_1_3_1">
      <hardwareInterface>hardware_interface/PositionJointInterface</hardwareInterface>
    </joint>
    <actuator name="motor_1_3_1">
      <hardwareInterface>hardware_interface/PositionJointInterface</hardwareInterface>
      <mechanicalReduction>1</mechanicalReduction>
    </actuator>
  </transmission>
  <transmission name="tran_1_3_2">
    <type>transmission_interface/SimpleTransmission</type>
    <joint name="q_1_3_2">
      <hardwareInterface>hardware_interface/PositionJointInterface</hardwareInterface>
    </joint>
    <actuator name="motor_1_3_2">
      <hardwareInterface>hardware_interface/PositionJointInterface</hardwareInterface>
      <mechanicalReduction>1</mechanicalReduction>
    </actuator>
  </transmission>
  <transmission name="tran_1_3_3">
    <type>transmission_interface/SimpleTransmission</type>
    <joint name="q_1_3_3">
      <hardwareInterface>hardware_interface/PositionJointInterface</hardwareInterface>
    </joint>
    <actuator name="motor_1_3_3">
      <hardwareInterface>hardware_interface/PositionJointInterface</hardwareInterface>
      <mechanicalReduction>1</mechanicalReduction>
    </actuator>
  </transmission>
  <transmission name="tran_1_3_4">
    <type>transmission_interface/SimpleTransmission</type>
    <joint name="q_1_3_4">
      <hardwareInterface>hardware_interface/PositionJointInterface</hardwareInterface>
    </joint>
    <actuator name="motor_1_3_4_">
      <hardwareInterface>hardware_interface/PositionJointInterface</hardwareInterface>
      <mechanicalReduction>1</mechanicalReduction>
    </actuator>
  </transmission>
  <!-- **************************************************************************************************************************************** -->
  <!-- ******* KINEMATIC PROPRIETIS (JOINTS) ******* -->
  <!-- **************************************************************************************************************************************** -->
  <!--base to folding fan bottom joint-->
  <joint name="folding_fan_joint_4" type="fixed">
    <parent link="base_link"/>
    <child link="folding_fan_link_4"/>
    <origin rpy="0 0 4.18876" xyz="0 0 -0.03"/>
    <!--limit effort="0" velocity="0.0" upper="0.0001" lower ="-0.0001" /-->
    <dynamics damping="20.0" friction="1000"/>
    <axis xyz="0 0 1"/>
  </joint>
  <!--q_1_1_0 FIXED-->
  <joint name="q_1_4_0_FIXED" type="fixed">
    <parent link="folding_fan_link_4"/>
    <child link="leg_B_4_1"/>
    <origin rpy="0 0 0" xyz="0.055 0 0"/>
    <dynamics damping="20.0" friction="1000"/>
    <!--limit effort="0" velocity="0.0" upper="0.0001" lower ="-0.0001" /-->
    <axis xyz="0 0 1"/>
  </joint>
  <!--q_1_i_1-->
  <joint name="q_1_4_1" type="revolute">
    <parent link="leg_B_4_1"/>
    <child link="leg_B_4_2"/>
    <origin rpy="0 0 0" xyz="0 0 0"/>
    <limit effort="1.4709975" lower="0" upper="3.14159" velocity="6.178465545"/>
    <dynamics damping="7.0" friction="0.1"/>
    <!--mimic joint="q_c" multiplier="1" offset="0" /-->
    <axis xyz="0 0 1"/>
  </joint>
  <!--q_1_i_2-->
  <joint name="q_1_4_2" type="revolute">
    <parent link="leg_B_4_2"/>
    <child link="leg_B_4_3"/>
    <origin rpy="0 0 0" xyz="0.08 0 0"/>
    <limit effort="1.4709975" lower="-1.570795" upper="1.570795" velocity="6.178465545"/>
    <dynamics damping="0.7" friction="1000"/>
    <axis xyz="0 0 1"/>
  </joint>
  <!--q_1_i_3-->
  <joint name="q_1_4_3" type="revolute">
    <parent link="leg_B_4_3"/>
    <child link="leg_B_4_4"/>
    <origin rpy="0 1.570795 0" xyz="0.06 0 0"/>
    <limit effort="1.765197" lower="-1.570795" upper="1.570795" velocity="6.178465545"/>
    <dynamics damping="7.0" friction="0.10"/>
    <axis xyz="0 1 0"/>
  </joint>
  <!--q_1_i_4-->
  <joint name="q_1_4_4" type="revolute">
    <parent link="leg_B_4_4"/>
    <child link="leg_B_4_5"/>
    <origin rpy="-1.570795 0 0" xyz="0.08 0 0"/>
    <limit effort="1.765197" lower="-1.570795" upper="1.570795" velocity="6.178465545"/>
    <dynamics damping="7.0" friction="0.1"/>
    <axis xyz="0 0 1"/>
  </joint>
  <!-- **************************************************************************************************************************************** -->
  <!-- ******* INERTIAL PROPRIETIS (LINKS) ******* -->
  <!-- **************************************************************************************************************************************** -->
  <!--folding fan robot bottom link-->
  <link name="folding_fan_link_4">
    <pose>0 0 0 0 0 0</pose>
    <selfCollide>1</selfCollide>
    <inertial>
      <mass value="0.8"/>
      <origin rpy="0 0 0" xyz="0 0 0"/>
      <inertia ixx="0.000344066666667" ixy="0.01" ixz="0.01" iyy="0.000344066666667" iyz="0.01" izz="0.00802406666667"/>
    </inertial>
    <visual>
      <origin rpy="0 0 0" xyz="0 0 0"/>
      <geometry>
        <cylinder length="0.019" radius="0.04"/>
      </geometry>
    </visual>
  </link>
  <!--folding fan robot bottom link-->
  <link name="leg_B_4_1">
    <pose>0 0 0 0 0 0</pose>
    <selfCollide>1</selfCollide>
    <inertial>
      <mass value="0.8"/>
      <origin rpy="0 0 0" xyz="0 0 0"/>
      <inertia ixx="6.90666666667e-05" ixy="0.01" ixz="0.01" iyy="6.90666666667e-05" iyz="0.01" izz="0.00302406666667"/>
    </inertial>
    <collision name="leg_B_4_1">
      <origin rpy="0 0 0" xyz="0 0 0"/>
      <geometry>
        <cylinder length="0.0038" radius="0.003"/>
      </geometry>
      <surface>
        <contact>
          <poissons_ratio>0.347</poissons_ratio>
          <elastic_modulus>8.8e+09</elastic_modulus>
          <ode>
            <soft_cfm>0.01</soft_cfm>
            <soft_erp>0.3</soft_erp>
            <kp>1000</kp>
            <kd>10</kd>
            <max_vel>100.0</max_vel>
            <min_depth>0.001</min_depth>
          </ode>
        </contact>
      </surface>
    </collision>
  </link>
  <!--leg_B_i_2 link-->
  <link name="leg_B_4_2">
    <pose>0 0 0 0 0 0</pose>
    <selfCollide>1</selfCollide>
    <inertial>
      <mass value="0.06"/>
      <origin rpy="0 1.570795 0" xyz="0.04 0 0"/>
      <inertia ixx="0.0004" ixy="0.01" ixz="0.01" iyy="0.01" iyz="0.01" izz="0.0004"/>
    </inertial>
    <collision name="leg_B_4_2">
      <origin rpy="0 1.570795 0" xyz="0.04 0 0"/>
      <geometry>
        <cylinder length="0.024" radius="0.003"/>
      </geometry>
      <surface>
        <contact>
          <poissons_ratio>0.347</poissons_ratio>
          <elastic_modulus>8.8e+09</elastic_modulus>
          <ode>
            <soft_cfm>0.01</soft_cfm>
            <soft_erp>0.3</soft_erp>
            <kp>1000</kp>
            <kd>10</kd>
            <max_vel>100.0</max_vel>
            <min_depth>0.001</min_depth>
          </ode>
        </contact>
      </surface>
    </collision>
    <visual>
      <origin rpy="0 1.570795 0" xyz="0.04 0 0"/>
      <geometry>
        <cylinder length="0.08" radius="0.005"/>
      </geometry>
    </visual>
  </link>
  <!--leg_B_i_3 link-->
  <link name="leg_B_4_3">
    <pose>0 0 0 0 0 0</pose>
    <selfCollide>1</selfCollide>
    <inertial>
      <mass value="0.06"/>
      <origin rpy="0 1.570795 0" xyz="0.03 0 0"/>
      <inertia ixx="0.0003" ixy="0.01" ixz="0.01" iyy="0.01" iyz="0.01" izz="0.0003"/>
    </inertial>
    <collision name="leg_B_4_3">
      <origin rpy="0 1.570795 0" xyz="0.03 0 0"/>
      <geometry>
        <cylinder length="0.036" radius="0.003"/>
      </geometry>
      <surface>
        <contact>
          <poissons_ratio>0.347</poissons_ratio>
          <elastic_modulus>8.8e+09</elastic_modulus>
          <ode>
            <soft_cfm>0.01</soft_cfm>
            <soft_erp>0.3</soft_erp>
            <kp>1000</kp>
            <kd>10</kd>
            <max_vel>100.0</max_vel>
            <min_depth>0.001</min_depth>
          </ode>
        </contact>
      </surface>
    </collision>
    <visual>
      <origin rpy="0 1.570795 0" xyz="0.03 0 0"/>
      <geometry>
        <cylinder length="0.06" radius="0.005"/>
      </geometry>
    </visual>
  </link>
  <!--leg_B_i_4 link-->
  <link name="leg_B_4_4">
    <pose>0 0 0 0 0 0</pose>
    <selfCollide>1</selfCollide>
    <inertial>
      <mass value="0.06"/>
      <origin rpy="0 -1.570795 0" xyz="0.04 0 0"/>
      <inertia ixx="0.0004" ixy="0.01" ixz="0.01" iyy="0.01" iyz="0.01" izz="0.0004"/>
    </inertial>
    <collision name="leg_B_4_4">
      <origin rpy="0 -1.570795 0" xyz="0.04 0 0"/>
      <geometry>
        <cylinder length="0.048" radius="0.003"/>
      </geometry>
    </collision>
    <surface>
      <contact>
        <poissons_ratio>0.347</poissons_ratio>
        <elastic_modulus>8.8e+09</elastic_modulus>
        <ode>
          <soft_cfm>0.01</soft_cfm>
          <soft_erp>0.3</soft_erp>
          <kp>1000</kp>
          <kd>10</kd>
          <max_vel>100.0</max_vel>
          <min_depth>0.001</min_depth>
        </ode>
      </contact>
    </surface>
    <visual>
      <origin rpy="0.0 -1.570795 0" xyz="0.04 0 0"/>
      <geometry>
        <cylinder length="0.08" radius="0.005"/>
      </geometry>
    </visual>
  </link>
  <!--leg_B_i_5 link-->
  <link name="leg_B_4_5">
    <pose>0 0 0 0 0 0</pose>
    <selfCollide>1</selfCollide>
    <inertial>
      <mass value="0.06"/>
      <origin rpy="0 1.570795 0" xyz="0.03 0 0"/>
      <inertia ixx="0.0003" ixy="0.01" ixz="0.01" iyy="0.01" iyz="0.01" izz="0.0003"/>
    </inertial>
    <collision name="leg_B_4_5">
      <origin rpy="0 1.570795 0" xyz="0.03 0 0"/>
      <geometry>
        <cylinder length="0.036" radius="0.003"/>
      </geometry>
      <surface>
        <contact>
          <poissons_ratio>0.347</poissons_ratio>
          <elastic_modulus>8.8e+09</elastic_modulus>
          <ode>
            <soft_cfm>0.01</soft_cfm>
            <soft_erp>0.3</soft_erp>
            <kp>1000</kp>
            <kd>10</kd>
            <max_vel>100.0</max_vel>
            <min_depth>0.001</min_depth>
          </ode>
        </contact>
      </surface>
    </collision>
    <visual>
      <origin rpy="0 1.570795 0" xyz="0.03 0 0"/>
      <geometry>
        <cylinder length="0.06" radius="0.005"/>
      </geometry>
    </visual>
  </link>
  <gazebo reference="folding_fan_link_4">
    <implicitSpringDamper>True</implicitSpringDamper>
    <selfCollide>1</selfCollide>
  </gazebo>
  <gazebo reference="folding_fan_link_4">
    <implicitSpringDamper>True</implicitSpringDamper>
    <selfCollide>1</selfCollide>
  </gazebo>
  <gazebo reference="leg_B_4_0">
    <implicitSpringDamper>True</implicitSpringDamper>
    <selfCollide>1</selfCollide>
  </gazebo>
  <gazebo reference="leg_B_4_1">
    <implicitSpringDamper>True</implicitSpringDamper>
    <selfCollide>1</selfCollide>
  </gazebo>
  <gazebo reference="leg_B_4_2">
    <implicitSpringDamper>True</implicitSpringDamper>
    <selfCollide>1</selfCollide>
  </gazebo>
  <gazebo reference="leg_B_4_3">
    <implicitSpringDamper>True</implicitSpringDamper>
    <selfCollide>1</selfCollide>
  </gazebo>
  <gazebo reference="leg_B_4_4">
    <implicitSpringDamper>True</implicitSpringDamper>
    <selfCollide>1</selfCollide>
  </gazebo>
  <gazebo reference="leg_B_4_5">
    <implicitSpringDamper>True</implicitSpringDamper>
    <selfCollide>1</selfCollide>
  </gazebo>
  <transmission name="tran_1_4_1">
    <type>transmission_interface/SimpleTransmission</type>
    <joint name="q_1_4_1">
      <hardwareInterface>hardware_interface/PositionJointInterface</hardwareInterface>
    </joint>
    <actuator name="motor_1_4_1">
      <hardwareInterface>hardware_interface/PositionJointInterface</hardwareInterface>
      <mechanicalReduction>1</mechanicalReduction>
    </actuator>
  </transmission>
  <transmission name="tran_1_4_2">
    <type>transmission_interface/SimpleTransmission</type>
    <joint name="q_1_4_2">
      <hardwareInterface>hardware_interface/PositionJointInterface</hardwareInterface>
    </joint>
    <actuator name="motor_1_4_2">
      <hardwareInterface>hardware_interface/PositionJointInterface</hardwareInterface>
      <mechanicalReduction>1</mechanicalReduction>
    </actuator>
  </transmission>
  <transmission name="tran_1_4_3">
    <type>transmission_interface/SimpleTransmission</type>
    <joint name="q_1_4_3">
      <hardwareInterface>hardware_interface/PositionJointInterface</hardwareInterface>
    </joint>
    <actuator name="motor_1_4_3">
      <hardwareInterface>hardware_interface/PositionJointInterface</hardwareInterface>
      <mechanicalReduction>1</mechanicalReduction>
    </actuator>
  </transmission>
  <transmission name="tran_1_4_4">
    <type>transmission_interface/SimpleTransmission</type>
    <joint name="q_1_4_4">
      <hardwareInterface>hardware_interface/PositionJointInterface</hardwareInterface>
    </joint>
    <actuator name="motor_1_4_4_">
      <hardwareInterface>hardware_interface/PositionJointInterface</hardwareInterface>
      <mechanicalReduction>1</mechanicalReduction>
    </actuator>
  </transmission>
  <!-- **************************************************************************************************************************************** -->
  <!-- ******* KINEMATIC PROPRIETIS (JOINTS) ******* -->
  <!-- **************************************************************************************************************************************** -->
  <!--base to folding fan bottom joint-->
  <joint name="folding_fan_joint_5" type="fixed">
    <parent link="base_link"/>
    <child link="folding_fan_link_5"/>
    <origin rpy="0 0 5.23595" xyz="0 0 -0.03"/>
    <!--limit effort="0" velocity="0.0" upper="0.0001" lower ="-0.0001" /-->
    <dynamics damping="20.0" friction="1000"/>
    <axis xyz="0 0 1"/>
  </joint>
  <!--q_1_1_0 FIXED-->
  <joint name="q_1_5_0_FIXED" type="fixed">
    <parent link="folding_fan_link_5"/>
    <child link="leg_B_5_1"/>
    <origin rpy="0 0 0" xyz="0.055 0 0"/>
    <dynamics damping="20.0" friction="1000"/>
    <!--limit effort="0" velocity="0.0" upper="0.0001" lower ="-0.0001" /-->
    <axis xyz="0 0 1"/>
  </joint>
  <!--q_1_i_1-->
  <joint name="q_1_5_1" type="revolute">
    <parent link="leg_B_5_1"/>
    <child link="leg_B_5_2"/>
    <origin rpy="0 0 0" xyz="0 0 0"/>
    <limit effort="1.4709975" lower="0" upper="3.14159" velocity="6.178465545"/>
    <dynamics damping="7.0" friction="0.1"/>
    <!--mimic joint="q_c" multiplier="1" offset="0" /-->
    <axis xyz="0 0 1"/>
  </joint>
  <!--q_1_i_2-->
  <joint name="q_1_5_2" type="revolute">
    <parent link="leg_B_5_2"/>
    <child link="leg_B_5_3"/>
    <origin rpy="0 0 0" xyz="0.08 0 0"/>
    <limit effort="1.4709975" lower="-1.570795" upper="1.570795" velocity="6.178465545"/>
    <dynamics damping="0.7" friction="1000"/>
    <axis xyz="0 0 1"/>
  </joint>
  <!--q_1_i_3-->
  <joint name="q_1_5_3" type="revolute">
    <parent link="leg_B_5_3"/>
    <child link="leg_B_5_4"/>
    <origin rpy="0 1.570795 0" xyz="0.06 0 0"/>
    <limit effort="1.765197" lower="-1.570795" upper="1.570795" velocity="6.178465545"/>
    <dynamics damping="7.0" friction="0.10"/>
    <axis xyz="0 1 0"/>
  </joint>
  <!--q_1_i_4-->
  <joint name="q_1_5_4" type="revolute">
    <parent link="leg_B_5_4"/>
    <child link="leg_B_5_5"/>
    <origin rpy="-1.570795 0 0" xyz="0.08 0 0"/>
    <limit effort="1.765197" lower="-1.570795" upper="1.570795" velocity="6.178465545"/>
    <dynamics damping="7.0" friction="0.1"/>
    <axis xyz="0 0 1"/>
  </joint>
  <!-- **************************************************************************************************************************************** -->
  <!-- ******* INERTIAL PROPRIETIS (LINKS) ******* -->
  <!-- **************************************************************************************************************************************** -->
  <!--folding fan robot bottom link-->
  <link name="folding_fan_link_5">
    <pose>0 0 0 0 0 0</pose>
    <selfCollide>1</selfCollide>
    <inertial>
      <mass value="0.8"/>
      <origin rpy="0 0 0" xyz="0 0 0"/>
      <inertia ixx="0.000344066666667" ixy="0.01" ixz="0.01" iyy="0.000344066666667" iyz="0.01" izz="0.00802406666667"/>
    </inertial>
    <visual>
      <origin rpy="0 0 0" xyz="0 0 0"/>
      <geometry>
        <cylinder length="0.019" radius="0.04"/>
      </geometry>
    </visual>
  </link>
  <!--folding fan robot bottom link-->
  <link name="leg_B_5_1">
    <pose>0 0 0 0 0 0</pose>
    <selfCollide>1</selfCollide>
    <inertial>
      <mass value="0.8"/>
      <origin rpy="0 0 0" xyz="0 0 0"/>
      <inertia ixx="6.90666666667e-05" ixy="0.01" ixz="0.01" iyy="6.90666666667e-05" iyz="0.01" izz="0.00302406666667"/>
    </inertial>
    <collision name="leg_B_5_1">
      <origin rpy="0 0 0" xyz="0 0 0"/>
      <geometry>
        <cylinder length="0.0038" radius="0.003"/>
      </geometry>
      <surface>
        <contact>
          <poissons_ratio>0.347</poissons_ratio>
          <elastic_modulus>8.8e+09</elastic_modulus>
          <ode>
            <soft_cfm>0.01</soft_cfm>
            <soft_erp>0.3</soft_erp>
            <kp>1000</kp>
            <kd>10</kd>
            <max_vel>100.0</max_vel>
            <min_depth>0.001</min_depth>
          </ode>
        </contact>
      </surface>
    </collision>
  </link>
  <!--leg_B_i_2 link-->
  <link name="leg_B_5_2">
    <pose>0 0 0 0 0 0</pose>
    <selfCollide>1</selfCollide>
    <inertial>
      <mass value="0.06"/>
      <origin rpy="0 1.570795 0" xyz="0.04 0 0"/>
      <inertia ixx="0.0004" ixy="0.01" ixz="0.01" iyy="0.01" iyz="0.01" izz="0.0004"/>
    </inertial>
    <collision name="leg_B_5_2">
      <origin rpy="0 1.570795 0" xyz="0.04 0 0"/>
      <geometry>
        <cylinder length="0.024" radius="0.003"/>
      </geometry>
      <surface>
        <contact>
          <poissons_ratio>0.347</poissons_ratio>
          <elastic_modulus>8.8e+09</elastic_modulus>
          <ode>
            <soft_cfm>0.01</soft_cfm>
            <soft_erp>0.3</soft_erp>
            <kp>1000</kp>
            <kd>10</kd>
            <max_vel>100.0</max_vel>
            <min_depth>0.001</min_depth>
          </ode>
        </contact>
      </surface>
    </collision>
    <visual>
      <origin rpy="0 1.570795 0" xyz="0.04 0 0"/>
      <geometry>
        <cylinder length="0.08" radius="0.005"/>
      </geometry>
    </visual>
  </link>
  <!--leg_B_i_3 link-->
  <link name="leg_B_5_3">
    <pose>0 0 0 0 0 0</pose>
    <selfCollide>1</selfCollide>
    <inertial>
      <mass value="0.06"/>
      <origin rpy="0 1.570795 0" xyz="0.03 0 0"/>
      <inertia ixx="0.0003" ixy="0.01" ixz="0.01" iyy="0.01" iyz="0.01" izz="0.0003"/>
    </inertial>
    <collision name="leg_B_5_3">
      <origin rpy="0 1.570795 0" xyz="0.03 0 0"/>
      <geometry>
        <cylinder length="0.036" radius="0.003"/>
      </geometry>
      <surface>
        <contact>
          <poissons_ratio>0.347</poissons_ratio>
          <elastic_modulus>8.8e+09</elastic_modulus>
          <ode>
            <soft_cfm>0.01</soft_cfm>
            <soft_erp>0.3</soft_erp>
            <kp>1000</kp>
            <kd>10</kd>
            <max_vel>100.0</max_vel>
            <min_depth>0.001</min_depth>
          </ode>
        </contact>
      </surface>
    </collision>
    <visual>
      <origin rpy="0 1.570795 0" xyz="0.03 0 0"/>
      <geometry>
        <cylinder length="0.06" radius="0.005"/>
      </geometry>
    </visual>
  </link>
  <!--leg_B_i_4 link-->
  <link name="leg_B_5_4">
    <pose>0 0 0 0 0 0</pose>
    <selfCollide>1</selfCollide>
    <inertial>
      <mass value="0.06"/>
      <origin rpy="0 -1.570795 0" xyz="0.04 0 0"/>
      <inertia ixx="0.0004" ixy="0.01" ixz="0.01" iyy="0.01" iyz="0.01" izz="0.0004"/>
    </inertial>
    <collision name="leg_B_5_4">
      <origin rpy="0 -1.570795 0" xyz="0.04 0 0"/>
      <geometry>
        <cylinder length="0.048" radius="0.003"/>
      </geometry>
    </collision>
    <surface>
      <contact>
        <poissons_ratio>0.347</poissons_ratio>
        <elastic_modulus>8.8e+09</elastic_modulus>
        <ode>
          <soft_cfm>0.01</soft_cfm>
          <soft_erp>0.3</soft_erp>
          <kp>1000</kp>
          <kd>10</kd>
          <max_vel>100.0</max_vel>
          <min_depth>0.001</min_depth>
        </ode>
      </contact>
    </surface>
    <visual>
      <origin rpy="0.0 -1.570795 0" xyz="0.04 0 0"/>
      <geometry>
        <cylinder length="0.08" radius="0.005"/>
      </geometry>
    </visual>
  </link>
  <!--leg_B_i_5 link-->
  <link name="leg_B_5_5">
    <pose>0 0 0 0 0 0</pose>
    <selfCollide>1</selfCollide>
    <inertial>
      <mass value="0.06"/>
      <origin rpy="0 1.570795 0" xyz="0.03 0 0"/>
      <inertia ixx="0.0003" ixy="0.01" ixz="0.01" iyy="0.01" iyz="0.01" izz="0.0003"/>
    </inertial>
    <collision name="leg_B_5_5">
      <origin rpy="0 1.570795 0" xyz="0.03 0 0"/>
      <geometry>
        <cylinder length="0.036" radius="0.003"/>
      </geometry>
      <surface>
        <contact>
          <poissons_ratio>0.347</poissons_ratio>
          <elastic_modulus>8.8e+09</elastic_modulus>
          <ode>
            <soft_cfm>0.01</soft_cfm>
            <soft_erp>0.3</soft_erp>
            <kp>1000</kp>
            <kd>10</kd>
            <max_vel>100.0</max_vel>
            <min_depth>0.001</min_depth>
          </ode>
        </contact>
      </surface>
    </collision>
    <visual>
      <origin rpy="0 1.570795 0" xyz="0.03 0 0"/>
      <geometry>
        <cylinder length="0.06" radius="0.005"/>
      </geometry>
    </visual>
  </link>
  <gazebo reference="folding_fan_link_5">
    <implicitSpringDamper>True</implicitSpringDamper>
    <selfCollide>1</selfCollide>
  </gazebo>
  <gazebo reference="folding_fan_link_5">
    <implicitSpringDamper>True</implicitSpringDamper>
    <selfCollide>1</selfCollide>
  </gazebo>
  <gazebo reference="leg_B_5_0">
    <implicitSpringDamper>True</implicitSpringDamper>
    <selfCollide>1</selfCollide>
  </gazebo>
  <gazebo reference="leg_B_5_1">
    <implicitSpringDamper>True</implicitSpringDamper>
    <selfCollide>1</selfCollide>
  </gazebo>
  <gazebo reference="leg_B_5_2">
    <implicitSpringDamper>True</implicitSpringDamper>
    <selfCollide>1</selfCollide>
  </gazebo>
  <gazebo reference="leg_B_5_3">
    <implicitSpringDamper>True</implicitSpringDamper>
    <selfCollide>1</selfCollide>
  </gazebo>
  <gazebo reference="leg_B_5_4">
    <implicitSpringDamper>True</implicitSpringDamper>
    <selfCollide>1</selfCollide>
  </gazebo>
  <gazebo reference="leg_B_5_5">
    <implicitSpringDamper>True</implicitSpringDamper>
    <selfCollide>1</selfCollide>
  </gazebo>
  <transmission name="tran_1_5_1">
    <type>transmission_interface/SimpleTransmission</type>
    <joint name="q_1_5_1">
      <hardwareInterface>hardware_interface/PositionJointInterface</hardwareInterface>
    </joint>
    <actuator name="motor_1_5_1">
      <hardwareInterface>hardware_interface/PositionJointInterface</hardwareInterface>
      <mechanicalReduction>1</mechanicalReduction>
    </actuator>
  </transmission>
  <transmission name="tran_1_5_2">
    <type>transmission_interface/SimpleTransmission</type>
    <joint name="q_1_5_2">
      <hardwareInterface>hardware_interface/PositionJointInterface</hardwareInterface>
    </joint>
    <actuator name="motor_1_5_2">
      <hardwareInterface>hardware_interface/PositionJointInterface</hardwareInterface>
      <mechanicalReduction>1</mechanicalReduction>
    </actuator>
  </transmission>
  <transmission name="tran_1_5_3">
    <type>transmission_interface/SimpleTransmission</type>
    <joint name="q_1_5_3">
      <hardwareInterface>hardware_interface/PositionJointInterface</hardwareInterface>
    </joint>
    <actuator name="motor_1_5_3">
      <hardwareInterface>hardware_interface/PositionJointInterface</hardwareInterface>
      <mechanicalReduction>1</mechanicalReduction>
    </actuator>
  </transmission>
  <transmission name="tran_1_5_4">
    <type>transmission_interface/SimpleTransmission</type>
    <joint name="q_1_5_4">
      <hardwareInterface>hardware_interface/PositionJointInterface</hardwareInterface>
    </joint>
    <actuator name="motor_1_5_4_">
      <hardwareInterface>hardware_interface/PositionJointInterface</hardwareInterface>
      <mechanicalReduction>1</mechanicalReduction>
    </actuator>
  </transmission>
  <!-- **************************************************************************************************************************************** -->
  <!-- ******* KINEMATIC PROPRIETIS (JOINTS) ******* -->
  <!-- **************************************************************************************************************************************** -->
  <!--base to folding fan bottom joint-->
  <joint name="folding_fan_joint_6" type="fixed">
    <parent link="base_link"/>
    <child link="folding_fan_link_6"/>
    <origin rpy="0 0 6.28314" xyz="0 0 -0.03"/>
    <!--limit effort="0" velocity="0.0" upper="0.0001" lower ="-0.0001" /-->
    <dynamics damping="20.0" friction="1000"/>
    <axis xyz="0 0 1"/>
  </joint>
  <!--q_1_1_0 FIXED-->
  <joint name="q_1_6_0_FIXED" type="fixed">
    <parent link="folding_fan_link_6"/>
    <child link="leg_B_6_1"/>
    <origin rpy="0 0 0" xyz="0.055 0 0"/>
    <dynamics damping="20.0" friction="1000"/>
    <!--limit effort="0" velocity="0.0" upper="0.0001" lower ="-0.0001" /-->
    <axis xyz="0 0 1"/>
  </joint>
  <!--q_1_i_1-->
  <joint name="q_1_6_1" type="revolute">
    <parent link="leg_B_6_1"/>
    <child link="leg_B_6_2"/>
    <origin rpy="0 0 0" xyz="0 0 0"/>
    <limit effort="1.4709975" lower="0" upper="3.14159" velocity="6.178465545"/>
    <dynamics damping="7.0" friction="0.1"/>
    <!--mimic joint="q_c" multiplier="1" offset="0" /-->
    <axis xyz="0 0 1"/>
  </joint>
  <!--q_1_i_2-->
  <joint name="q_1_6_2" type="revolute">
    <parent link="leg_B_6_2"/>
    <child link="leg_B_6_3"/>
    <origin rpy="0 0 0" xyz="0.08 0 0"/>
    <limit effort="1.4709975" lower="-1.570795" upper="1.570795" velocity="6.178465545"/>
    <dynamics damping="0.7" friction="1000"/>
    <axis xyz="0 0 1"/>
  </joint>
  <!--q_1_i_3-->
  <joint name="q_1_6_3" type="revolute">
    <parent link="leg_B_6_3"/>
    <child link="leg_B_6_4"/>
    <origin rpy="0 1.570795 0" xyz="0.06 0 0"/>
    <limit effort="1.765197" lower="-1.570795" upper="1.570795" velocity="6.178465545"/>
    <dynamics damping="7.0" friction="0.10"/>
    <axis xyz="0 1 0"/>
  </joint>
  <!--q_1_i_4-->
  <joint name="q_1_6_4" type="revolute">
    <parent link="leg_B_6_4"/>
    <child link="leg_B_6_5"/>
    <origin rpy="-1.570795 0 0" xyz="0.08 0 0"/>
    <limit effort="1.765197" lower="-1.570795" upper="1.570795" velocity="6.178465545"/>
    <dynamics damping="7.0" friction="0.1"/>
    <axis xyz="0 0 1"/>
  </joint>
  <!-- **************************************************************************************************************************************** -->
  <!-- ******* INERTIAL PROPRIETIS (LINKS) ******* -->
  <!-- **************************************************************************************************************************************** -->
  <!--folding fan robot bottom link-->
  <link name="folding_fan_link_6">
    <pose>0 0 0 0 0 0</pose>
    <selfCollide>1</selfCollide>
    <inertial>
      <mass value="0.8"/>
      <origin rpy="0 0 0" xyz="0 0 0"/>
      <inertia ixx="0.000344066666667" ixy="0.01" ixz="0.01" iyy="0.000344066666667" iyz="0.01" izz="0.00802406666667"/>
    </inertial>
    <visual>
      <origin rpy="0 0 0" xyz="0 0 0"/>
      <geometry>
        <cylinder length="0.019" radius="0.04"/>
      </geometry>
    </visual>
  </link>
  <!--folding fan robot bottom link-->
  <link name="leg_B_6_1">
    <pose>0 0 0 0 0 0</pose>
    <selfCollide>1</selfCollide>
    <inertial>
      <mass value="0.8"/>
      <origin rpy="0 0 0" xyz="0 0 0"/>
      <inertia ixx="6.90666666667e-05" ixy="0.01" ixz="0.01" iyy="6.90666666667e-05" iyz="0.01" izz="0.00302406666667"/>
    </inertial>
    <collision name="leg_B_6_1">
      <origin rpy="0 0 0" xyz="0 0 0"/>
      <geometry>
        <cylinder length="0.0038" radius="0.003"/>
      </geometry>
      <surface>
        <contact>
          <poissons_ratio>0.347</poissons_ratio>
          <elastic_modulus>8.8e+09</elastic_modulus>
          <ode>
            <soft_cfm>0.01</soft_cfm>
            <soft_erp>0.3</soft_erp>
            <kp>1000</kp>
            <kd>10</kd>
            <max_vel>100.0</max_vel>
            <min_depth>0.001</min_depth>
          </ode>
        </contact>
      </surface>
    </collision>
  </link>
  <!--leg_B_i_2 link-->
  <link name="leg_B_6_2">
    <pose>0 0 0 0 0 0</pose>
    <selfCollide>1</selfCollide>
    <inertial>
      <mass value="0.06"/>
      <origin rpy="0 1.570795 0" xyz="0.04 0 0"/>
      <inertia ixx="0.0004" ixy="0.01" ixz="0.01" iyy="0.01" iyz="0.01" izz="0.0004"/>
    </inertial>
    <collision name="leg_B_6_2">
      <origin rpy="0 1.570795 0" xyz="0.04 0 0"/>
      <geometry>
        <cylinder length="0.024" radius="0.003"/>
      </geometry>
      <surface>
        <contact>
          <poissons_ratio>0.347</poissons_ratio>
          <elastic_modulus>8.8e+09</elastic_modulus>
          <ode>
            <soft_cfm>0.01</soft_cfm>
            <soft_erp>0.3</soft_erp>
            <kp>1000</kp>
            <kd>10</kd>
            <max_vel>100.0</max_vel>
            <min_depth>0.001</min_depth>
          </ode>
        </contact>
      </surface>
    </collision>
    <visual>
      <origin rpy="0 1.570795 0" xyz="0.04 0 0"/>
      <geometry>
        <cylinder length="0.08" radius="0.005"/>
      </geometry>
    </visual>
  </link>
  <!--leg_B_i_3 link-->
  <link name="leg_B_6_3">
    <pose>0 0 0 0 0 0</pose>
    <selfCollide>1</selfCollide>
    <inertial>
      <mass value="0.06"/>
      <origin rpy="0 1.570795 0" xyz="0.03 0 0"/>
      <inertia ixx="0.0003" ixy="0.01" ixz="0.01" iyy="0.01" iyz="0.01" izz="0.0003"/>
    </inertial>
    <collision name="leg_B_6_3">
      <origin rpy="0 1.570795 0" xyz="0.03 0 0"/>
      <geometry>
        <cylinder length="0.036" radius="0.003"/>
      </geometry>
      <surface>
        <contact>
          <poissons_ratio>0.347</poissons_ratio>
          <elastic_modulus>8.8e+09</elastic_modulus>
          <ode>
            <soft_cfm>0.01</soft_cfm>
            <soft_erp>0.3</soft_erp>
            <kp>1000</kp>
            <kd>10</kd>
            <max_vel>100.0</max_vel>
            <min_depth>0.001</min_depth>
          </ode>
        </contact>
      </surface>
    </collision>
    <visual>
      <origin rpy="0 1.570795 0" xyz="0.03 0 0"/>
      <geometry>
        <cylinder length="0.06" radius="0.005"/>
      </geometry>
    </visual>
  </link>
  <!--leg_B_i_4 link-->
  <link name="leg_B_6_4">
    <pose>0 0 0 0 0 0</pose>
    <selfCollide>1</selfCollide>
    <inertial>
      <mass value="0.06"/>
      <origin rpy="0 -1.570795 0" xyz="0.04 0 0"/>
      <inertia ixx="0.0004" ixy="0.01" ixz="0.01" iyy="0.01" iyz="0.01" izz="0.0004"/>
    </inertial>
    <collision name="leg_B_6_4">
      <origin rpy="0 -1.570795 0" xyz="0.04 0 0"/>
      <geometry>
        <cylinder length="0.048" radius="0.003"/>
      </geometry>
    </collision>
    <surface>
      <contact>
        <poissons_ratio>0.347</poissons_ratio>
        <elastic_modulus>8.8e+09</elastic_modulus>
        <ode>
          <soft_cfm>0.01</soft_cfm>
          <soft_erp>0.3</soft_erp>
          <kp>1000</kp>
          <kd>10</kd>
          <max_vel>100.0</max_vel>
          <min_depth>0.001</min_depth>
        </ode>
      </contact>
    </surface>
    <visual>
      <origin rpy="0.0 -1.570795 0" xyz="0.04 0 0"/>
      <geometry>
        <cylinder length="0.08" radius="0.005"/>
      </geometry>
    </visual>
  </link>
  <!--leg_B_i_5 link-->
  <link name="leg_B_6_5">
    <pose>0 0 0 0 0 0</pose>
    <selfCollide>1</selfCollide>
    <inertial>
      <mass value="0.06"/>
      <origin rpy="0 1.570795 0" xyz="0.03 0 0"/>
      <inertia ixx="0.0003" ixy="0.01" ixz="0.01" iyy="0.01" iyz="0.01" izz="0.0003"/>
    </inertial>
    <collision name="leg_B_6_5">
      <origin rpy="0 1.570795 0" xyz="0.03 0 0"/>
      <geometry>
        <cylinder length="0.036" radius="0.003"/>
      </geometry>
      <surface>
        <contact>
          <poissons_ratio>0.347</poissons_ratio>
          <elastic_modulus>8.8e+09</elastic_modulus>
          <ode>
            <soft_cfm>0.01</soft_cfm>
            <soft_erp>0.3</soft_erp>
            <kp>1000</kp>
            <kd>10</kd>
            <max_vel>100.0</max_vel>
            <min_depth>0.001</min_depth>
          </ode>
        </contact>
      </surface>
    </collision>
    <visual>
      <origin rpy="0 1.570795 0" xyz="0.03 0 0"/>
      <geometry>
        <cylinder length="0.06" radius="0.005"/>
      </geometry>
    </visual>
  </link>
  <gazebo reference="folding_fan_link_6">
    <implicitSpringDamper>True</implicitSpringDamper>
    <selfCollide>1</selfCollide>
  </gazebo>
  <gazebo reference="folding_fan_link_6">
    <implicitSpringDamper>True</implicitSpringDamper>
    <selfCollide>1</selfCollide>
  </gazebo>
  <gazebo reference="leg_B_6_0">
    <implicitSpringDamper>True</implicitSpringDamper>
    <selfCollide>1</selfCollide>
  </gazebo>
  <gazebo reference="leg_B_6_1">
    <implicitSpringDamper>True</implicitSpringDamper>
    <selfCollide>1</selfCollide>
  </gazebo>
  <gazebo reference="leg_B_6_2">
    <implicitSpringDamper>True</implicitSpringDamper>
    <selfCollide>1</selfCollide>
  </gazebo>
  <gazebo reference="leg_B_6_3">
    <implicitSpringDamper>True</implicitSpringDamper>
    <selfCollide>1</selfCollide>
  </gazebo>
  <gazebo reference="leg_B_6_4">
    <implicitSpringDamper>True</implicitSpringDamper>
    <selfCollide>1</selfCollide>
  </gazebo>
  <gazebo reference="leg_B_6_5">
    <implicitSpringDamper>True</implicitSpringDamper>
    <selfCollide>1</selfCollide>
  </gazebo>
  <transmission name="tran_1_6_1">
    <type>transmission_interface/SimpleTransmission</type>
    <joint name="q_1_6_1">
      <hardwareInterface>hardware_interface/PositionJointInterface</hardwareInterface>
    </joint>
    <actuator name="motor_1_6_1">
      <hardwareInterface>hardware_interface/PositionJointInterface</hardwareInterface>
      <mechanicalReduction>1</mechanicalReduction>
    </actuator>
  </transmission>
  <transmission name="tran_1_6_2">
    <type>transmission_interface/SimpleTransmission</type>
    <joint name="q_1_6_2">
      <hardwareInterface>hardware_interface/PositionJointInterface</hardwareInterface>
    </joint>
    <actuator name="motor_1_6_2">
      <hardwareInterface>hardware_interface/PositionJointInterface</hardwareInterface>
      <mechanicalReduction>1</mechanicalReduction>
    </actuator>
  </transmission>
  <transmission name="tran_1_6_3">
    <type>transmission_interface/SimpleTransmission</type>
    <joint name="q_1_6_3">
      <hardwareInterface>hardware_interface/PositionJointInterface</hardwareInterface>
    </joint>
    <actuator name="motor_1_6_3">
      <hardwareInterface>hardware_interface/PositionJointInterface</hardwareInterface>
      <mechanicalReduction>1</mechanicalReduction>
    </actuator>
  </transmission>
  <transmission name="tran_1_6_4">
    <type>transmission_interface/SimpleTransmission</type>
    <joint name="q_1_6_4">
      <hardwareInterface>hardware_interface/PositionJointInterface</hardwareInterface>
    </joint>
    <actuator name="motor_1_6_4_">
      <hardwareInterface>hardware_interface/PositionJointInterface</hardwareInterface>
      <mechanicalReduction>1</mechanicalReduction>
    </actuator>
  </transmission>
  <!--base to folding fan bottom joint-->
  <joint name="folding_fan_upper_joint_1" type="fixed">
    <parent link="base_link"/>
    <child link="FF_link_U_1"/>
    <origin rpy="0 0 1.04719" xyz="0 0 0.09"/>
    <!--limit effort="0" velocity="0.0" upper="0.0001" lower ="-0.0001" /-->
    <dynamics damping="7.0" friction="0.1"/>
  </joint>
  <!--fixed link-->
  <link name="FF_link_U_1">
    <pose>0 0 0 0 0 0</pose>
    <selfCollide>1</selfCollide>
    <origin rpy="0 0 0" xyz="0 0 0"/>
    <surface>
      <contact>
        <poissons_ratio>0.347</poissons_ratio>
        <elastic_modulus>8.8e+09</elastic_modulus>
        <ode>
          <soft_cfm>0.01</soft_cfm>
          <soft_erp>0.3</soft_erp>
          <kp>1000</kp>
          <kd>10</kd>
          <max_vel>100.0</max_vel>
          <min_depth>0.001</min_depth>
        </ode>
      </contact>
    </surface>
    <inertial>
      <mass value="0.1"/>
      <origin rpy="0 0 0" xyz="0 0 0"/>
      <inertia ixx="0.01" ixy="0.01" ixz="0.01" iyy="0.01" iyz="0.01" izz="0.01"/>
    </inertial>
  </link>
  <!--q_2_i_1-->
  <joint name="q_2_1_1" type="revolute">
    <parent link="FF_link_U_1"/>
    <child link="L_U_1_1"/>
    <origin rpy="0 0 0" xyz="0.08 0 0"/>
    <limit effort="1.4709975" lower="-1.570795" upper="1.570795" velocity="6.178465545"/>
    <dynamics damping="7.0" friction="0.1"/>
    <axis xyz="0 1 0"/>
  </joint>
  <!--q_2_i_2-->
  <joint name="q_2_1_2" type="revolute">
    <parent link="L_U_1_1"/>
    <child link="L_U_1_2"/>
    <origin rpy="0 -1.570795 0" xyz="0.06 0 0"/>
    <limit effort="1.4709975" lower="-1.570795" upper="1.570795" velocity="6.178465545"/>
    <dynamics damping="7.0" friction="0.1"/>
    <axis xyz="0 1 0"/>
  </joint>
  <!--leg_U_i_1 link-->
  <link name="L_U_1_1">
    <pose>0 0 0 0 0 0</pose>
    <selfCollide>1</selfCollide>
    <inertial>
      <mass value="0.06"/>
      <origin rpy="0 1.570795 0" xyz="0.03 0 0"/>
      <inertia ixx="0.0003" ixy="0.01" ixz="0.01" iyy="0.01" iyz="0.01" izz="0.0003"/>
    </inertial>
    <collision name="L_U_1_1">
      <origin rpy="0 1.570795 0" xyz="0.03 0 0"/>
      <geometry>
        <cylinder length="0.036" radius="0.003"/>
      </geometry>
      <surface>
        <contact>
          <poissons_ratio>0.347</poissons_ratio>
          <elastic_modulus>8.8e+09</elastic_modulus>
          <ode>
            <soft_cfm>0.001</soft_cfm>
            <soft_erp>0.3</soft_erp>
            <kp>1000</kp>
            <kd>10</kd>
            <max_vel>0.0</max_vel>
            <min_depth>0.1</min_depth>
          </ode>
        </contact>
      </surface>
    </collision>
    <visual>
      <origin rpy="0 1.570795 0" xyz="0.03 0 0"/>
      <geometry>
        <cylinder length="0.06" radius="0.005"/>
      </geometry>
    </visual>
  </link>
  <!--leg_U_i_1 link-->
  <link name="L_U_1_2">
    <pose>0 0 0 0 0 0</pose>
    <selfCollide>1</selfCollide>
    <inertial>
      <mass value="0.06"/>
      <origin rpy="0 1.570795 0" xyz="0.03 0 0"/>
      <inertia ixx="0.0003" ixy="0.01" ixz="0.01" iyy="0.01" iyz="0.01" izz="0.0003"/>
    </inertial>
    <collision name="L_U_1_2">
      <origin rpy="0 1.570795 0" xyz="0.03 0 0"/>
      <geometry>
        <cylinder length="0.036" radius="0.003"/>
      </geometry>
      <surface>
        <contact>
          <poissons_ratio>0.347</poissons_ratio>
          <elastic_modulus>8.8e+09</elastic_modulus>
          <ode>
            <soft_cfm>0.01</soft_cfm>
            <soft_erp>0.3</soft_erp>
            <kp>1000</kp>
            <kd>10</kd>
            <max_vel>100.0</max_vel>
            <min_depth>0.1</min_depth>
          </ode>
        </contact>
      </surface>
    </collision>
    <visual>
      <origin rpy="0 1.570795 0" xyz="0.03 0 0"/>
      <geometry>
        <cylinder length="0.06" radius="0.005"/>
      </geometry>
    </visual>
  </link>
  <gazebo reference="FF_link_U_1">
    <implicitSpringDamper>True</implicitSpringDamper>
    <selfCollide>1</selfCollide>
  </gazebo>
  <gazebo reference="leg_U_1_1">
    <implicitSpringDamper>True</implicitSpringDamper>
    <selfCollide>1</selfCollide>
  </gazebo>
  <gazebo reference="leg_U_1_2">
    <implicitSpringDamper>True</implicitSpringDamper>
    <selfCollide>1</selfCollide>
  </gazebo>
  <transmission name="tran_2_1_1">
    <type>transmission_interface/SimpleTransmission</type>
    <joint name="q_2_1_1">
      <hardwareInterface>hardware_interface/PositionJointInterface</hardwareInterface>
    </joint>
    <actuator name="motor_2_1_1">
      <hardwareInterface>hardware_interface/PositionJointInterface</hardwareInterface>
      <mechanicalReduction>1</mechanicalReduction>
    </actuator>
  </transmission>
  <transmission name="tran_2_1_2">
    <type>transmission_interface/SimpleTransmission</type>
    <joint name="q_2_1_2">
      <hardwareInterface>hardware_interface/PositionJointInterface</hardwareInterface>
    </joint>
    <actuator name="motor_2_1_2">
      <hardwareInterface>hardware_interface/PositionJointInterface</hardwareInterface>
      <mechanicalReduction>1</mechanicalReduction>
    </actuator>
  </transmission>
  <!--base to folding fan bottom joint-->
  <joint name="folding_fan_upper_joint_2" type="fixed">
    <parent link="base_link"/>
    <child link="FF_link_U_2"/>
    <origin rpy="0 0 2.09438" xyz="0 0 0.09"/>
    <!--limit effort="0" velocity="0.0" upper="0.0001" lower ="-0.0001" /-->
    <dynamics damping="7.0" friction="0.1"/>
  </joint>
  <!--fixed link-->
  <link name="FF_link_U_2">
    <pose>0 0 0 0 0 0</pose>
    <selfCollide>1</selfCollide>
    <origin rpy="0 0 0" xyz="0 0 0"/>
    <surface>
      <contact>
        <poissons_ratio>0.347</poissons_ratio>
        <elastic_modulus>8.8e+09</elastic_modulus>
        <ode>
          <soft_cfm>0.01</soft_cfm>
          <soft_erp>0.3</soft_erp>
          <kp>1000</kp>
          <kd>10</kd>
          <max_vel>100.0</max_vel>
          <min_depth>0.001</min_depth>
        </ode>
      </contact>
    </surface>
    <inertial>
      <mass value="0.1"/>
      <origin rpy="0 0 0" xyz="0 0 0"/>
      <inertia ixx="0.01" ixy="0.01" ixz="0.01" iyy="0.01" iyz="0.01" izz="0.01"/>
    </inertial>
  </link>
  <!--q_2_i_1-->
  <joint name="q_2_2_1" type="revolute">
    <parent link="FF_link_U_2"/>
    <child link="L_U_2_1"/>
    <origin rpy="0 0 0" xyz="0.08 0 0"/>
    <limit effort="1.4709975" lower="-1.570795" upper="1.570795" velocity="6.178465545"/>
    <dynamics damping="7.0" friction="0.1"/>
    <axis xyz="0 1 0"/>
  </joint>
  <!--q_2_i_2-->
  <joint name="q_2_2_2" type="revolute">
    <parent link="L_U_2_1"/>
    <child link="L_U_2_2"/>
    <origin rpy="0 -1.570795 0" xyz="0.06 0 0"/>
    <limit effort="1.4709975" lower="-1.570795" upper="1.570795" velocity="6.178465545"/>
    <dynamics damping="7.0" friction="0.1"/>
    <axis xyz="0 1 0"/>
  </joint>
  <!--leg_U_i_1 link-->
  <link name="L_U_2_1">
    <pose>0 0 0 0 0 0</pose>
    <selfCollide>1</selfCollide>
    <inertial>
      <mass value="0.06"/>
      <origin rpy="0 1.570795 0" xyz="0.03 0 0"/>
      <inertia ixx="0.0003" ixy="0.01" ixz="0.01" iyy="0.01" iyz="0.01" izz="0.0003"/>
    </inertial>
    <collision name="L_U_2_1">
      <origin rpy="0 1.570795 0" xyz="0.03 0 0"/>
      <geometry>
        <cylinder length="0.036" radius="0.003"/>
      </geometry>
      <surface>
        <contact>
          <poissons_ratio>0.347</poissons_ratio>
          <elastic_modulus>8.8e+09</elastic_modulus>
          <ode>
            <soft_cfm>0.001</soft_cfm>
            <soft_erp>0.3</soft_erp>
            <kp>1000</kp>
            <kd>10</kd>
            <max_vel>0.0</max_vel>
            <min_depth>0.1</min_depth>
          </ode>
        </contact>
      </surface>
    </collision>
    <visual>
      <origin rpy="0 1.570795 0" xyz="0.03 0 0"/>
      <geometry>
        <cylinder length="0.06" radius="0.005"/>
      </geometry>
    </visual>
  </link>
  <!--leg_U_i_1 link-->
  <link name="L_U_2_2">
    <pose>0 0 0 0 0 0</pose>
    <selfCollide>1</selfCollide>
    <inertial>
      <mass value="0.06"/>
      <origin rpy="0 1.570795 0" xyz="0.03 0 0"/>
      <inertia ixx="0.0003" ixy="0.01" ixz="0.01" iyy="0.01" iyz="0.01" izz="0.0003"/>
    </inertial>
    <collision name="L_U_2_2">
      <origin rpy="0 1.570795 0" xyz="0.03 0 0"/>
      <geometry>
        <cylinder length="0.036" radius="0.003"/>
      </geometry>
      <surface>
        <contact>
          <poissons_ratio>0.347</poissons_ratio>
          <elastic_modulus>8.8e+09</elastic_modulus>
          <ode>
            <soft_cfm>0.01</soft_cfm>
            <soft_erp>0.3</soft_erp>
            <kp>1000</kp>
            <kd>10</kd>
            <max_vel>100.0</max_vel>
            <min_depth>0.1</min_depth>
          </ode>
        </contact>
      </surface>
    </collision>
    <visual>
      <origin rpy="0 1.570795 0" xyz="0.03 0 0"/>
      <geometry>
        <cylinder length="0.06" radius="0.005"/>
      </geometry>
    </visual>
  </link>
  <gazebo reference="FF_link_U_2">
    <implicitSpringDamper>True</implicitSpringDamper>
    <selfCollide>1</selfCollide>
  </gazebo>
  <gazebo reference="leg_U_2_1">
    <implicitSpringDamper>True</implicitSpringDamper>
    <selfCollide>1</selfCollide>
  </gazebo>
  <gazebo reference="leg_U_2_2">
    <implicitSpringDamper>True</implicitSpringDamper>
    <selfCollide>1</selfCollide>
  </gazebo>
  <transmission name="tran_2_2_1">
    <type>transmission_interface/SimpleTransmission</type>
    <joint name="q_2_2_1">
      <hardwareInterface>hardware_interface/PositionJointInterface</hardwareInterface>
    </joint>
    <actuator name="motor_2_2_1">
      <hardwareInterface>hardware_interface/PositionJointInterface</hardwareInterface>
      <mechanicalReduction>1</mechanicalReduction>
    </actuator>
  </transmission>
  <transmission name="tran_2_2_2">
    <type>transmission_interface/SimpleTransmission</type>
    <joint name="q_2_2_2">
      <hardwareInterface>hardware_interface/PositionJointInterface</hardwareInterface>
    </joint>
    <actuator name="motor_2_2_2">
      <hardwareInterface>hardware_interface/PositionJointInterface</hardwareInterface>
      <mechanicalReduction>1</mechanicalReduction>
    </actuator>
  </transmission>
  <!--base to folding fan bottom joint-->
  <joint name="folding_fan_upper_joint_3" type="fixed">
    <parent link="base_link"/>
    <child link="FF_link_U_3"/>
    <origin rpy="0 0 3.14157" xyz="0 0 0.09"/>
    <!--limit effort="0" velocity="0.0" upper="0.0001" lower ="-0.0001" /-->
    <dynamics damping="7.0" friction="0.1"/>
  </joint>
  <!--fixed link-->
  <link name="FF_link_U_3">
    <pose>0 0 0 0 0 0</pose>
    <selfCollide>1</selfCollide>
    <origin rpy="0 0 0" xyz="0 0 0"/>
    <surface>
      <contact>
        <poissons_ratio>0.347</poissons_ratio>
        <elastic_modulus>8.8e+09</elastic_modulus>
        <ode>
          <soft_cfm>0.01</soft_cfm>
          <soft_erp>0.3</soft_erp>
          <kp>1000</kp>
          <kd>10</kd>
          <max_vel>100.0</max_vel>
          <min_depth>0.001</min_depth>
        </ode>
      </contact>
    </surface>
    <inertial>
      <mass value="0.1"/>
      <origin rpy="0 0 0" xyz="0 0 0"/>
      <inertia ixx="0.01" ixy="0.01" ixz="0.01" iyy="0.01" iyz="0.01" izz="0.01"/>
    </inertial>
  </link>
  <!--q_2_i_1-->
  <joint name="q_2_3_1" type="revolute">
    <parent link="FF_link_U_3"/>
    <child link="L_U_3_1"/>
    <origin rpy="0 0 0" xyz="0.08 0 0"/>
    <limit effort="1.4709975" lower="-1.570795" upper="1.570795" velocity="6.178465545"/>
    <dynamics damping="7.0" friction="0.1"/>
    <axis xyz="0 1 0"/>
  </joint>
  <!--q_2_i_2-->
  <joint name="q_2_3_2" type="revolute">
    <parent link="L_U_3_1"/>
    <child link="L_U_3_2"/>
    <origin rpy="0 -1.570795 0" xyz="0.06 0 0"/>
    <limit effort="1.4709975" lower="-1.570795" upper="1.570795" velocity="6.178465545"/>
    <dynamics damping="7.0" friction="0.1"/>
    <axis xyz="0 1 0"/>
  </joint>
  <!--leg_U_i_1 link-->
  <link name="L_U_3_1">
    <pose>0 0 0 0 0 0</pose>
    <selfCollide>1</selfCollide>
    <inertial>
      <mass value="0.06"/>
      <origin rpy="0 1.570795 0" xyz="0.03 0 0"/>
      <inertia ixx="0.0003" ixy="0.01" ixz="0.01" iyy="0.01" iyz="0.01" izz="0.0003"/>
    </inertial>
    <collision name="L_U_3_1">
      <origin rpy="0 1.570795 0" xyz="0.03 0 0"/>
      <geometry>
        <cylinder length="0.036" radius="0.003"/>
      </geometry>
      <surface>
        <contact>
          <poissons_ratio>0.347</poissons_ratio>
          <elastic_modulus>8.8e+09</elastic_modulus>
          <ode>
            <soft_cfm>0.001</soft_cfm>
            <soft_erp>0.3</soft_erp>
            <kp>1000</kp>
            <kd>10</kd>
            <max_vel>0.0</max_vel>
            <min_depth>0.1</min_depth>
          </ode>
        </contact>
      </surface>
    </collision>
    <visual>
      <origin rpy="0 1.570795 0" xyz="0.03 0 0"/>
      <geometry>
        <cylinder length="0.06" radius="0.005"/>
      </geometry>
    </visual>
  </link>
  <!--leg_U_i_1 link-->
  <link name="L_U_3_2">
    <pose>0 0 0 0 0 0</pose>
    <selfCollide>1</selfCollide>
    <inertial>
      <mass value="0.06"/>
      <origin rpy="0 1.570795 0" xyz="0.03 0 0"/>
      <inertia ixx="0.0003" ixy="0.01" ixz="0.01" iyy="0.01" iyz="0.01" izz="0.0003"/>
    </inertial>
    <collision name="L_U_3_2">
      <origin rpy="0 1.570795 0" xyz="0.03 0 0"/>
      <geometry>
        <cylinder length="0.036" radius="0.003"/>
      </geometry>
      <surface>
        <contact>
          <poissons_ratio>0.347</poissons_ratio>
          <elastic_modulus>8.8e+09</elastic_modulus>
          <ode>
            <soft_cfm>0.01</soft_cfm>
            <soft_erp>0.3</soft_erp>
            <kp>1000</kp>
            <kd>10</kd>
            <max_vel>100.0</max_vel>
            <min_depth>0.1</min_depth>
          </ode>
        </contact>
      </surface>
    </collision>
    <visual>
      <origin rpy="0 1.570795 0" xyz="0.03 0 0"/>
      <geometry>
        <cylinder length="0.06" radius="0.005"/>
      </geometry>
    </visual>
  </link>
  <gazebo reference="FF_link_U_3">
    <implicitSpringDamper>True</implicitSpringDamper>
    <selfCollide>1</selfCollide>
  </gazebo>
  <gazebo reference="leg_U_3_1">
    <implicitSpringDamper>True</implicitSpringDamper>
    <selfCollide>1</selfCollide>
  </gazebo>
  <gazebo reference="leg_U_3_2">
    <implicitSpringDamper>True</implicitSpringDamper>
    <selfCollide>1</selfCollide>
  </gazebo>
  <transmission name="tran_2_3_1">
    <type>transmission_interface/SimpleTransmission</type>
    <joint name="q_2_3_1">
      <hardwareInterface>hardware_interface/PositionJointInterface</hardwareInterface>
    </joint>
    <actuator name="motor_2_3_1">
      <hardwareInterface>hardware_interface/PositionJointInterface</hardwareInterface>
      <mechanicalReduction>1</mechanicalReduction>
    </actuator>
  </transmission>
  <transmission name="tran_2_3_2">
    <type>transmission_interface/SimpleTransmission</type>
    <joint name="q_2_3_2">
      <hardwareInterface>hardware_interface/PositionJointInterface</hardwareInterface>
    </joint>
    <actuator name="motor_2_3_2">
      <hardwareInterface>hardware_interface/PositionJointInterface</hardwareInterface>
      <mechanicalReduction>1</mechanicalReduction>
    </actuator>
  </transmission>
  <!--base to folding fan bottom joint-->
  <joint name="folding_fan_upper_joint_4" type="fixed">
    <parent link="base_link"/>
    <child link="FF_link_U_4"/>
    <origin rpy="0 0 4.18876" xyz="0 0 0.09"/>
    <!--limit effort="0" velocity="0.0" upper="0.0001" lower ="-0.0001" /-->
    <dynamics damping="7.0" friction="0.1"/>
  </joint>
  <!--fixed link-->
  <link name="FF_link_U_4">
    <pose>0 0 0 0 0 0</pose>
    <selfCollide>1</selfCollide>
    <origin rpy="0 0 0" xyz="0 0 0"/>
    <surface>
      <contact>
        <poissons_ratio>0.347</poissons_ratio>
        <elastic_modulus>8.8e+09</elastic_modulus>
        <ode>
          <soft_cfm>0.01</soft_cfm>
          <soft_erp>0.3</soft_erp>
          <kp>1000</kp>
          <kd>10</kd>
          <max_vel>100.0</max_vel>
          <min_depth>0.001</min_depth>
        </ode>
      </contact>
    </surface>
    <inertial>
      <mass value="0.1"/>
      <origin rpy="0 0 0" xyz="0 0 0"/>
      <inertia ixx="0.01" ixy="0.01" ixz="0.01" iyy="0.01" iyz="0.01" izz="0.01"/>
    </inertial>
  </link>
  <!--q_2_i_1-->
  <joint name="q_2_4_1" type="revolute">
    <parent link="FF_link_U_4"/>
    <child link="L_U_4_1"/>
    <origin rpy="0 0 0" xyz="0.08 0 0"/>
    <limit effort="1.4709975" lower="-1.570795" upper="1.570795" velocity="6.178465545"/>
    <dynamics damping="7.0" friction="0.1"/>
    <axis xyz="0 1 0"/>
  </joint>
  <!--q_2_i_2-->
  <joint name="q_2_4_2" type="revolute">
    <parent link="L_U_4_1"/>
    <child link="L_U_4_2"/>
    <origin rpy="0 -1.570795 0" xyz="0.06 0 0"/>
    <limit effort="1.4709975" lower="-1.570795" upper="1.570795" velocity="6.178465545"/>
    <dynamics damping="7.0" friction="0.1"/>
    <axis xyz="0 1 0"/>
  </joint>
  <!--leg_U_i_1 link-->
  <link name="L_U_4_1">
    <pose>0 0 0 0 0 0</pose>
    <selfCollide>1</selfCollide>
    <inertial>
      <mass value="0.06"/>
      <origin rpy="0 1.570795 0" xyz="0.03 0 0"/>
      <inertia ixx="0.0003" ixy="0.01" ixz="0.01" iyy="0.01" iyz="0.01" izz="0.0003"/>
    </inertial>
    <collision name="L_U_4_1">
      <origin rpy="0 1.570795 0" xyz="0.03 0 0"/>
      <geometry>
        <cylinder length="0.036" radius="0.003"/>
      </geometry>
      <surface>
        <contact>
          <poissons_ratio>0.347</poissons_ratio>
          <elastic_modulus>8.8e+09</elastic_modulus>
          <ode>
            <soft_cfm>0.001</soft_cfm>
            <soft_erp>0.3</soft_erp>
            <kp>1000</kp>
            <kd>10</kd>
            <max_vel>0.0</max_vel>
            <min_depth>0.1</min_depth>
          </ode>
        </contact>
      </surface>
    </collision>
    <visual>
      <origin rpy="0 1.570795 0" xyz="0.03 0 0"/>
      <geometry>
        <cylinder length="0.06" radius="0.005"/>
      </geometry>
    </visual>
  </link>
  <!--leg_U_i_1 link-->
  <link name="L_U_4_2">
    <pose>0 0 0 0 0 0</pose>
    <selfCollide>1</selfCollide>
    <inertial>
      <mass value="0.06"/>
      <origin rpy="0 1.570795 0" xyz="0.03 0 0"/>
      <inertia ixx="0.0003" ixy="0.01" ixz="0.01" iyy="0.01" iyz="0.01" izz="0.0003"/>
    </inertial>
    <collision name="L_U_4_2">
      <origin rpy="0 1.570795 0" xyz="0.03 0 0"/>
      <geometry>
        <cylinder length="0.036" radius="0.003"/>
      </geometry>
      <surface>
        <contact>
          <poissons_ratio>0.347</poissons_ratio>
          <elastic_modulus>8.8e+09</elastic_modulus>
          <ode>
            <soft_cfm>0.01</soft_cfm>
            <soft_erp>0.3</soft_erp>
            <kp>1000</kp>
            <kd>10</kd>
            <max_vel>100.0</max_vel>
            <min_depth>0.1</min_depth>
          </ode>
        </contact>
      </surface>
    </collision>
    <visual>
      <origin rpy="0 1.570795 0" xyz="0.03 0 0"/>
      <geometry>
        <cylinder length="0.06" radius="0.005"/>
      </geometry>
    </visual>
  </link>
  <gazebo reference="FF_link_U_4">
    <implicitSpringDamper>True</implicitSpringDamper>
    <selfCollide>1</selfCollide>
  </gazebo>
  <gazebo reference="leg_U_4_1">
    <implicitSpringDamper>True</implicitSpringDamper>
    <selfCollide>1</selfCollide>
  </gazebo>
  <gazebo reference="leg_U_4_2">
    <implicitSpringDamper>True</implicitSpringDamper>
    <selfCollide>1</selfCollide>
  </gazebo>
  <transmission name="tran_2_4_1">
    <type>transmission_interface/SimpleTransmission</type>
    <joint name="q_2_4_1">
      <hardwareInterface>hardware_interface/PositionJointInterface</hardwareInterface>
    </joint>
    <actuator name="motor_2_4_1">
      <hardwareInterface>hardware_interface/PositionJointInterface</hardwareInterface>
      <mechanicalReduction>1</mechanicalReduction>
    </actuator>
  </transmission>
  <transmission name="tran_2_4_2">
    <type>transmission_interface/SimpleTransmission</type>
    <joint name="q_2_4_2">
      <hardwareInterface>hardware_interface/PositionJointInterface</hardwareInterface>
    </joint>
    <actuator name="motor_2_4_2">
      <hardwareInterface>hardware_interface/PositionJointInterface</hardwareInterface>
      <mechanicalReduction>1</mechanicalReduction>
    </actuator>
  </transmission>
  <!--base to folding fan bottom joint-->
  <joint name="folding_fan_upper_joint_5" type="fixed">
    <parent link="base_link"/>
    <child link="FF_link_U_5"/>
    <origin rpy="0 0 5.23595" xyz="0 0 0.09"/>
    <!--limit effort="0" velocity="0.0" upper="0.0001" lower ="-0.0001" /-->
    <dynamics damping="7.0" friction="0.1"/>
  </joint>
  <!--fixed link-->
  <link name="FF_link_U_5">
    <pose>0 0 0 0 0 0</pose>
    <selfCollide>1</selfCollide>
    <origin rpy="0 0 0" xyz="0 0 0"/>
    <surface>
      <contact>
        <poissons_ratio>0.347</poissons_ratio>
        <elastic_modulus>8.8e+09</elastic_modulus>
        <ode>
          <soft_cfm>0.01</soft_cfm>
          <soft_erp>0.3</soft_erp>
          <kp>1000</kp>
          <kd>10</kd>
          <max_vel>100.0</max_vel>
          <min_depth>0.001</min_depth>
        </ode>
      </contact>
    </surface>
    <inertial>
      <mass value="0.1"/>
      <origin rpy="0 0 0" xyz="0 0 0"/>
      <inertia ixx="0.01" ixy="0.01" ixz="0.01" iyy="0.01" iyz="0.01" izz="0.01"/>
    </inertial>
  </link>
  <!--q_2_i_1-->
  <joint name="q_2_5_1" type="revolute">
    <parent link="FF_link_U_5"/>
    <child link="L_U_5_1"/>
    <origin rpy="0 0 0" xyz="0.08 0 0"/>
    <limit effort="1.4709975" lower="-1.570795" upper="1.570795" velocity="6.178465545"/>
    <dynamics damping="7.0" friction="0.1"/>
    <axis xyz="0 1 0"/>
  </joint>
  <!--q_2_i_2-->
  <joint name="q_2_5_2" type="revolute">
    <parent link="L_U_5_1"/>
    <child link="L_U_5_2"/>
    <origin rpy="0 -1.570795 0" xyz="0.06 0 0"/>
    <limit effort="1.4709975" lower="-1.570795" upper="1.570795" velocity="6.178465545"/>
    <dynamics damping="7.0" friction="0.1"/>
    <axis xyz="0 1 0"/>
  </joint>
  <!--leg_U_i_1 link-->
  <link name="L_U_5_1">
    <pose>0 0 0 0 0 0</pose>
    <selfCollide>1</selfCollide>
    <inertial>
      <mass value="0.06"/>
      <origin rpy="0 1.570795 0" xyz="0.03 0 0"/>
      <inertia ixx="0.0003" ixy="0.01" ixz="0.01" iyy="0.01" iyz="0.01" izz="0.0003"/>
    </inertial>
    <collision name="L_U_5_1">
      <origin rpy="0 1.570795 0" xyz="0.03 0 0"/>
      <geometry>
        <cylinder length="0.036" radius="0.003"/>
      </geometry>
      <surface>
        <contact>
          <poissons_ratio>0.347</poissons_ratio>
          <elastic_modulus>8.8e+09</elastic_modulus>
          <ode>
            <soft_cfm>0.001</soft_cfm>
            <soft_erp>0.3</soft_erp>
            <kp>1000</kp>
            <kd>10</kd>
            <max_vel>0.0</max_vel>
            <min_depth>0.1</min_depth>
          </ode>
        </contact>
      </surface>
    </collision>
    <visual>
      <origin rpy="0 1.570795 0" xyz="0.03 0 0"/>
      <geometry>
        <cylinder length="0.06" radius="0.005"/>
      </geometry>
    </visual>
  </link>
  <!--leg_U_i_1 link-->
  <link name="L_U_5_2">
    <pose>0 0 0 0 0 0</pose>
    <selfCollide>1</selfCollide>
    <inertial>
      <mass value="0.06"/>
      <origin rpy="0 1.570795 0" xyz="0.03 0 0"/>
      <inertia ixx="0.0003" ixy="0.01" ixz="0.01" iyy="0.01" iyz="0.01" izz="0.0003"/>
    </inertial>
    <collision name="L_U_5_2">
      <origin rpy="0 1.570795 0" xyz="0.03 0 0"/>
      <geometry>
        <cylinder length="0.036" radius="0.003"/>
      </geometry>
      <surface>
        <contact>
          <poissons_ratio>0.347</poissons_ratio>
          <elastic_modulus>8.8e+09</elastic_modulus>
          <ode>
            <soft_cfm>0.01</soft_cfm>
            <soft_erp>0.3</soft_erp>
            <kp>1000</kp>
            <kd>10</kd>
            <max_vel>100.0</max_vel>
            <min_depth>0.1</min_depth>
          </ode>
        </contact>
      </surface>
    </collision>
    <visual>
      <origin rpy="0 1.570795 0" xyz="0.03 0 0"/>
      <geometry>
        <cylinder length="0.06" radius="0.005"/>
      </geometry>
    </visual>
  </link>
  <gazebo reference="FF_link_U_5">
    <implicitSpringDamper>True</implicitSpringDamper>
    <selfCollide>1</selfCollide>
  </gazebo>
  <gazebo reference="leg_U_5_1">
    <implicitSpringDamper>True</implicitSpringDamper>
    <selfCollide>1</selfCollide>
  </gazebo>
  <gazebo reference="leg_U_5_2">
    <implicitSpringDamper>True</implicitSpringDamper>
    <selfCollide>1</selfCollide>
  </gazebo>
  <transmission name="tran_2_5_1">
    <type>transmission_interface/SimpleTransmission</type>
    <joint name="q_2_5_1">
      <hardwareInterface>hardware_interface/PositionJointInterface</hardwareInterface>
    </joint>
    <actuator name="motor_2_5_1">
      <hardwareInterface>hardware_interface/PositionJointInterface</hardwareInterface>
      <mechanicalReduction>1</mechanicalReduction>
    </actuator>
  </transmission>
  <transmission name="tran_2_5_2">
    <type>transmission_interface/SimpleTransmission</type>
    <joint name="q_2_5_2">
      <hardwareInterface>hardware_interface/PositionJointInterface</hardwareInterface>
    </joint>
    <actuator name="motor_2_5_2">
      <hardwareInterface>hardware_interface/PositionJointInterface</hardwareInterface>
      <mechanicalReduction>1</mechanicalReduction>
    </actuator>
  </transmission>
  <!--base to folding fan bottom joint-->
  <joint name="folding_fan_upper_joint_6" type="fixed">
    <parent link="base_link"/>
    <child link="FF_link_U_6"/>
    <origin rpy="0 0 6.28314" xyz="0 0 0.09"/>
    <!--limit effort="0" velocity="0.0" upper="0.0001" lower ="-0.0001" /-->
    <dynamics damping="7.0" friction="0.1"/>
  </joint>
  <!--fixed link-->
  <link name="FF_link_U_6">
    <pose>0 0 0 0 0 0</pose>
    <selfCollide>1</selfCollide>
    <origin rpy="0 0 0" xyz="0 0 0"/>
    <surface>
      <contact>
        <poissons_ratio>0.347</poissons_ratio>
        <elastic_modulus>8.8e+09</elastic_modulus>
        <ode>
          <soft_cfm>0.01</soft_cfm>
          <soft_erp>0.3</soft_erp>
          <kp>1000</kp>
          <kd>10</kd>
          <max_vel>100.0</max_vel>
          <min_depth>0.001</min_depth>
        </ode>
      </contact>
    </surface>
    <inertial>
      <mass value="0.1"/>
      <origin rpy="0 0 0" xyz="0 0 0"/>
      <inertia ixx="0.01" ixy="0.01" ixz="0.01" iyy="0.01" iyz="0.01" izz="0.01"/>
    </inertial>
  </link>
  <!--q_2_i_1-->
  <joint name="q_2_6_1" type="revolute">
    <parent link="FF_link_U_6"/>
    <child link="L_U_6_1"/>
    <origin rpy="0 0 0" xyz="0.08 0 0"/>
    <limit effort="1.4709975" lower="-1.570795" upper="1.570795" velocity="6.178465545"/>
    <dynamics damping="7.0" friction="0.1"/>
    <axis xyz="0 1 0"/>
  </joint>
  <!--q_2_i_2-->
  <joint name="q_2_6_2" type="revolute">
    <parent link="L_U_6_1"/>
    <child link="L_U_6_2"/>
    <origin rpy="0 -1.570795 0" xyz="0.06 0 0"/>
    <limit effort="1.4709975" lower="-1.570795" upper="1.570795" velocity="6.178465545"/>
    <dynamics damping="7.0" friction="0.1"/>
    <axis xyz="0 1 0"/>
  </joint>
  <!--leg_U_i_1 link-->
  <link name="L_U_6_1">
    <pose>0 0 0 0 0 0</pose>
    <selfCollide>1</selfCollide>
    <inertial>
      <mass value="0.06"/>
      <origin rpy="0 1.570795 0" xyz="0.03 0 0"/>
      <inertia ixx="0.0003" ixy="0.01" ixz="0.01" iyy="0.01" iyz="0.01" izz="0.0003"/>
    </inertial>
    <collision name="L_U_6_1">
      <origin rpy="0 1.570795 0" xyz="0.03 0 0"/>
      <geometry>
        <cylinder length="0.036" radius="0.003"/>
      </geometry>
      <surface>
        <contact>
          <poissons_ratio>0.347</poissons_ratio>
          <elastic_modulus>8.8e+09</elastic_modulus>
          <ode>
            <soft_cfm>0.001</soft_cfm>
            <soft_erp>0.3</soft_erp>
            <kp>1000</kp>
            <kd>10</kd>
            <max_vel>0.0</max_vel>
            <min_depth>0.1</min_depth>
          </ode>
        </contact>
      </surface>
    </collision>
    <visual>
      <origin rpy="0 1.570795 0" xyz="0.03 0 0"/>
      <geometry>
        <cylinder length="0.06" radius="0.005"/>
      </geometry>
    </visual>
  </link>
  <!--leg_U_i_1 link-->
  <link name="L_U_6_2">
    <pose>0 0 0 0 0 0</pose>
    <selfCollide>1</selfCollide>
    <inertial>
      <mass value="0.06"/>
      <origin rpy="0 1.570795 0" xyz="0.03 0 0"/>
      <inertia ixx="0.0003" ixy="0.01" ixz="0.01" iyy="0.01" iyz="0.01" izz="0.0003"/>
    </inertial>
    <collision name="L_U_6_2">
      <origin rpy="0 1.570795 0" xyz="0.03 0 0"/>
      <geometry>
        <cylinder length="0.036" radius="0.003"/>
      </geometry>
      <surface>
        <contact>
          <poissons_ratio>0.347</poissons_ratio>
          <elastic_modulus>8.8e+09</elastic_modulus>
          <ode>
            <soft_cfm>0.01</soft_cfm>
            <soft_erp>0.3</soft_erp>
            <kp>1000</kp>
            <kd>10</kd>
            <max_vel>100.0</max_vel>
            <min_depth>0.1</min_depth>
          </ode>
        </contact>
      </surface>
    </collision>
    <visual>
      <origin rpy="0 1.570795 0" xyz="0.03 0 0"/>
      <geometry>
        <cylinder length="0.06" radius="0.005"/>
      </geometry>
    </visual>
  </link>
  <gazebo reference="FF_link_U_6">
    <implicitSpringDamper>True</implicitSpringDamper>
    <selfCollide>1</selfCollide>
  </gazebo>
  <gazebo reference="leg_U_6_1">
    <implicitSpringDamper>True</implicitSpringDamper>
    <selfCollide>1</selfCollide>
  </gazebo>
  <gazebo reference="leg_U_6_2">
    <implicitSpringDamper>True</implicitSpringDamper>
    <selfCollide>1</selfCollide>
  </gazebo>
  <transmission name="tran_2_6_1">
    <type>transmission_interface/SimpleTransmission</type>
    <joint name="q_2_6_1">
      <hardwareInterface>hardware_interface/PositionJointInterface</hardwareInterface>
    </joint>
    <actuator name="motor_2_6_1">
      <hardwareInterface>hardware_interface/PositionJointInterface</hardwareInterface>
      <mechanicalReduction>1</mechanicalReduction>
    </actuator>
  </transmission>
  <transmission name="tran_2_6_2">
    <type>transmission_interface/SimpleTransmission</type>
    <joint name="q_2_6_2">
      <hardwareInterface>hardware_interface/PositionJointInterface</hardwareInterface>
    </joint>
    <actuator name="motor_2_6_2">
      <hardwareInterface>hardware_interface/PositionJointInterface</hardwareInterface>
      <mechanicalReduction>1</mechanicalReduction>
    </actuator>
  </transmission>
  <physics default="true" name="ode_custom" type="ode">
    <real_time_update_rate>1000</real_time_update_rate>
    <max_step_size>0.001</max_step_size>
    <min_step_size>0.0001</min_step_size>
    <max_contacts>50</max_contacts>
    <!--use_dynamic_moi_rescaling>1</use_dynamic_moi_rescaling-->
    <ode>
      <constraints cfm="0.01" contact_max_correcting_vel="10.0" contact_surface_layer="0.01" erp="0.3"/>
      <solver>
        <type>quick</type>
        <precon_iters>100</precon_iters>
        <iteractions>500</iteractions>
        <!--SOR>1.2</SOR-->
      </solver>
    </ode>
  </physics>
  <gazebo>
    <plugin filename="libgazebo_ros_control.so" name="gazebo_ros_control">
      <robotNamespace>/shell_robot_model</robotNamespace>
      <robotSimType>gazebo_ros_control/DefaultRobotHWSim</robotSimType>
    </plugin>
  </gazebo>
</robot>

