<sdf version='1.6'>
  <world name='default'>
    <light name='sun' type='directional'>
      <cast_shadows>1</cast_shadows>
      <pose frame=''>0 0 10 0 -0 0</pose>
      <diffuse>0.8 0.8 0.8 1</diffuse>
      <specular>0.2 0.2 0.2 1</specular>
      <attenuation>
        <range>1000</range>
        <constant>0.9</constant>
        <linear>0.01</linear>
        <quadratic>0.001</quadratic>
      </attenuation>
      <direction>-0.5 0.1 -0.9</direction>
    </light>
    <model name='ground_plane'>
      <static>1</static>
      <link name='link'>
        <collision name='collision'>
          <geometry>
            <plane>
              <normal>0 0 1</normal>
              <size>100 100</size>
            </plane>
          </geometry>
          <surface>
            <contact>
              <collide_bitmask>65535</collide_bitmask>
              <ode/>
            </contact>
            <friction>
              <ode>
                <mu>100</mu>
                <mu2>50</mu2>
              </ode>
              <torsional>
                <ode/>
              </torsional>
            </friction>
            <bounce/>
          </surface>
          <max_contacts>10</max_contacts>
        </collision>
        <visual name='visual'>
          <cast_shadows>0</cast_shadows>
          <geometry>
            <plane>
              <normal>0 0 1</normal>
              <size>100 100</size>
            </plane>
          </geometry>
          <material>
            <script>
              <uri>file://media/materials/scripts/gazebo.material</uri>
              <name>Gazebo/Grey</name>
            </script>
          </material>
        </visual>
        <self_collide>0</self_collide>
        <enable_wind>0</enable_wind>
        <kinematic>0</kinematic>
      </link>
    </model>
    <gravity>0 0 -9.8</gravity>
    <magnetic_field>6e-06 2.3e-05 -4.2e-05</magnetic_field>
    <atmosphere type='adiabatic'/>
    <physics name='default_physics' default='0' type='ode'>
      <max_step_size>0.001</max_step_size>
      <real_time_factor>1</real_time_factor>
      <real_time_update_rate>1000</real_time_update_rate>
    </physics>
    <scene>
      <ambient>0.4 0.4 0.4 1</ambient>
      <background>0.7 0.7 0.7 1</background>
      <shadows>1</shadows>
    </scene>
    <audio>
      <device>default</device>
    </audio>
    <wind/>
    <spherical_coordinates>
      <surface_model>EARTH_WGS84</surface_model>
      <latitude_deg>0</latitude_deg>
      <longitude_deg>0</longitude_deg>
      <elevation>0</elevation>
      <heading_deg>0</heading_deg>
    </spherical_coordinates>
    <model name='shell_robot_model'>
      <link name='map'>
        <pose frame=''>0 0 0 0 -0 0</pose>
        <inertial>
          <pose frame=''>-0 -0 0.121429 0 -0 0</pose>
          <mass>12.6</mass>
          <inertia>
            <ixx>0.208469</ixx>
            <ixy>0.0299993</ixy>
            <ixz>0.0299995</ixz>
            <iyy>0.208467</iyy>
            <iyz>0.0299981</iyz>
            <izz>0.200814</izz>
          </inertia>
        </inertial>
        <collision name='map_fixed_joint_lump__base_link_collision'>
          <pose frame=''>0 0 0.14 0 -0 0</pose>
          <geometry>
            <cylinder>
              <length>0.005</length>
              <radius>0.1</radius>
            </cylinder>
          </geometry>
          <surface>
            <contact>
              <ode/>
            </contact>
            <friction>
              <ode/>
              <torsional>
                <ode/>
              </torsional>
            </friction>
            <bounce/>
          </surface>
          <max_contacts>10</max_contacts>
        </collision>
        <collision name='map_fixed_joint_lump__bottom_chassis_collision_1'>
          <pose frame=''>0 0 0.08 0 -0 0</pose>
          <geometry>
            <cylinder>
              <length>0.005</length>
              <radius>0.1</radius>
            </cylinder>
          </geometry>
          <surface>
            <contact>
              <ode/>
            </contact>
            <friction>
              <ode/>
              <torsional>
                <ode/>
              </torsional>
            </friction>
            <bounce/>
          </surface>
          <max_contacts>10</max_contacts>
        </collision>
        <collision name='map_fixed_joint_lump__leg_B_1_1_collision_2'>
          <pose frame=''>0.0275 0.047631 0.11 0 -0 1.04719</pose>
          <geometry>
            <cylinder>
              <length>0.0038</length>
              <radius>0.003</radius>
            </cylinder>
          </geometry>
          <surface>
            <contact>
              <ode/>
            </contact>
            <friction>
              <ode/>
              <torsional>
                <ode/>
              </torsional>
            </friction>
            <bounce/>
          </surface>
          <max_contacts>10</max_contacts>
        </collision>
        <collision name='map_fixed_joint_lump__leg_B_2_1_collision_3'>
          <pose frame=''>-0.027499 0.047632 0.11 0 -0 2.09438</pose>
          <geometry>
            <cylinder>
              <length>0.0038</length>
              <radius>0.003</radius>
            </cylinder>
          </geometry>
          <surface>
            <contact>
              <ode/>
            </contact>
            <friction>
              <ode/>
              <torsional>
                <ode/>
              </torsional>
            </friction>
            <bounce/>
          </surface>
          <max_contacts>10</max_contacts>
        </collision>
        <collision name='map_fixed_joint_lump__leg_B_3_1_collision_4'>
          <pose frame=''>-0.055 1e-06 0.11 0 -0 3.14157</pose>
          <geometry>
            <cylinder>
              <length>0.0038</length>
              <radius>0.003</radius>
            </cylinder>
          </geometry>
          <surface>
            <contact>
              <ode/>
            </contact>
            <friction>
              <ode/>
              <torsional>
                <ode/>
              </torsional>
            </friction>
            <bounce/>
          </surface>
          <max_contacts>10</max_contacts>
        </collision>
        <collision name='map_fixed_joint_lump__leg_B_4_1_collision_5'>
          <pose frame=''>-0.027501 -0.047631 0.11 0 -0 -2.09443</pose>
          <geometry>
            <cylinder>
              <length>0.0038</length>
              <radius>0.003</radius>
            </cylinder>
          </geometry>
          <surface>
            <contact>
              <ode/>
            </contact>
            <friction>
              <ode/>
              <torsional>
                <ode/>
              </torsional>
            </friction>
            <bounce/>
          </surface>
          <max_contacts>10</max_contacts>
        </collision>
        <collision name='map_fixed_joint_lump__leg_B_5_1_collision_6'>
          <pose frame=''>0.027498 -0.047632 0.11 0 -0 -1.04724</pose>
          <geometry>
            <cylinder>
              <length>0.0038</length>
              <radius>0.003</radius>
            </cylinder>
          </geometry>
          <surface>
            <contact>
              <ode/>
            </contact>
            <friction>
              <ode/>
              <torsional>
                <ode/>
              </torsional>
            </friction>
            <bounce/>
          </surface>
          <max_contacts>10</max_contacts>
        </collision>
        <collision name='map_fixed_joint_lump__leg_B_6_1_collision_7'>
          <pose frame=''>0.055 -2e-06 0.11 0 -0 -4.5e-05</pose>
          <geometry>
            <cylinder>
              <length>0.0038</length>
              <radius>0.003</radius>
            </cylinder>
          </geometry>
          <surface>
            <contact>
              <ode/>
            </contact>
            <friction>
              <ode/>
              <torsional>
                <ode/>
              </torsional>
            </friction>
            <bounce/>
          </surface>
          <max_contacts>10</max_contacts>
        </collision>
        <collision name='map_fixed_joint_lump__upper_chassis_collision_8'>
          <pose frame=''>0 0 0.2 0 -0 0</pose>
          <geometry>
            <cylinder>
              <length>0.005</length>
              <radius>0.1</radius>
            </cylinder>
          </geometry>
          <surface>
            <contact>
              <ode/>
            </contact>
            <friction>
              <ode/>
              <torsional>
                <ode/>
              </torsional>
            </friction>
            <bounce/>
          </surface>
          <max_contacts>10</max_contacts>
        </collision>
        <visual name='map_fixed_joint_lump__base_link_visual'>
          <pose frame=''>0 0 0.14 0 -0 0</pose>
          <geometry>
            <cylinder>
              <length>0.005</length>
              <radius>0.1</radius>
            </cylinder>
          </geometry>
          <material>
            <script>
              <uri>__default__</uri>
              <name>__default__</name>
            </script>
          </material>
        </visual>
        <visual name='map_fixed_joint_lump__bottom_chassis_visual_1'>
          <pose frame=''>0 0 0.08 0 -0 0</pose>
          <geometry>
            <cylinder>
              <length>0.005</length>
              <radius>0.1</radius>
            </cylinder>
          </geometry>
          <material>
            <script>
              <uri>__default__</uri>
              <name>__default__</name>
            </script>
          </material>
        </visual>
        <visual name='map_fixed_joint_lump__folding_fan_link_1_visual_2'>
          <pose frame=''>0 0 0.11 0 -0 1.04719</pose>
          <geometry>
            <cylinder>
              <length>0.019</length>
              <radius>0.04</radius>
            </cylinder>
          </geometry>
          <material>
            <script>
              <uri>__default__</uri>
              <name>__default__</name>
            </script>
          </material>
        </visual>
        <visual name='map_fixed_joint_lump__leg_B_1_1_visual_3'>
          <pose frame=''>0.0275 0.047631 0.11 0 -0 1.04719</pose>
          <geometry>
            <cylinder>
              <length>0.019</length>
              <radius>0.015</radius>
            </cylinder>
          </geometry>
          <material>
            <script>
              <uri>__default__</uri>
              <name>__default__</name>
            </script>
          </material>
        </visual>
        <visual name='map_fixed_joint_lump__folding_fan_link_2_visual_4'>
          <pose frame=''>0 0 0.11 0 -0 2.09438</pose>
          <geometry>
            <cylinder>
              <length>0.019</length>
              <radius>0.04</radius>
            </cylinder>
          </geometry>
          <material>
            <script>
              <uri>__default__</uri>
              <name>__default__</name>
            </script>
          </material>
        </visual>
        <visual name='map_fixed_joint_lump__leg_B_2_1_visual_5'>
          <pose frame=''>-0.027499 0.047632 0.11 0 -0 2.09438</pose>
          <geometry>
            <cylinder>
              <length>0.019</length>
              <radius>0.015</radius>
            </cylinder>
          </geometry>
          <material>
            <script>
              <uri>__default__</uri>
              <name>__default__</name>
            </script>
          </material>
        </visual>
        <visual name='map_fixed_joint_lump__folding_fan_link_3_visual_6'>
          <pose frame=''>0 0 0.11 0 -0 3.14157</pose>
          <geometry>
            <cylinder>
              <length>0.019</length>
              <radius>0.04</radius>
            </cylinder>
          </geometry>
          <material>
            <script>
              <uri>__default__</uri>
              <name>__default__</name>
            </script>
          </material>
        </visual>
        <visual name='map_fixed_joint_lump__leg_B_3_1_visual_7'>
          <pose frame=''>-0.055 1e-06 0.11 0 -0 3.14157</pose>
          <geometry>
            <cylinder>
              <length>0.019</length>
              <radius>0.015</radius>
            </cylinder>
          </geometry>
          <material>
            <script>
              <uri>__default__</uri>
              <name>__default__</name>
            </script>
          </material>
        </visual>
        <visual name='map_fixed_joint_lump__folding_fan_link_4_visual_8'>
          <pose frame=''>0 0 0.11 0 -0 -2.09443</pose>
          <geometry>
            <cylinder>
              <length>0.019</length>
              <radius>0.04</radius>
            </cylinder>
          </geometry>
          <material>
            <script>
              <uri>__default__</uri>
              <name>__default__</name>
            </script>
          </material>
        </visual>
        <visual name='map_fixed_joint_lump__leg_B_4_1_visual_9'>
          <pose frame=''>-0.027501 -0.047631 0.11 0 -0 -2.09443</pose>
          <geometry>
            <cylinder>
              <length>0.019</length>
              <radius>0.015</radius>
            </cylinder>
          </geometry>
          <material>
            <script>
              <uri>__default__</uri>
              <name>__default__</name>
            </script>
          </material>
        </visual>
        <visual name='map_fixed_joint_lump__folding_fan_link_5_visual_10'>
          <pose frame=''>0 0 0.11 0 -0 -1.04724</pose>
          <geometry>
            <cylinder>
              <length>0.019</length>
              <radius>0.04</radius>
            </cylinder>
          </geometry>
          <material>
            <script>
              <uri>__default__</uri>
              <name>__default__</name>
            </script>
          </material>
        </visual>
        <visual name='map_fixed_joint_lump__leg_B_5_1_visual_11'>
          <pose frame=''>0.027498 -0.047632 0.11 0 -0 -1.04724</pose>
          <geometry>
            <cylinder>
              <length>0.019</length>
              <radius>0.015</radius>
            </cylinder>
          </geometry>
          <material>
            <script>
              <uri>__default__</uri>
              <name>__default__</name>
            </script>
          </material>
        </visual>
        <visual name='map_fixed_joint_lump__folding_fan_link_6_visual_12'>
          <pose frame=''>0 0 0.11 0 -0 -4.5e-05</pose>
          <geometry>
            <cylinder>
              <length>0.019</length>
              <radius>0.04</radius>
            </cylinder>
          </geometry>
          <material>
            <script>
              <uri>__default__</uri>
              <name>__default__</name>
            </script>
          </material>
        </visual>
        <visual name='map_fixed_joint_lump__leg_B_6_1_visual_13'>
          <pose frame=''>0.055 -2e-06 0.11 0 -0 -4.5e-05</pose>
          <geometry>
            <cylinder>
              <length>0.019</length>
              <radius>0.015</radius>
            </cylinder>
          </geometry>
          <material>
            <script>
              <uri>__default__</uri>
              <name>__default__</name>
            </script>
          </material>
        </visual>
        <visual name='map_fixed_joint_lump__upper_chassis_visual_14'>
          <pose frame=''>0 0 0.2 0 -0 0</pose>
          <geometry>
            <cylinder>
              <length>0.005</length>
              <radius>0.1</radius>
            </cylinder>
          </geometry>
          <material>
            <script>
              <uri>__default__</uri>
              <name>__default__</name>
            </script>
          </material>
        </visual>
        <velocity_decay/>
        <velocity_decay/>
        <velocity_decay/>
        <velocity_decay/>
        <velocity_decay/>
        <velocity_decay/>
        <velocity_decay/>
        <velocity_decay/>
        <velocity_decay/>
        <velocity_decay/>
        <velocity_decay/>
        <velocity_decay/>
        <velocity_decay/>
        <velocity_decay/>
        <velocity_decay/>
        <velocity_decay/>
        <velocity_decay/>
        <velocity_decay/>
        <velocity_decay/>
        <velocity_decay/>
        <velocity_decay/>
        <velocity_decay/>
        <velocity_decay/>
        <velocity_decay/>
        <velocity_decay/>
        <velocity_decay/>
        <velocity_decay/>
        <gravity>1</gravity>
        <velocity_decay/>
        <self_collide>1</self_collide>
        <enable_wind>0</enable_wind>
        <kinematic>0</kinematic>
      </link>
      <link name='leg_B_1_2'>
        <pose frame=''>0.0275 0.047631 0.11 0 -0 1.04719</pose>
        <inertial>
          <pose frame=''>0.04 0 0 3.14159 1.57079 3.14159</pose>
          <mass>0.06</mass>
          <inertia>
            <ixx>0.0004</ixx>
            <ixy>0.01</ixy>
            <ixz>0.01</ixz>
            <iyy>0.01</iyy>
            <iyz>0.01</iyz>
            <izz>0.0004</izz>
          </inertia>
        </inertial>
        <collision name='leg_B_1_2_collision'>
          <pose frame=''>0.04 0 0 3.14159 1.57079 3.14159</pose>
          <geometry>
            <cylinder>
              <length>0.024</length>
              <radius>0.003</radius>
            </cylinder>
          </geometry>
          <surface>
            <contact>
              <ode/>
            </contact>
            <friction>
              <ode/>
              <torsional>
                <ode/>
              </torsional>
            </friction>
            <bounce/>
          </surface>
          <max_contacts>10</max_contacts>
        </collision>
        <visual name='leg_B_1_2_visual'>
          <pose frame=''>0.04 0 0 3.14159 1.57079 3.14159</pose>
          <geometry>
            <cylinder>
              <length>0.08</length>
              <radius>0.005</radius>
            </cylinder>
          </geometry>
          <material>
            <script>
              <uri>__default__</uri>
              <name>__default__</name>
            </script>
          </material>
        </visual>
        <gravity>1</gravity>
        <velocity_decay/>
        <self_collide>1</self_collide>
        <enable_wind>0</enable_wind>
        <kinematic>0</kinematic>
      </link>
      <joint name='q_1_1_1' type='revolute'>
        <child>leg_B_1_2</child>
        <parent>map</parent>
        <axis>
          <xyz>0 0 1</xyz>
          <limit>
            <lower>0</lower>
            <upper>3.14159</upper>
            <effort>1.5</effort>
            <velocity>0.04</velocity>
          </limit>
          <dynamics>
            <damping>0.8</damping>
            <friction>0</friction>
            <spring_reference>0</spring_reference>
            <spring_stiffness>0</spring_stiffness>
          </dynamics>
          <use_parent_model_frame>1</use_parent_model_frame>
        </axis>
      </joint>
      <link name='leg_B_1_3'>
        <pose frame=''>0.067501 0.116913 0.11 0 -0 1.04719</pose>
        <inertial>
          <pose frame=''>0.03 0 0 3.14159 1.57079 3.14159</pose>
          <mass>0.06</mass>
          <inertia>
            <ixx>0.0003</ixx>
            <ixy>0.01</ixy>
            <ixz>0.01</ixz>
            <iyy>0.01</iyy>
            <iyz>0.01</iyz>
            <izz>0.0003</izz>
          </inertia>
        </inertial>
        <collision name='leg_B_1_3_collision'>
          <pose frame=''>0.03 0 0 3.14159 1.57079 3.14159</pose>
          <geometry>
            <cylinder>
              <length>0.036</length>
              <radius>0.003</radius>
            </cylinder>
          </geometry>
          <surface>
            <contact>
              <ode/>
            </contact>
            <friction>
              <ode/>
              <torsional>
                <ode/>
              </torsional>
            </friction>
            <bounce/>
          </surface>
          <max_contacts>10</max_contacts>
        </collision>
        <visual name='leg_B_1_3_visual'>
          <pose frame=''>0.03 0 0 3.14159 1.57079 3.14159</pose>
          <geometry>
            <cylinder>
              <length>0.06</length>
              <radius>0.005</radius>
            </cylinder>
          </geometry>
          <material>
            <script>
              <uri>__default__</uri>
              <name>__default__</name>
            </script>
          </material>
        </visual>
        <gravity>1</gravity>
        <velocity_decay/>
        <self_collide>1</self_collide>
        <enable_wind>0</enable_wind>
        <kinematic>0</kinematic>
      </link>
      <joint name='q_1_1_2' type='revolute'>
        <child>leg_B_1_3</child>
        <parent>leg_B_1_2</parent>
        <axis>
          <xyz>0 0 1</xyz>
          <limit>
            <lower>-1.57079</lower>
            <upper>1.57079</upper>
            <effort>1.5</effort>
            <velocity>0.04</velocity>
          </limit>
          <dynamics>
            <damping>0.7</damping>
            <friction>0</friction>
            <spring_reference>0</spring_reference>
            <spring_stiffness>0</spring_stiffness>
          </dynamics>
          <use_parent_model_frame>1</use_parent_model_frame>
        </axis>
      </joint>
      <link name='leg_B_1_4'>
        <pose frame=''>0.097501 0.168874 0.11 3.14159 1.57079 -2.0944</pose>
        <inertial>
          <pose frame=''>0.04 0 0 3.14159 -1.57079 3.14159</pose>
          <mass>0.06</mass>
          <inertia>
            <ixx>0.0004</ixx>
            <ixy>0.01</ixy>
            <ixz>0.01</ixz>
            <iyy>0.01</iyy>
            <iyz>0.01</iyz>
            <izz>0.0004</izz>
          </inertia>
        </inertial>
        <collision name='leg_B_1_4_collision'>
          <pose frame=''>0.04 0 0 3.14159 -1.57079 3.14159</pose>
          <geometry>
            <cylinder>
              <length>0.048</length>
              <radius>0.003</radius>
            </cylinder>
          </geometry>
          <surface>
            <contact>
              <ode/>
            </contact>
            <friction>
              <ode/>
              <torsional>
                <ode/>
              </torsional>
            </friction>
            <bounce/>
          </surface>
          <max_contacts>10</max_contacts>
        </collision>
        <visual name='leg_B_1_4_visual'>
          <pose frame=''>0.04 0 0 3.14159 -1.57079 3.14159</pose>
          <geometry>
            <cylinder>
              <length>0.08</length>
              <radius>0.005</radius>
            </cylinder>
          </geometry>
          <material>
            <script>
              <uri>__default__</uri>
              <name>__default__</name>
            </script>
          </material>
        </visual>
        <gravity>1</gravity>
        <velocity_decay/>
        <self_collide>1</self_collide>
        <enable_wind>0</enable_wind>
        <kinematic>0</kinematic>
      </link>
      <joint name='q_1_1_3' type='revolute'>
        <child>leg_B_1_4</child>
        <parent>leg_B_1_3</parent>
        <axis>
          <xyz>-0.866022 0.500007 0</xyz>
          <limit>
            <lower>-1.57079</lower>
            <upper>1.57079</upper>
            <effort>1.8</effort>
            <velocity>0.04</velocity>
          </limit>
          <dynamics>
            <damping>0.7</damping>
            <friction>0</friction>
            <spring_reference>0</spring_reference>
            <spring_stiffness>0</spring_stiffness>
          </dynamics>
          <use_parent_model_frame>1</use_parent_model_frame>
        </axis>
      </joint>
      <link name='leg_B_1_5'>
        <pose frame=''>0.097501 0.168874 0.03 1.5708 1.57079 -2.0944</pose>
        <inertial>
          <pose frame=''>0.03 0 0 3.14159 1.57079 3.14159</pose>
          <mass>0.06</mass>
          <inertia>
            <ixx>0.0003</ixx>
            <ixy>0.01</ixy>
            <ixz>0.01</ixz>
            <iyy>0.01</iyy>
            <iyz>0.01</iyz>
            <izz>0.0003</izz>
          </inertia>
        </inertial>
        <collision name='leg_B_1_5_collision'>
          <pose frame=''>0.03 0 0 3.14159 1.57079 3.14159</pose>
          <geometry>
            <cylinder>
              <length>0.036</length>
              <radius>0.003</radius>
            </cylinder>
          </geometry>
          <surface>
            <contact>
              <ode/>
            </contact>
            <friction>
              <ode/>
              <torsional>
                <ode/>
              </torsional>
            </friction>
            <bounce/>
          </surface>
          <max_contacts>10</max_contacts>
        </collision>
        <visual name='leg_B_1_5_visual'>
          <pose frame=''>0.03 0 0 3.14159 1.57079 3.14159</pose>
          <geometry>
            <cylinder>
              <length>0.06</length>
              <radius>0.005</radius>
            </cylinder>
          </geometry>
          <material>
            <script>
              <uri>__default__</uri>
              <name>__default__</name>
            </script>
          </material>
        </visual>
        <gravity>1</gravity>
        <velocity_decay/>
        <self_collide>1</self_collide>
        <enable_wind>0</enable_wind>
        <kinematic>0</kinematic>
      </link>
      <joint name='q_1_1_4' type='revolute'>
        <child>leg_B_1_5</child>
        <parent>leg_B_1_4</parent>
        <axis>
          <xyz>-0.866021 0.500008 0</xyz>
          <limit>
            <lower>-1.57079</lower>
            <upper>1.57079</upper>
            <effort>1.8</effort>
            <velocity>0.04</velocity>
          </limit>
          <dynamics>
            <damping>0.7</damping>
            <friction>0</friction>
            <spring_reference>0</spring_reference>
            <spring_stiffness>0</spring_stiffness>
          </dynamics>
          <use_parent_model_frame>1</use_parent_model_frame>
        </axis>
      </joint>
      <link name='leg_B_2_2'>
        <pose frame=''>-0.027499 0.047632 0.11 0 -0 2.09438</pose>
        <inertial>
          <pose frame=''>0.04 0 0 3.14159 1.57079 3.14159</pose>
          <mass>0.06</mass>
          <inertia>
            <ixx>0.0004</ixx>
            <ixy>0.01</ixy>
            <ixz>0.01</ixz>
            <iyy>0.01</iyy>
            <iyz>0.01</iyz>
            <izz>0.0004</izz>
          </inertia>
        </inertial>
        <collision name='leg_B_2_2_collision'>
          <pose frame=''>0.04 0 0 3.14159 1.57079 3.14159</pose>
          <geometry>
            <cylinder>
              <length>0.024</length>
              <radius>0.003</radius>
            </cylinder>
          </geometry>
          <surface>
            <contact>
              <ode/>
            </contact>
            <friction>
              <ode/>
              <torsional>
                <ode/>
              </torsional>
            </friction>
            <bounce/>
          </surface>
          <max_contacts>10</max_contacts>
        </collision>
        <visual name='leg_B_2_2_visual'>
          <pose frame=''>0.04 0 0 3.14159 1.57079 3.14159</pose>
          <geometry>
            <cylinder>
              <length>0.08</length>
              <radius>0.005</radius>
            </cylinder>
          </geometry>
          <material>
            <script>
              <uri>__default__</uri>
              <name>__default__</name>
            </script>
          </material>
        </visual>
        <gravity>1</gravity>
        <velocity_decay/>
        <self_collide>1</self_collide>
        <enable_wind>0</enable_wind>
        <kinematic>0</kinematic>
      </link>
      <joint name='q_1_2_1' type='revolute'>
        <child>leg_B_2_2</child>
        <parent>map</parent>
        <axis>
          <xyz>0 0 1</xyz>
          <limit>
            <lower>0</lower>
            <upper>3.14159</upper>
            <effort>1.5</effort>
            <velocity>0.04</velocity>
          </limit>
          <dynamics>
            <damping>0.8</damping>
            <friction>0</friction>
            <spring_reference>0</spring_reference>
            <spring_stiffness>0</spring_stiffness>
          </dynamics>
          <use_parent_model_frame>1</use_parent_model_frame>
        </axis>
      </joint>
      <link name='leg_B_2_3'>
        <pose frame=''>-0.067498 0.116914 0.11 0 -0 2.09438</pose>
        <inertial>
          <pose frame=''>0.03 0 0 3.14159 1.57079 3.14159</pose>
          <mass>0.06</mass>
          <inertia>
            <ixx>0.0003</ixx>
            <ixy>0.01</ixy>
            <ixz>0.01</ixz>
            <iyy>0.01</iyy>
            <iyz>0.01</iyz>
            <izz>0.0003</izz>
          </inertia>
        </inertial>
        <collision name='leg_B_2_3_collision'>
          <pose frame=''>0.03 0 0 3.14159 1.57079 3.14159</pose>
          <geometry>
            <cylinder>
              <length>0.036</length>
              <radius>0.003</radius>
            </cylinder>
          </geometry>
          <surface>
            <contact>
              <ode/>
            </contact>
            <friction>
              <ode/>
              <torsional>
                <ode/>
              </torsional>
            </friction>
            <bounce/>
          </surface>
          <max_contacts>10</max_contacts>
        </collision>
        <visual name='leg_B_2_3_visual'>
          <pose frame=''>0.03 0 0 3.14159 1.57079 3.14159</pose>
          <geometry>
            <cylinder>
              <length>0.06</length>
              <radius>0.005</radius>
            </cylinder>
          </geometry>
          <material>
            <script>
              <uri>__default__</uri>
              <name>__default__</name>
            </script>
          </material>
        </visual>
        <gravity>1</gravity>
        <velocity_decay/>
        <self_collide>1</self_collide>
        <enable_wind>0</enable_wind>
        <kinematic>0</kinematic>
      </link>
      <joint name='q_1_2_2' type='revolute'>
        <child>leg_B_2_3</child>
        <parent>leg_B_2_2</parent>
        <axis>
          <xyz>0 0 1</xyz>
          <limit>
            <lower>-1.57079</lower>
            <upper>1.57079</upper>
            <effort>1.5</effort>
            <velocity>0.04</velocity>
          </limit>
          <dynamics>
            <damping>0.7</damping>
            <friction>0</friction>
            <spring_reference>0</spring_reference>
            <spring_stiffness>0</spring_stiffness>
          </dynamics>
          <use_parent_model_frame>1</use_parent_model_frame>
        </axis>
      </joint>
      <link name='leg_B_2_4'>
        <pose frame=''>-0.097497 0.168876 0.11 3.14159 1.57079 -1.04721</pose>
        <inertial>
          <pose frame=''>0.04 0 0 3.14159 -1.57079 3.14159</pose>
          <mass>0.06</mass>
          <inertia>
            <ixx>0.0004</ixx>
            <ixy>0.01</ixy>
            <ixz>0.01</ixz>
            <iyy>0.01</iyy>
            <iyz>0.01</iyz>
            <izz>0.0004</izz>
          </inertia>
        </inertial>
        <collision name='leg_B_2_4_collision'>
          <pose frame=''>0.04 0 0 3.14159 -1.57079 3.14159</pose>
          <geometry>
            <cylinder>
              <length>0.048</length>
              <radius>0.003</radius>
            </cylinder>
          </geometry>
          <surface>
            <contact>
              <ode/>
            </contact>
            <friction>
              <ode/>
              <torsional>
                <ode/>
              </torsional>
            </friction>
            <bounce/>
          </surface>
          <max_contacts>10</max_contacts>
        </collision>
        <visual name='leg_B_2_4_visual'>
          <pose frame=''>0.04 0 0 3.14159 -1.57079 3.14159</pose>
          <geometry>
            <cylinder>
              <length>0.08</length>
              <radius>0.005</radius>
            </cylinder>
          </geometry>
          <material>
            <script>
              <uri>__default__</uri>
              <name>__default__</name>
            </script>
          </material>
        </visual>
        <gravity>1</gravity>
        <velocity_decay/>
        <self_collide>1</self_collide>
        <enable_wind>0</enable_wind>
        <kinematic>0</kinematic>
      </link>
      <joint name='q_1_2_3' type='revolute'>
        <child>leg_B_2_4</child>
        <parent>leg_B_2_3</parent>
        <axis>
          <xyz>-0.866033 -0.499987 -0</xyz>
          <limit>
            <lower>-1.57079</lower>
            <upper>1.57079</upper>
            <effort>1.8</effort>
            <velocity>0.04</velocity>
          </limit>
          <dynamics>
            <damping>0.7</damping>
            <friction>0</friction>
            <spring_reference>0</spring_reference>
            <spring_stiffness>0</spring_stiffness>
          </dynamics>
          <use_parent_model_frame>1</use_parent_model_frame>
        </axis>
      </joint>
      <link name='leg_B_2_5'>
        <pose frame=''>-0.097498 0.168877 0.03 1.57079 1.57079 -1.04721</pose>
        <inertial>
          <pose frame=''>0.03 0 0 3.14159 1.57079 3.14159</pose>
          <mass>0.06</mass>
          <inertia>
            <ixx>0.0003</ixx>
            <ixy>0.01</ixy>
            <ixz>0.01</ixz>
            <iyy>0.01</iyy>
            <iyz>0.01</iyz>
            <izz>0.0003</izz>
          </inertia>
        </inertial>
        <collision name='leg_B_2_5_collision'>
          <pose frame=''>0.03 0 0 3.14159 1.57079 3.14159</pose>
          <geometry>
            <cylinder>
              <length>0.036</length>
              <radius>0.003</radius>
            </cylinder>
          </geometry>
          <surface>
            <contact>
              <ode/>
            </contact>
            <friction>
              <ode/>
              <torsional>
                <ode/>
              </torsional>
            </friction>
            <bounce/>
          </surface>
          <max_contacts>10</max_contacts>
        </collision>
        <visual name='leg_B_2_5_visual'>
          <pose frame=''>0.03 0 0 3.14159 1.57079 3.14159</pose>
          <geometry>
            <cylinder>
              <length>0.06</length>
              <radius>0.005</radius>
            </cylinder>
          </geometry>
          <material>
            <script>
              <uri>__default__</uri>
              <name>__default__</name>
            </script>
          </material>
        </visual>
        <gravity>1</gravity>
        <velocity_decay/>
        <self_collide>1</self_collide>
        <enable_wind>0</enable_wind>
        <kinematic>0</kinematic>
      </link>
      <joint name='q_1_2_4' type='revolute'>
        <child>leg_B_2_5</child>
        <parent>leg_B_2_4</parent>
        <axis>
          <xyz>-0.866034 -0.499986 0</xyz>
          <limit>
            <lower>-1.57079</lower>
            <upper>1.57079</upper>
            <effort>1.8</effort>
            <velocity>0.04</velocity>
          </limit>
          <dynamics>
            <damping>0.7</damping>
            <friction>0</friction>
            <spring_reference>0</spring_reference>
            <spring_stiffness>0</spring_stiffness>
          </dynamics>
          <use_parent_model_frame>1</use_parent_model_frame>
        </axis>
      </joint>
      <link name='leg_B_3_2'>
        <pose frame=''>-0.055 1e-06 0.11 0 -0 3.14157</pose>
        <inertial>
          <pose frame=''>0.04 0 0 3.14159 1.57079 3.14159</pose>
          <mass>0.06</mass>
          <inertia>
            <ixx>0.0004</ixx>
            <ixy>0.01</ixy>
            <ixz>0.01</ixz>
            <iyy>0.01</iyy>
            <iyz>0.01</iyz>
            <izz>0.0004</izz>
          </inertia>
        </inertial>
        <collision name='leg_B_3_2_collision'>
          <pose frame=''>0.04 0 0 3.14159 1.57079 3.14159</pose>
          <geometry>
            <cylinder>
              <length>0.024</length>
              <radius>0.003</radius>
            </cylinder>
          </geometry>
          <surface>
            <contact>
              <ode/>
            </contact>
            <friction>
              <ode/>
              <torsional>
                <ode/>
              </torsional>
            </friction>
            <bounce/>
          </surface>
          <max_contacts>10</max_contacts>
        </collision>
        <visual name='leg_B_3_2_visual'>
          <pose frame=''>0.04 0 0 3.14159 1.57079 3.14159</pose>
          <geometry>
            <cylinder>
              <length>0.08</length>
              <radius>0.005</radius>
            </cylinder>
          </geometry>
          <material>
            <script>
              <uri>__default__</uri>
              <name>__default__</name>
            </script>
          </material>
        </visual>
        <gravity>1</gravity>
        <velocity_decay/>
        <self_collide>1</self_collide>
        <enable_wind>0</enable_wind>
        <kinematic>0</kinematic>
      </link>
      <joint name='q_1_3_1' type='revolute'>
        <child>leg_B_3_2</child>
        <parent>map</parent>
        <axis>
          <xyz>0 0 1</xyz>
          <limit>
            <lower>0</lower>
            <upper>3.14159</upper>
            <effort>1.5</effort>
            <velocity>0.04</velocity>
          </limit>
          <dynamics>
            <damping>0.8</damping>
            <friction>0</friction>
            <spring_reference>0</spring_reference>
            <spring_stiffness>0</spring_stiffness>
          </dynamics>
          <use_parent_model_frame>1</use_parent_model_frame>
        </axis>
      </joint>
      <link name='leg_B_3_3'>
        <pose frame=''>-0.135 3e-06 0.11 0 -0 3.14157</pose>
        <inertial>
          <pose frame=''>0.03 0 0 3.14159 1.57079 3.14159</pose>
          <mass>0.06</mass>
          <inertia>
            <ixx>0.0003</ixx>
            <ixy>0.01</ixy>
            <ixz>0.01</ixz>
            <iyy>0.01</iyy>
            <iyz>0.01</iyz>
            <izz>0.0003</izz>
          </inertia>
        </inertial>
        <collision name='leg_B_3_3_collision'>
          <pose frame=''>0.03 0 0 3.14159 1.57079 3.14159</pose>
          <geometry>
            <cylinder>
              <length>0.036</length>
              <radius>0.003</radius>
            </cylinder>
          </geometry>
          <surface>
            <contact>
              <ode/>
            </contact>
            <friction>
              <ode/>
              <torsional>
                <ode/>
              </torsional>
            </friction>
            <bounce/>
          </surface>
          <max_contacts>10</max_contacts>
        </collision>
        <visual name='leg_B_3_3_visual'>
          <pose frame=''>0.03 0 0 3.14159 1.57079 3.14159</pose>
          <geometry>
            <cylinder>
              <length>0.06</length>
              <radius>0.005</radius>
            </cylinder>
          </geometry>
          <material>
            <script>
              <uri>__default__</uri>
              <name>__default__</name>
            </script>
          </material>
        </visual>
        <gravity>1</gravity>
        <velocity_decay/>
        <self_collide>1</self_collide>
        <enable_wind>0</enable_wind>
        <kinematic>0</kinematic>
      </link>
      <joint name='q_1_3_2' type='revolute'>
        <child>leg_B_3_3</child>
        <parent>leg_B_3_2</parent>
        <axis>
          <xyz>0 0 1</xyz>
          <limit>
            <lower>-1.57079</lower>
            <upper>1.57079</upper>
            <effort>1.5</effort>
            <velocity>0.04</velocity>
          </limit>
          <dynamics>
            <damping>0.7</damping>
            <friction>0</friction>
            <spring_reference>0</spring_reference>
            <spring_stiffness>0</spring_stiffness>
          </dynamics>
          <use_parent_model_frame>1</use_parent_model_frame>
        </axis>
      </joint>
      <link name='leg_B_3_4'>
        <pose frame=''>-0.195 4e-06 0.11 -3.14159 1.57079 -2.3e-05</pose>
        <inertial>
          <pose frame=''>0.04 0 0 3.14159 -1.57079 3.14159</pose>
          <mass>0.06</mass>
          <inertia>
            <ixx>0.0004</ixx>
            <ixy>0.01</ixy>
            <ixz>0.01</ixz>
            <iyy>0.01</iyy>
            <iyz>0.01</iyz>
            <izz>0.0004</izz>
          </inertia>
        </inertial>
        <collision name='leg_B_3_4_collision'>
          <pose frame=''>0.04 0 0 3.14159 -1.57079 3.14159</pose>
          <geometry>
            <cylinder>
              <length>0.048</length>
              <radius>0.003</radius>
            </cylinder>
          </geometry>
          <surface>
            <contact>
              <ode/>
            </contact>
            <friction>
              <ode/>
              <torsional>
                <ode/>
              </torsional>
            </friction>
            <bounce/>
          </surface>
          <max_contacts>10</max_contacts>
        </collision>
        <visual name='leg_B_3_4_visual'>
          <pose frame=''>0.04 0 0 3.14159 -1.57079 3.14159</pose>
          <geometry>
            <cylinder>
              <length>0.08</length>
              <radius>0.005</radius>
            </cylinder>
          </geometry>
          <material>
            <script>
              <uri>__default__</uri>
              <name>__default__</name>
            </script>
          </material>
        </visual>
        <gravity>1</gravity>
        <velocity_decay/>
        <self_collide>1</self_collide>
        <enable_wind>0</enable_wind>
        <kinematic>0</kinematic>
      </link>
      <joint name='q_1_3_3' type='revolute'>
        <child>leg_B_3_4</child>
        <parent>leg_B_3_3</parent>
        <axis>
          <xyz>-2.3e-05 -1 0</xyz>
          <limit>
            <lower>-1.57079</lower>
            <upper>1.57079</upper>
            <effort>1.8</effort>
            <velocity>0.04</velocity>
          </limit>
          <dynamics>
            <damping>0.7</damping>
            <friction>0</friction>
            <spring_reference>0</spring_reference>
            <spring_stiffness>0</spring_stiffness>
          </dynamics>
          <use_parent_model_frame>1</use_parent_model_frame>
        </axis>
      </joint>
      <link name='leg_B_3_5'>
        <pose frame=''>-0.195 4e-06 0.03 1.57079 1.57079 -2.3e-05</pose>
        <inertial>
          <pose frame=''>0.03 0 0 3.14159 1.57079 3.14159</pose>
          <mass>0.06</mass>
          <inertia>
            <ixx>0.0003</ixx>
            <ixy>0.01</ixy>
            <ixz>0.01</ixz>
            <iyy>0.01</iyy>
            <iyz>0.01</iyz>
            <izz>0.0003</izz>
          </inertia>
        </inertial>
        <collision name='leg_B_3_5_collision'>
          <pose frame=''>0.03 0 0 3.14159 1.57079 3.14159</pose>
          <geometry>
            <cylinder>
              <length>0.036</length>
              <radius>0.003</radius>
            </cylinder>
          </geometry>
          <surface>
            <contact>
              <ode/>
            </contact>
            <friction>
              <ode/>
              <torsional>
                <ode/>
              </torsional>
            </friction>
            <bounce/>
          </surface>
          <max_contacts>10</max_contacts>
        </collision>
        <visual name='leg_B_3_5_visual'>
          <pose frame=''>0.03 0 0 3.14159 1.57079 3.14159</pose>
          <geometry>
            <cylinder>
              <length>0.06</length>
              <radius>0.005</radius>
            </cylinder>
          </geometry>
          <material>
            <script>
              <uri>__default__</uri>
              <name>__default__</name>
            </script>
          </material>
        </visual>
        <gravity>1</gravity>
        <velocity_decay/>
        <self_collide>1</self_collide>
        <enable_wind>0</enable_wind>
        <kinematic>0</kinematic>
      </link>
      <joint name='q_1_3_4' type='revolute'>
        <child>leg_B_3_5</child>
        <parent>leg_B_3_4</parent>
        <axis>
          <xyz>-2.4e-05 -1 0</xyz>
          <limit>
            <lower>-1.57079</lower>
            <upper>1.57079</upper>
            <effort>1.8</effort>
            <velocity>0.04</velocity>
          </limit>
          <dynamics>
            <damping>0.7</damping>
            <friction>0</friction>
            <spring_reference>0</spring_reference>
            <spring_stiffness>0</spring_stiffness>
          </dynamics>
          <use_parent_model_frame>1</use_parent_model_frame>
        </axis>
      </joint>
      <link name='leg_B_4_2'>
        <pose frame=''>-0.027501 -0.047631 0.11 0 -0 -2.09443</pose>
        <inertial>
          <pose frame=''>0.04 0 0 3.14159 1.57079 3.14159</pose>
          <mass>0.06</mass>
          <inertia>
            <ixx>0.0004</ixx>
            <ixy>0.01</ixy>
            <ixz>0.01</ixz>
            <iyy>0.01</iyy>
            <iyz>0.01</iyz>
            <izz>0.0004</izz>
          </inertia>
        </inertial>
        <collision name='leg_B_4_2_collision'>
          <pose frame=''>0.04 0 0 3.14159 1.57079 3.14159</pose>
          <geometry>
            <cylinder>
              <length>0.024</length>
              <radius>0.003</radius>
            </cylinder>
          </geometry>
          <surface>
            <contact>
              <ode/>
            </contact>
            <friction>
              <ode/>
              <torsional>
                <ode/>
              </torsional>
            </friction>
            <bounce/>
          </surface>
          <max_contacts>10</max_contacts>
        </collision>
        <visual name='leg_B_4_2_visual'>
          <pose frame=''>0.04 0 0 3.14159 1.57079 3.14159</pose>
          <geometry>
            <cylinder>
              <length>0.08</length>
              <radius>0.005</radius>
            </cylinder>
          </geometry>
          <material>
            <script>
              <uri>__default__</uri>
              <name>__default__</name>
            </script>
          </material>
        </visual>
        <gravity>1</gravity>
        <velocity_decay/>
        <self_collide>1</self_collide>
        <enable_wind>0</enable_wind>
        <kinematic>0</kinematic>
      </link>
      <joint name='q_1_4_1' type='revolute'>
        <child>leg_B_4_2</child>
        <parent>map</parent>
        <axis>
          <xyz>0 0 1</xyz>
          <limit>
            <lower>0</lower>
            <upper>3.14159</upper>
            <effort>1.5</effort>
            <velocity>0.04</velocity>
          </limit>
          <dynamics>
            <damping>0.8</damping>
            <friction>0</friction>
            <spring_reference>0</spring_reference>
            <spring_stiffness>0</spring_stiffness>
          </dynamics>
          <use_parent_model_frame>1</use_parent_model_frame>
        </axis>
      </joint>
      <link name='leg_B_4_3'>
        <pose frame=''>-0.067504 -0.116911 0.11 0 -0 -2.09443</pose>
        <inertial>
          <pose frame=''>0.03 0 0 3.14159 1.57079 3.14159</pose>
          <mass>0.06</mass>
          <inertia>
            <ixx>0.0003</ixx>
            <ixy>0.01</ixy>
            <ixz>0.01</ixz>
            <iyy>0.01</iyy>
            <iyz>0.01</iyz>
            <izz>0.0003</izz>
          </inertia>
        </inertial>
        <collision name='leg_B_4_3_collision'>
          <pose frame=''>0.03 0 0 3.14159 1.57079 3.14159</pose>
          <geometry>
            <cylinder>
              <length>0.036</length>
              <radius>0.003</radius>
            </cylinder>
          </geometry>
          <surface>
            <contact>
              <ode/>
            </contact>
            <friction>
              <ode/>
              <torsional>
                <ode/>
              </torsional>
            </friction>
            <bounce/>
          </surface>
          <max_contacts>10</max_contacts>
        </collision>
        <visual name='leg_B_4_3_visual'>
          <pose frame=''>0.03 0 0 3.14159 1.57079 3.14159</pose>
          <geometry>
            <cylinder>
              <length>0.06</length>
              <radius>0.005</radius>
            </cylinder>
          </geometry>
          <material>
            <script>
              <uri>__default__</uri>
              <name>__default__</name>
            </script>
          </material>
        </visual>
        <gravity>1</gravity>
        <velocity_decay/>
        <self_collide>1</self_collide>
        <enable_wind>0</enable_wind>
        <kinematic>0</kinematic>
      </link>
      <joint name='q_1_4_2' type='revolute'>
        <child>leg_B_4_3</child>
        <parent>leg_B_4_2</parent>
        <axis>
          <xyz>0 0 1</xyz>
          <limit>
            <lower>-1.57079</lower>
            <upper>1.57079</upper>
            <effort>1.5</effort>
            <velocity>0.04</velocity>
          </limit>
          <dynamics>
            <damping>0.7</damping>
            <friction>0</friction>
            <spring_reference>0</spring_reference>
            <spring_stiffness>0</spring_stiffness>
          </dynamics>
          <use_parent_model_frame>1</use_parent_model_frame>
        </axis>
      </joint>
      <link name='leg_B_4_4'>
        <pose frame=''>-0.097505 -0.168872 0.11 0 1.57079 -2.09443</pose>
        <inertial>
          <pose frame=''>0.04 0 0 3.14159 -1.57079 3.14159</pose>
          <mass>0.06</mass>
          <inertia>
            <ixx>0.0004</ixx>
            <ixy>0.01</ixy>
            <ixz>0.01</ixz>
            <iyy>0.01</iyy>
            <iyz>0.01</iyz>
            <izz>0.0004</izz>
          </inertia>
        </inertial>
        <collision name='leg_B_4_4_collision'>
          <pose frame=''>0.04 0 0 3.14159 -1.57079 3.14159</pose>
          <geometry>
            <cylinder>
              <length>0.048</length>
              <radius>0.003</radius>
            </cylinder>
          </geometry>
          <surface>
            <contact>
              <ode/>
            </contact>
            <friction>
              <ode/>
              <torsional>
                <ode/>
              </torsional>
            </friction>
            <bounce/>
          </surface>
          <max_contacts>10</max_contacts>
        </collision>
        <visual name='leg_B_4_4_visual'>
          <pose frame=''>0.04 0 0 3.14159 -1.57079 3.14159</pose>
          <geometry>
            <cylinder>
              <length>0.08</length>
              <radius>0.005</radius>
            </cylinder>
          </geometry>
          <material>
            <script>
              <uri>__default__</uri>
              <name>__default__</name>
            </script>
          </material>
        </visual>
        <gravity>1</gravity>
        <velocity_decay/>
        <self_collide>1</self_collide>
        <enable_wind>0</enable_wind>
        <kinematic>0</kinematic>
      </link>
      <joint name='q_1_4_3' type='revolute'>
        <child>leg_B_4_4</child>
        <parent>leg_B_4_3</parent>
        <axis>
          <xyz>0.86601 -0.500026 0</xyz>
          <limit>
            <lower>-1.57079</lower>
            <upper>1.57079</upper>
            <effort>1.8</effort>
            <velocity>0.04</velocity>
          </limit>
          <dynamics>
            <damping>0.7</damping>
            <friction>0</friction>
            <spring_reference>0</spring_reference>
            <spring_stiffness>0</spring_stiffness>
          </dynamics>
          <use_parent_model_frame>1</use_parent_model_frame>
        </axis>
      </joint>
      <link name='leg_B_4_5'>
        <pose frame=''>-0.097505 -0.168872 0.03 1.5708 1.57079 1.04716</pose>
        <inertial>
          <pose frame=''>0.03 0 0 3.14159 1.57079 3.14159</pose>
          <mass>0.06</mass>
          <inertia>
            <ixx>0.0003</ixx>
            <ixy>0.01</ixy>
            <ixz>0.01</ixz>
            <iyy>0.01</iyy>
            <iyz>0.01</iyz>
            <izz>0.0003</izz>
          </inertia>
        </inertial>
        <collision name='leg_B_4_5_collision'>
          <pose frame=''>0.03 0 0 3.14159 1.57079 3.14159</pose>
          <geometry>
            <cylinder>
              <length>0.036</length>
              <radius>0.003</radius>
            </cylinder>
          </geometry>
          <surface>
            <contact>
              <ode/>
            </contact>
            <friction>
              <ode/>
              <torsional>
                <ode/>
              </torsional>
            </friction>
            <bounce/>
          </surface>
          <max_contacts>10</max_contacts>
        </collision>
        <visual name='leg_B_4_5_visual'>
          <pose frame=''>0.03 0 0 3.14159 1.57079 3.14159</pose>
          <geometry>
            <cylinder>
              <length>0.06</length>
              <radius>0.005</radius>
            </cylinder>
          </geometry>
          <material>
            <script>
              <uri>__default__</uri>
              <name>__default__</name>
            </script>
          </material>
        </visual>
        <gravity>1</gravity>
        <velocity_decay/>
        <self_collide>1</self_collide>
        <enable_wind>0</enable_wind>
        <kinematic>0</kinematic>
      </link>
      <joint name='q_1_4_4' type='revolute'>
        <child>leg_B_4_5</child>
        <parent>leg_B_4_4</parent>
        <axis>
          <xyz>0.86601 -0.500027 0</xyz>
          <limit>
            <lower>-1.57079</lower>
            <upper>1.57079</upper>
            <effort>1.8</effort>
            <velocity>0.04</velocity>
          </limit>
          <dynamics>
            <damping>0.7</damping>
            <friction>0</friction>
            <spring_reference>0</spring_reference>
            <spring_stiffness>0</spring_stiffness>
          </dynamics>
          <use_parent_model_frame>1</use_parent_model_frame>
        </axis>
      </joint>
      <link name='leg_B_5_2'>
        <pose frame=''>0.027498 -0.047632 0.11 0 -0 -1.04724</pose>
        <inertial>
          <pose frame=''>0.04 0 0 3.14159 1.57079 3.14159</pose>
          <mass>0.06</mass>
          <inertia>
            <ixx>0.0004</ixx>
            <ixy>0.01</ixy>
            <ixz>0.01</ixz>
            <iyy>0.01</iyy>
            <iyz>0.01</iyz>
            <izz>0.0004</izz>
          </inertia>
        </inertial>
        <collision name='leg_B_5_2_collision'>
          <pose frame=''>0.04 0 0 3.14159 1.57079 3.14159</pose>
          <geometry>
            <cylinder>
              <length>0.024</length>
              <radius>0.003</radius>
            </cylinder>
          </geometry>
          <surface>
            <contact>
              <ode/>
            </contact>
            <friction>
              <ode/>
              <torsional>
                <ode/>
              </torsional>
            </friction>
            <bounce/>
          </surface>
          <max_contacts>10</max_contacts>
        </collision>
        <visual name='leg_B_5_2_visual'>
          <pose frame=''>0.04 0 0 3.14159 1.57079 3.14159</pose>
          <geometry>
            <cylinder>
              <length>0.08</length>
              <radius>0.005</radius>
            </cylinder>
          </geometry>
          <material>
            <script>
              <uri>__default__</uri>
              <name>__default__</name>
            </script>
          </material>
        </visual>
        <gravity>1</gravity>
        <velocity_decay/>
        <self_collide>1</self_collide>
        <enable_wind>0</enable_wind>
        <kinematic>0</kinematic>
      </link>
      <joint name='q_1_5_1' type='revolute'>
        <child>leg_B_5_2</child>
        <parent>map</parent>
        <axis>
          <xyz>0 0 1</xyz>
          <limit>
            <lower>0</lower>
            <upper>3.14159</upper>
            <effort>1.5</effort>
            <velocity>0.04</velocity>
          </limit>
          <dynamics>
            <damping>0.8</damping>
            <friction>0</friction>
            <spring_reference>0</spring_reference>
            <spring_stiffness>0</spring_stiffness>
          </dynamics>
          <use_parent_model_frame>1</use_parent_model_frame>
        </axis>
      </joint>
      <link name='leg_B_5_3'>
        <pose frame=''>0.067496 -0.116916 0.11 0 -0 -1.04724</pose>
        <inertial>
          <pose frame=''>0.03 0 0 3.14159 1.57079 3.14159</pose>
          <mass>0.06</mass>
          <inertia>
            <ixx>0.0003</ixx>
            <ixy>0.01</ixy>
            <ixz>0.01</ixz>
            <iyy>0.01</iyy>
            <iyz>0.01</iyz>
            <izz>0.0003</izz>
          </inertia>
        </inertial>
        <collision name='leg_B_5_3_collision'>
          <pose frame=''>0.03 0 0 3.14159 1.57079 3.14159</pose>
          <geometry>
            <cylinder>
              <length>0.036</length>
              <radius>0.003</radius>
            </cylinder>
          </geometry>
          <surface>
            <contact>
              <ode/>
            </contact>
            <friction>
              <ode/>
              <torsional>
                <ode/>
              </torsional>
            </friction>
            <bounce/>
          </surface>
          <max_contacts>10</max_contacts>
        </collision>
        <visual name='leg_B_5_3_visual'>
          <pose frame=''>0.03 0 0 3.14159 1.57079 3.14159</pose>
          <geometry>
            <cylinder>
              <length>0.06</length>
              <radius>0.005</radius>
            </cylinder>
          </geometry>
          <material>
            <script>
              <uri>__default__</uri>
              <name>__default__</name>
            </script>
          </material>
        </visual>
        <gravity>1</gravity>
        <velocity_decay/>
        <self_collide>1</self_collide>
        <enable_wind>0</enable_wind>
        <kinematic>0</kinematic>
      </link>
      <joint name='q_1_5_2' type='revolute'>
        <child>leg_B_5_3</child>
        <parent>leg_B_5_2</parent>
        <axis>
          <xyz>0 0 1</xyz>
          <limit>
            <lower>-1.57079</lower>
            <upper>1.57079</upper>
            <effort>1.5</effort>
            <velocity>0.04</velocity>
          </limit>
          <dynamics>
            <damping>0.7</damping>
            <friction>0</friction>
            <spring_reference>0</spring_reference>
            <spring_stiffness>0</spring_stiffness>
          </dynamics>
          <use_parent_model_frame>1</use_parent_model_frame>
        </axis>
      </joint>
      <link name='leg_B_5_4'>
        <pose frame=''>0.097494 -0.168879 0.11 0 1.57079 -1.04724</pose>
        <inertial>
          <pose frame=''>0.04 0 0 3.14159 -1.57079 3.14159</pose>
          <mass>0.06</mass>
          <inertia>
            <ixx>0.0004</ixx>
            <ixy>0.01</ixy>
            <ixz>0.01</ixz>
            <iyy>0.01</iyy>
            <iyz>0.01</iyz>
            <izz>0.0004</izz>
          </inertia>
        </inertial>
        <collision name='leg_B_5_4_collision'>
          <pose frame=''>0.04 0 0 3.14159 -1.57079 3.14159</pose>
          <geometry>
            <cylinder>
              <length>0.048</length>
              <radius>0.003</radius>
            </cylinder>
          </geometry>
          <surface>
            <contact>
              <ode/>
            </contact>
            <friction>
              <ode/>
              <torsional>
                <ode/>
              </torsional>
            </friction>
            <bounce/>
          </surface>
          <max_contacts>10</max_contacts>
        </collision>
        <visual name='leg_B_5_4_visual'>
          <pose frame=''>0.04 0 0 3.14159 -1.57079 3.14159</pose>
          <geometry>
            <cylinder>
              <length>0.08</length>
              <radius>0.005</radius>
            </cylinder>
          </geometry>
          <material>
            <script>
              <uri>__default__</uri>
              <name>__default__</name>
            </script>
          </material>
        </visual>
        <gravity>1</gravity>
        <velocity_decay/>
        <self_collide>1</self_collide>
        <enable_wind>0</enable_wind>
        <kinematic>0</kinematic>
      </link>
      <joint name='q_1_5_3' type='revolute'>
        <child>leg_B_5_4</child>
        <parent>leg_B_5_3</parent>
        <axis>
          <xyz>0.866044 0.499967 0</xyz>
          <limit>
            <lower>-1.57079</lower>
            <upper>1.57079</upper>
            <effort>1.8</effort>
            <velocity>0.04</velocity>
          </limit>
          <dynamics>
            <damping>0.7</damping>
            <friction>0</friction>
            <spring_reference>0</spring_reference>
            <spring_stiffness>0</spring_stiffness>
          </dynamics>
          <use_parent_model_frame>1</use_parent_model_frame>
        </axis>
      </joint>
      <link name='leg_B_5_5'>
        <pose frame=''>0.097494 -0.168879 0.03 -1.57079 1.57079 -1.04724</pose>
        <inertial>
          <pose frame=''>0.03 0 0 3.14159 1.57079 3.14159</pose>
          <mass>0.06</mass>
          <inertia>
            <ixx>0.0003</ixx>
            <ixy>0.01</ixy>
            <ixz>0.01</ixz>
            <iyy>0.01</iyy>
            <iyz>0.01</iyz>
            <izz>0.0003</izz>
          </inertia>
        </inertial>
        <collision name='leg_B_5_5_collision'>
          <pose frame=''>0.03 0 0 3.14159 1.57079 3.14159</pose>
          <geometry>
            <cylinder>
              <length>0.036</length>
              <radius>0.003</radius>
            </cylinder>
          </geometry>
          <surface>
            <contact>
              <ode/>
            </contact>
            <friction>
              <ode/>
              <torsional>
                <ode/>
              </torsional>
            </friction>
            <bounce/>
          </surface>
          <max_contacts>10</max_contacts>
        </collision>
        <visual name='leg_B_5_5_visual'>
          <pose frame=''>0.03 0 0 3.14159 1.57079 3.14159</pose>
          <geometry>
            <cylinder>
              <length>0.06</length>
              <radius>0.005</radius>
            </cylinder>
          </geometry>
          <material>
            <script>
              <uri>__default__</uri>
              <name>__default__</name>
            </script>
          </material>
        </visual>
        <gravity>1</gravity>
        <velocity_decay/>
        <self_collide>1</self_collide>
        <enable_wind>0</enable_wind>
        <kinematic>0</kinematic>
      </link>
      <joint name='q_1_5_4' type='revolute'>
        <child>leg_B_5_5</child>
        <parent>leg_B_5_4</parent>
        <axis>
          <xyz>0.866045 0.499966 0</xyz>
          <limit>
            <lower>-1.57079</lower>
            <upper>1.57079</upper>
            <effort>1.8</effort>
            <velocity>0.04</velocity>
          </limit>
          <dynamics>
            <damping>0.7</damping>
            <friction>0</friction>
            <spring_reference>0</spring_reference>
            <spring_stiffness>0</spring_stiffness>
          </dynamics>
          <use_parent_model_frame>1</use_parent_model_frame>
        </axis>
      </joint>
      <link name='leg_B_6_2'>
        <pose frame=''>0.055 -2e-06 0.11 0 -0 -4.5e-05</pose>
        <inertial>
          <pose frame=''>0.04 0 0 3.14159 1.57079 3.14159</pose>
          <mass>0.06</mass>
          <inertia>
            <ixx>0.0004</ixx>
            <ixy>0.01</ixy>
            <ixz>0.01</ixz>
            <iyy>0.01</iyy>
            <iyz>0.01</iyz>
            <izz>0.0004</izz>
          </inertia>
        </inertial>
        <collision name='leg_B_6_2_collision'>
          <pose frame=''>0.04 0 0 3.14159 1.57079 3.14159</pose>
          <geometry>
            <cylinder>
              <length>0.024</length>
              <radius>0.003</radius>
            </cylinder>
          </geometry>
          <surface>
            <contact>
              <ode/>
            </contact>
            <friction>
              <ode/>
              <torsional>
                <ode/>
              </torsional>
            </friction>
            <bounce/>
          </surface>
          <max_contacts>10</max_contacts>
        </collision>
        <visual name='leg_B_6_2_visual'>
          <pose frame=''>0.04 0 0 3.14159 1.57079 3.14159</pose>
          <geometry>
            <cylinder>
              <length>0.08</length>
              <radius>0.005</radius>
            </cylinder>
          </geometry>
          <material>
            <script>
              <uri>__default__</uri>
              <name>__default__</name>
            </script>
          </material>
        </visual>
        <gravity>1</gravity>
        <velocity_decay/>
        <self_collide>1</self_collide>
        <enable_wind>0</enable_wind>
        <kinematic>0</kinematic>
      </link>
      <joint name='q_1_6_1' type='revolute'>
        <child>leg_B_6_2</child>
        <parent>map</parent>
        <axis>
          <xyz>0 0 1</xyz>
          <limit>
            <lower>0</lower>
            <upper>3.14159</upper>
            <effort>1.5</effort>
            <velocity>0.04</velocity>
          </limit>
          <dynamics>
            <damping>0.8</damping>
            <friction>0</friction>
            <spring_reference>0</spring_reference>
            <spring_stiffness>0</spring_stiffness>
          </dynamics>
          <use_parent_model_frame>1</use_parent_model_frame>
        </axis>
      </joint>
      <link name='leg_B_6_3'>
        <pose frame=''>0.135 -6e-06 0.11 0 -0 -4.5e-05</pose>
        <inertial>
          <pose frame=''>0.03 0 0 3.14159 1.57079 3.14159</pose>
          <mass>0.06</mass>
          <inertia>
            <ixx>0.0003</ixx>
            <ixy>0.01</ixy>
            <ixz>0.01</ixz>
            <iyy>0.01</iyy>
            <iyz>0.01</iyz>
            <izz>0.0003</izz>
          </inertia>
        </inertial>
        <collision name='leg_B_6_3_collision'>
          <pose frame=''>0.03 0 0 3.14159 1.57079 3.14159</pose>
          <geometry>
            <cylinder>
              <length>0.036</length>
              <radius>0.003</radius>
            </cylinder>
          </geometry>
          <surface>
            <contact>
              <ode/>
            </contact>
            <friction>
              <ode/>
              <torsional>
                <ode/>
              </torsional>
            </friction>
            <bounce/>
          </surface>
          <max_contacts>10</max_contacts>
        </collision>
        <visual name='leg_B_6_3_visual'>
          <pose frame=''>0.03 0 0 3.14159 1.57079 3.14159</pose>
          <geometry>
            <cylinder>
              <length>0.06</length>
              <radius>0.005</radius>
            </cylinder>
          </geometry>
          <material>
            <script>
              <uri>__default__</uri>
              <name>__default__</name>
            </script>
          </material>
        </visual>
        <gravity>1</gravity>
        <velocity_decay/>
        <self_collide>1</self_collide>
        <enable_wind>0</enable_wind>
        <kinematic>0</kinematic>
      </link>
      <joint name='q_1_6_2' type='revolute'>
        <child>leg_B_6_3</child>
        <parent>leg_B_6_2</parent>
        <axis>
          <xyz>0 0 1</xyz>
          <limit>
            <lower>-1.57079</lower>
            <upper>1.57079</upper>
            <effort>1.5</effort>
            <velocity>0.04</velocity>
          </limit>
          <dynamics>
            <damping>0.7</damping>
            <friction>0</friction>
            <spring_reference>0</spring_reference>
            <spring_stiffness>0</spring_stiffness>
          </dynamics>
          <use_parent_model_frame>1</use_parent_model_frame>
        </axis>
      </joint>
      <link name='leg_B_6_4'>
        <pose frame=''>0.195 -9e-06 0.11 -3.14159 1.57079 3.14155</pose>
        <inertial>
          <pose frame=''>0.04 0 0 3.14159 -1.57079 3.14159</pose>
          <mass>0.06</mass>
          <inertia>
            <ixx>0.0004</ixx>
            <ixy>0.01</ixy>
            <ixz>0.01</ixz>
            <iyy>0.01</iyy>
            <iyz>0.01</iyz>
            <izz>0.0004</izz>
          </inertia>
        </inertial>
        <collision name='leg_B_6_4_collision'>
          <pose frame=''>0.04 0 0 3.14159 -1.57079 3.14159</pose>
          <geometry>
            <cylinder>
              <length>0.048</length>
              <radius>0.003</radius>
            </cylinder>
          </geometry>
          <surface>
            <contact>
              <ode/>
            </contact>
            <friction>
              <ode/>
              <torsional>
                <ode/>
              </torsional>
            </friction>
            <bounce/>
          </surface>
          <max_contacts>10</max_contacts>
        </collision>
        <visual name='leg_B_6_4_visual'>
          <pose frame=''>0.04 0 0 3.14159 -1.57079 3.14159</pose>
          <geometry>
            <cylinder>
              <length>0.08</length>
              <radius>0.005</radius>
            </cylinder>
          </geometry>
          <material>
            <script>
              <uri>__default__</uri>
              <name>__default__</name>
            </script>
          </material>
        </visual>
        <gravity>1</gravity>
        <velocity_decay/>
        <self_collide>1</self_collide>
        <enable_wind>0</enable_wind>
        <kinematic>0</kinematic>
      </link>
      <joint name='q_1_6_3' type='revolute'>
        <child>leg_B_6_4</child>
        <parent>leg_B_6_3</parent>
        <axis>
          <xyz>4.5e-05 1 0</xyz>
          <limit>
            <lower>-1.57079</lower>
            <upper>1.57079</upper>
            <effort>1.8</effort>
            <velocity>0.04</velocity>
          </limit>
          <dynamics>
            <damping>0.7</damping>
            <friction>0</friction>
            <spring_reference>0</spring_reference>
            <spring_stiffness>0</spring_stiffness>
          </dynamics>
          <use_parent_model_frame>1</use_parent_model_frame>
        </axis>
      </joint>
      <link name='leg_B_6_5'>
        <pose frame=''>0.195 -9e-06 0.03 1.57079 1.57079 3.14155</pose>
        <inertial>
          <pose frame=''>0.03 0 0 3.14159 1.57079 3.14159</pose>
          <mass>0.06</mass>
          <inertia>
            <ixx>0.0003</ixx>
            <ixy>0.01</ixy>
            <ixz>0.01</ixz>
            <iyy>0.01</iyy>
            <iyz>0.01</iyz>
            <izz>0.0003</izz>
          </inertia>
        </inertial>
        <collision name='leg_B_6_5_collision'>
          <pose frame=''>0.03 0 0 3.14159 1.57079 3.14159</pose>
          <geometry>
            <cylinder>
              <length>0.036</length>
              <radius>0.003</radius>
            </cylinder>
          </geometry>
          <surface>
            <contact>
              <ode/>
            </contact>
            <friction>
              <ode/>
              <torsional>
                <ode/>
              </torsional>
            </friction>
            <bounce/>
          </surface>
          <max_contacts>10</max_contacts>
        </collision>
        <visual name='leg_B_6_5_visual'>
          <pose frame=''>0.03 0 0 3.14159 1.57079 3.14159</pose>
          <geometry>
            <cylinder>
              <length>0.06</length>
              <radius>0.005</radius>
            </cylinder>
          </geometry>
          <material>
            <script>
              <uri>__default__</uri>
              <name>__default__</name>
            </script>
          </material>
        </visual>
        <gravity>1</gravity>
        <velocity_decay/>
        <self_collide>1</self_collide>
        <enable_wind>0</enable_wind>
        <kinematic>0</kinematic>
      </link>
      <joint name='q_1_6_4' type='revolute'>
        <child>leg_B_6_5</child>
        <parent>leg_B_6_4</parent>
        <axis>
          <xyz>4.7e-05 1 0</xyz>
          <limit>
            <lower>-1.57079</lower>
            <upper>1.57079</upper>
            <effort>1.8</effort>
            <velocity>0.04</velocity>
          </limit>
          <dynamics>
            <damping>0.7</damping>
            <friction>0</friction>
            <spring_reference>0</spring_reference>
            <spring_stiffness>0</spring_stiffness>
          </dynamics>
          <use_parent_model_frame>1</use_parent_model_frame>
        </axis>
      </joint>
      <link name='L_U_1_1'>
        <pose frame=''>0.040001 0.069282 0.23 0 -0 1.04719</pose>
        <inertial>
          <pose frame=''>0.03 0 0 3.14159 1.57079 3.14159</pose>
          <mass>0.06</mass>
          <inertia>
            <ixx>0.0003</ixx>
            <ixy>0.01</ixy>
            <ixz>0.01</ixz>
            <iyy>0.01</iyy>
            <iyz>0.01</iyz>
            <izz>0.0003</izz>
          </inertia>
        </inertial>
        <collision name='L_U_1_1_collision'>
          <pose frame=''>0.03 0 0 3.14159 1.57079 3.14159</pose>
          <geometry>
            <cylinder>
              <length>0.036</length>
              <radius>0.003</radius>
            </cylinder>
          </geometry>
          <max_contacts>10</max_contacts>
          <surface>
            <contact>
              <ode/>
            </contact>
            <bounce/>
            <friction>
              <torsional>
                <ode/>
              </torsional>
              <ode/>
            </friction>
          </surface>
        </collision>
        <visual name='L_U_1_1_visual'>
          <pose frame=''>0.03 0 0 3.14159 1.57079 3.14159</pose>
          <geometry>
            <cylinder>
              <length>0.06</length>
              <radius>0.005</radius>
            </cylinder>
          </geometry>
        </visual>
        <self_collide>0</self_collide>
        <enable_wind>0</enable_wind>
        <kinematic>0</kinematic>
      </link>
      <joint name='q_2_1_1' type='revolute'>
        <child>L_U_1_1</child>
        <parent>map</parent>
        <axis>
          <xyz>-0.866022 0.500007 0</xyz>
          <limit>
            <lower>-1.57079</lower>
            <upper>1.57079</upper>
            <effort>1.5</effort>
            <velocity>0.04</velocity>
          </limit>
          <dynamics>
            <damping>0.8</damping>
            <friction>0</friction>
            <spring_reference>0</spring_reference>
            <spring_stiffness>0</spring_stiffness>
          </dynamics>
          <use_parent_model_frame>1</use_parent_model_frame>
        </axis>
      </joint>
      <link name='L_U_1_2'>
        <pose frame=''>0.070001 0.121243 0.23 3.14159 -1.57079 -2.0944</pose>
        <inertial>
          <pose frame=''>0.03 0 0 3.14159 1.57079 3.14159</pose>
          <mass>0.06</mass>
          <inertia>
            <ixx>0.0003</ixx>
            <ixy>0.01</ixy>
            <ixz>0.01</ixz>
            <iyy>0.01</iyy>
            <iyz>0.01</iyz>
            <izz>0.0003</izz>
          </inertia>
        </inertial>
        <collision name='L_U_1_2_collision'>
          <pose frame=''>0.03 0 0 3.14159 1.57079 3.14159</pose>
          <geometry>
            <cylinder>
              <length>0.036</length>
              <radius>0.003</radius>
            </cylinder>
          </geometry>
          <max_contacts>10</max_contacts>
          <surface>
            <contact>
              <ode/>
            </contact>
            <bounce/>
            <friction>
              <torsional>
                <ode/>
              </torsional>
              <ode/>
            </friction>
          </surface>
        </collision>
        <visual name='L_U_1_2_visual'>
          <pose frame=''>0.03 0 0 3.14159 1.57079 3.14159</pose>
          <geometry>
            <cylinder>
              <length>0.06</length>
              <radius>0.005</radius>
            </cylinder>
          </geometry>
        </visual>
        <self_collide>0</self_collide>
        <enable_wind>0</enable_wind>
        <kinematic>0</kinematic>
      </link>
      <joint name='q_2_1_2' type='revolute'>
        <child>L_U_1_2</child>
        <parent>L_U_1_1</parent>
        <axis>
          <xyz>-0.866022 0.500007 0</xyz>
          <limit>
            <lower>-1.57079</lower>
            <upper>1.57079</upper>
            <effort>1.5</effort>
            <velocity>0.04</velocity>
          </limit>
          <dynamics>
            <damping>0.8</damping>
            <friction>0</friction>
            <spring_reference>0</spring_reference>
            <spring_stiffness>0</spring_stiffness>
          </dynamics>
          <use_parent_model_frame>1</use_parent_model_frame>
        </axis>
      </joint>
      <link name='L_U_2_1'>
        <pose frame=''>-0.039999 0.069283 0.23 0 -0 2.09438</pose>
        <inertial>
          <pose frame=''>0.03 0 0 3.14159 1.57079 3.14159</pose>
          <mass>0.06</mass>
          <inertia>
            <ixx>0.0003</ixx>
            <ixy>0.01</ixy>
            <ixz>0.01</ixz>
            <iyy>0.01</iyy>
            <iyz>0.01</iyz>
            <izz>0.0003</izz>
          </inertia>
        </inertial>
        <collision name='L_U_2_1_collision'>
          <pose frame=''>0.03 0 0 3.14159 1.57079 3.14159</pose>
          <geometry>
            <cylinder>
              <length>0.036</length>
              <radius>0.003</radius>
            </cylinder>
          </geometry>
          <max_contacts>10</max_contacts>
          <surface>
            <contact>
              <ode/>
            </contact>
            <bounce/>
            <friction>
              <torsional>
                <ode/>
              </torsional>
              <ode/>
            </friction>
          </surface>
        </collision>
        <visual name='L_U_2_1_visual'>
          <pose frame=''>0.03 0 0 3.14159 1.57079 3.14159</pose>
          <geometry>
            <cylinder>
              <length>0.06</length>
              <radius>0.005</radius>
            </cylinder>
          </geometry>
        </visual>
        <self_collide>0</self_collide>
        <enable_wind>0</enable_wind>
        <kinematic>0</kinematic>
      </link>
      <joint name='q_2_2_1' type='revolute'>
        <child>L_U_2_1</child>
        <parent>map</parent>
        <axis>
          <xyz>-0.866033 -0.499987 0</xyz>
          <limit>
            <lower>-1.57079</lower>
            <upper>1.57079</upper>
            <effort>1.5</effort>
            <velocity>0.04</velocity>
          </limit>
          <dynamics>
            <damping>0.8</damping>
            <friction>0</friction>
            <spring_reference>0</spring_reference>
            <spring_stiffness>0</spring_stiffness>
          </dynamics>
          <use_parent_model_frame>1</use_parent_model_frame>
        </axis>
      </joint>
      <link name='L_U_2_2'>
        <pose frame=''>-0.069998 0.121245 0.23 -3.14159 -1.57079 -1.04721</pose>
        <inertial>
          <pose frame=''>0.03 0 0 3.14159 1.57079 3.14159</pose>
          <mass>0.06</mass>
          <inertia>
            <ixx>0.0003</ixx>
            <ixy>0.01</ixy>
            <ixz>0.01</ixz>
            <iyy>0.01</iyy>
            <iyz>0.01</iyz>
            <izz>0.0003</izz>
          </inertia>
        </inertial>
        <collision name='L_U_2_2_collision'>
          <pose frame=''>0.03 0 0 3.14159 1.57079 3.14159</pose>
          <geometry>
            <cylinder>
              <length>0.036</length>
              <radius>0.003</radius>
            </cylinder>
          </geometry>
          <max_contacts>10</max_contacts>
          <surface>
            <contact>
              <ode/>
            </contact>
            <bounce/>
            <friction>
              <torsional>
                <ode/>
              </torsional>
              <ode/>
            </friction>
          </surface>
        </collision>
        <visual name='L_U_2_2_visual'>
          <pose frame=''>0.03 0 0 3.14159 1.57079 3.14159</pose>
          <geometry>
            <cylinder>
              <length>0.06</length>
              <radius>0.005</radius>
            </cylinder>
          </geometry>
        </visual>
        <self_collide>0</self_collide>
        <enable_wind>0</enable_wind>
        <kinematic>0</kinematic>
      </link>
      <joint name='q_2_2_2' type='revolute'>
        <child>L_U_2_2</child>
        <parent>L_U_2_1</parent>
        <axis>
          <xyz>-0.866033 -0.499987 0</xyz>
          <limit>
            <lower>-1.57079</lower>
            <upper>1.57079</upper>
            <effort>1.5</effort>
            <velocity>0.04</velocity>
          </limit>
          <dynamics>
            <damping>0.8</damping>
            <friction>0</friction>
            <spring_reference>0</spring_reference>
            <spring_stiffness>0</spring_stiffness>
          </dynamics>
          <use_parent_model_frame>1</use_parent_model_frame>
        </axis>
      </joint>
      <link name='L_U_3_1'>
        <pose frame=''>-0.08 2e-06 0.23 0 -0 3.14157</pose>
        <inertial>
          <pose frame=''>0.03 0 0 3.14159 1.57079 3.14159</pose>
          <mass>0.06</mass>
          <inertia>
            <ixx>0.0003</ixx>
            <ixy>0.01</ixy>
            <ixz>0.01</ixz>
            <iyy>0.01</iyy>
            <iyz>0.01</iyz>
            <izz>0.0003</izz>
          </inertia>
        </inertial>
        <collision name='L_U_3_1_collision'>
          <pose frame=''>0.03 0 0 3.14159 1.57079 3.14159</pose>
          <geometry>
            <cylinder>
              <length>0.036</length>
              <radius>0.003</radius>
            </cylinder>
          </geometry>
          <max_contacts>10</max_contacts>
          <surface>
            <contact>
              <ode/>
            </contact>
            <bounce/>
            <friction>
              <torsional>
                <ode/>
              </torsional>
              <ode/>
            </friction>
          </surface>
        </collision>
        <visual name='L_U_3_1_visual'>
          <pose frame=''>0.03 0 0 3.14159 1.57079 3.14159</pose>
          <geometry>
            <cylinder>
              <length>0.06</length>
              <radius>0.005</radius>
            </cylinder>
          </geometry>
        </visual>
        <self_collide>0</self_collide>
        <enable_wind>0</enable_wind>
        <kinematic>0</kinematic>
      </link>
      <joint name='q_2_3_1' type='revolute'>
        <child>L_U_3_1</child>
        <parent>map</parent>
        <axis>
          <xyz>-2.3e-05 -1 0</xyz>
          <limit>
            <lower>-1.57079</lower>
            <upper>1.57079</upper>
            <effort>1.5</effort>
            <velocity>0.04</velocity>
          </limit>
          <dynamics>
            <damping>0.8</damping>
            <friction>0</friction>
            <spring_reference>0</spring_reference>
            <spring_stiffness>0</spring_stiffness>
          </dynamics>
          <use_parent_model_frame>1</use_parent_model_frame>
        </axis>
      </joint>
      <link name='L_U_3_2'>
        <pose frame=''>-0.14 3e-06 0.23 3.14159 -1.57079 -2.3e-05</pose>
        <inertial>
          <pose frame=''>0.03 0 0 3.14159 1.57079 3.14159</pose>
          <mass>0.06</mass>
          <inertia>
            <ixx>0.0003</ixx>
            <ixy>0.01</ixy>
            <ixz>0.01</ixz>
            <iyy>0.01</iyy>
            <iyz>0.01</iyz>
            <izz>0.0003</izz>
          </inertia>
        </inertial>
        <collision name='L_U_3_2_collision'>
          <pose frame=''>0.03 0 0 3.14159 1.57079 3.14159</pose>
          <geometry>
            <cylinder>
              <length>0.036</length>
              <radius>0.003</radius>
            </cylinder>
          </geometry>
          <max_contacts>10</max_contacts>
          <surface>
            <contact>
              <ode/>
            </contact>
            <bounce/>
            <friction>
              <torsional>
                <ode/>
              </torsional>
              <ode/>
            </friction>
          </surface>
        </collision>
        <visual name='L_U_3_2_visual'>
          <pose frame=''>0.03 0 0 3.14159 1.57079 3.14159</pose>
          <geometry>
            <cylinder>
              <length>0.06</length>
              <radius>0.005</radius>
            </cylinder>
          </geometry>
        </visual>
        <self_collide>0</self_collide>
        <enable_wind>0</enable_wind>
        <kinematic>0</kinematic>
      </link>
      <joint name='q_2_3_2' type='revolute'>
        <child>L_U_3_2</child>
        <parent>L_U_3_1</parent>
        <axis>
          <xyz>-2.3e-05 -1 0</xyz>
          <limit>
            <lower>-1.57079</lower>
            <upper>1.57079</upper>
            <effort>1.5</effort>
            <velocity>0.04</velocity>
          </limit>
          <dynamics>
            <damping>0.8</damping>
            <friction>0</friction>
            <spring_reference>0</spring_reference>
            <spring_stiffness>0</spring_stiffness>
          </dynamics>
          <use_parent_model_frame>1</use_parent_model_frame>
        </axis>
      </joint>
      <link name='L_U_4_1'>
        <pose frame=''>-0.040002 -0.069281 0.23 0 -0 -2.09443</pose>
        <inertial>
          <pose frame=''>0.03 0 0 3.14159 1.57079 3.14159</pose>
          <mass>0.06</mass>
          <inertia>
            <ixx>0.0003</ixx>
            <ixy>0.01</ixy>
            <ixz>0.01</ixz>
            <iyy>0.01</iyy>
            <iyz>0.01</iyz>
            <izz>0.0003</izz>
          </inertia>
        </inertial>
        <collision name='L_U_4_1_collision'>
          <pose frame=''>0.03 0 0 3.14159 1.57079 3.14159</pose>
          <geometry>
            <cylinder>
              <length>0.036</length>
              <radius>0.003</radius>
            </cylinder>
          </geometry>
          <max_contacts>10</max_contacts>
          <surface>
            <contact>
              <ode/>
            </contact>
            <bounce/>
            <friction>
              <torsional>
                <ode/>
              </torsional>
              <ode/>
            </friction>
          </surface>
        </collision>
        <visual name='L_U_4_1_visual'>
          <pose frame=''>0.03 0 0 3.14159 1.57079 3.14159</pose>
          <geometry>
            <cylinder>
              <length>0.06</length>
              <radius>0.005</radius>
            </cylinder>
          </geometry>
        </visual>
        <self_collide>0</self_collide>
        <enable_wind>0</enable_wind>
        <kinematic>0</kinematic>
      </link>
      <joint name='q_2_4_1' type='revolute'>
        <child>L_U_4_1</child>
        <parent>map</parent>
        <axis>
          <xyz>0.86601 -0.500026 0</xyz>
          <limit>
            <lower>-1.57079</lower>
            <upper>1.57079</upper>
            <effort>1.5</effort>
            <velocity>0.04</velocity>
          </limit>
          <dynamics>
            <damping>0.8</damping>
            <friction>0</friction>
            <spring_reference>0</spring_reference>
            <spring_stiffness>0</spring_stiffness>
          </dynamics>
          <use_parent_model_frame>1</use_parent_model_frame>
        </axis>
      </joint>
      <link name='L_U_4_2'>
        <pose frame=''>-0.070004 -0.121241 0.23 0 -1.57079 -2.09443</pose>
        <inertial>
          <pose frame=''>0.03 0 0 3.14159 1.57079 3.14159</pose>
          <mass>0.06</mass>
          <inertia>
            <ixx>0.0003</ixx>
            <ixy>0.01</ixy>
            <ixz>0.01</ixz>
            <iyy>0.01</iyy>
            <iyz>0.01</iyz>
            <izz>0.0003</izz>
          </inertia>
        </inertial>
        <collision name='L_U_4_2_collision'>
          <pose frame=''>0.03 0 0 3.14159 1.57079 3.14159</pose>
          <geometry>
            <cylinder>
              <length>0.036</length>
              <radius>0.003</radius>
            </cylinder>
          </geometry>
          <max_contacts>10</max_contacts>
          <surface>
            <contact>
              <ode/>
            </contact>
            <bounce/>
            <friction>
              <torsional>
                <ode/>
              </torsional>
              <ode/>
            </friction>
          </surface>
        </collision>
        <visual name='L_U_4_2_visual'>
          <pose frame=''>0.03 0 0 3.14159 1.57079 3.14159</pose>
          <geometry>
            <cylinder>
              <length>0.06</length>
              <radius>0.005</radius>
            </cylinder>
          </geometry>
        </visual>
        <self_collide>0</self_collide>
        <enable_wind>0</enable_wind>
        <kinematic>0</kinematic>
      </link>
      <joint name='q_2_4_2' type='revolute'>
        <child>L_U_4_2</child>
        <parent>L_U_4_1</parent>
        <axis>
          <xyz>0.86601 -0.500026 -0</xyz>
          <limit>
            <lower>-1.57079</lower>
            <upper>1.57079</upper>
            <effort>1.5</effort>
            <velocity>0.04</velocity>
          </limit>
          <dynamics>
            <damping>0.8</damping>
            <friction>0</friction>
            <spring_reference>0</spring_reference>
            <spring_stiffness>0</spring_stiffness>
          </dynamics>
          <use_parent_model_frame>1</use_parent_model_frame>
        </axis>
      </joint>
      <link name='L_U_5_1'>
        <pose frame=''>0.039997 -0.069284 0.23 0 -0 -1.04724</pose>
        <inertial>
          <pose frame=''>0.03 0 0 3.14159 1.57079 3.14159</pose>
          <mass>0.06</mass>
          <inertia>
            <ixx>0.0003</ixx>
            <ixy>0.01</ixy>
            <ixz>0.01</ixz>
            <iyy>0.01</iyy>
            <iyz>0.01</iyz>
            <izz>0.0003</izz>
          </inertia>
        </inertial>
        <collision name='L_U_5_1_collision'>
          <pose frame=''>0.03 0 0 3.14159 1.57079 3.14159</pose>
          <geometry>
            <cylinder>
              <length>0.036</length>
              <radius>0.003</radius>
            </cylinder>
          </geometry>
          <max_contacts>10</max_contacts>
          <surface>
            <contact>
              <ode/>
            </contact>
            <bounce/>
            <friction>
              <torsional>
                <ode/>
              </torsional>
              <ode/>
            </friction>
          </surface>
        </collision>
        <visual name='L_U_5_1_visual'>
          <pose frame=''>0.03 0 0 3.14159 1.57079 3.14159</pose>
          <geometry>
            <cylinder>
              <length>0.06</length>
              <radius>0.005</radius>
            </cylinder>
          </geometry>
        </visual>
        <self_collide>0</self_collide>
        <enable_wind>0</enable_wind>
        <kinematic>0</kinematic>
      </link>
      <joint name='q_2_5_1' type='revolute'>
        <child>L_U_5_1</child>
        <parent>map</parent>
        <axis>
          <xyz>0.866044 0.499967 0</xyz>
          <limit>
            <lower>-1.57079</lower>
            <upper>1.57079</upper>
            <effort>1.5</effort>
            <velocity>0.04</velocity>
          </limit>
          <dynamics>
            <damping>0.8</damping>
            <friction>0</friction>
            <spring_reference>0</spring_reference>
            <spring_stiffness>0</spring_stiffness>
          </dynamics>
          <use_parent_model_frame>1</use_parent_model_frame>
        </axis>
      </joint>
      <link name='L_U_5_2'>
        <pose frame=''>0.069995 -0.121246 0.23 0 -1.57079 -1.04724</pose>
        <inertial>
          <pose frame=''>0.03 0 0 3.14159 1.57079 3.14159</pose>
          <mass>0.06</mass>
          <inertia>
            <ixx>0.0003</ixx>
            <ixy>0.01</ixy>
            <ixz>0.01</ixz>
            <iyy>0.01</iyy>
            <iyz>0.01</iyz>
            <izz>0.0003</izz>
          </inertia>
        </inertial>
        <collision name='L_U_5_2_collision'>
          <pose frame=''>0.03 0 0 3.14159 1.57079 3.14159</pose>
          <geometry>
            <cylinder>
              <length>0.036</length>
              <radius>0.003</radius>
            </cylinder>
          </geometry>
          <max_contacts>10</max_contacts>
          <surface>
            <contact>
              <ode/>
            </contact>
            <bounce/>
            <friction>
              <torsional>
                <ode/>
              </torsional>
              <ode/>
            </friction>
          </surface>
        </collision>
        <visual name='L_U_5_2_visual'>
          <pose frame=''>0.03 0 0 3.14159 1.57079 3.14159</pose>
          <geometry>
            <cylinder>
              <length>0.06</length>
              <radius>0.005</radius>
            </cylinder>
          </geometry>
        </visual>
        <self_collide>0</self_collide>
        <enable_wind>0</enable_wind>
        <kinematic>0</kinematic>
      </link>
      <joint name='q_2_5_2' type='revolute'>
        <child>L_U_5_2</child>
        <parent>L_U_5_1</parent>
        <axis>
          <xyz>0.866044 0.499967 -0</xyz>
          <limit>
            <lower>-1.57079</lower>
            <upper>1.57079</upper>
            <effort>1.5</effort>
            <velocity>0.04</velocity>
          </limit>
          <dynamics>
            <damping>0.8</damping>
            <friction>0</friction>
            <spring_reference>0</spring_reference>
            <spring_stiffness>0</spring_stiffness>
          </dynamics>
          <use_parent_model_frame>1</use_parent_model_frame>
        </axis>
      </joint>
      <link name='L_U_6_1'>
        <pose frame=''>0.08 -4e-06 0.23 0 -0 -4.5e-05</pose>
        <inertial>
          <pose frame=''>0.03 0 0 3.14159 1.57079 3.14159</pose>
          <mass>0.06</mass>
          <inertia>
            <ixx>0.0003</ixx>
            <ixy>0.01</ixy>
            <ixz>0.01</ixz>
            <iyy>0.01</iyy>
            <iyz>0.01</iyz>
            <izz>0.0003</izz>
          </inertia>
        </inertial>
        <collision name='L_U_6_1_collision'>
          <pose frame=''>0.03 0 0 3.14159 1.57079 3.14159</pose>
          <geometry>
            <cylinder>
              <length>0.036</length>
              <radius>0.003</radius>
            </cylinder>
          </geometry>
          <max_contacts>10</max_contacts>
          <surface>
            <contact>
              <ode/>
            </contact>
            <bounce/>
            <friction>
              <torsional>
                <ode/>
              </torsional>
              <ode/>
            </friction>
          </surface>
        </collision>
        <visual name='L_U_6_1_visual'>
          <pose frame=''>0.03 0 0 3.14159 1.57079 3.14159</pose>
          <geometry>
            <cylinder>
              <length>0.06</length>
              <radius>0.005</radius>
            </cylinder>
          </geometry>
        </visual>
        <self_collide>0</self_collide>
        <enable_wind>0</enable_wind>
        <kinematic>0</kinematic>
      </link>
      <joint name='q_2_6_1' type='revolute'>
        <child>L_U_6_1</child>
        <parent>map</parent>
        <axis>
          <xyz>4.5e-05 1 0</xyz>
          <limit>
            <lower>-1.57079</lower>
            <upper>1.57079</upper>
            <effort>1.5</effort>
            <velocity>0.04</velocity>
          </limit>
          <dynamics>
            <damping>0.8</damping>
            <friction>0</friction>
            <spring_reference>0</spring_reference>
            <spring_stiffness>0</spring_stiffness>
          </dynamics>
          <use_parent_model_frame>1</use_parent_model_frame>
        </axis>
      </joint>
      <link name='L_U_6_2'>
        <pose frame=''>0.14 -6e-06 0.23 3.14159 -1.57079 3.14155</pose>
        <inertial>
          <pose frame=''>0.03 0 0 3.14159 1.57079 3.14159</pose>
          <mass>0.06</mass>
          <inertia>
            <ixx>0.0003</ixx>
            <ixy>0.01</ixy>
            <ixz>0.01</ixz>
            <iyy>0.01</iyy>
            <iyz>0.01</iyz>
            <izz>0.0003</izz>
          </inertia>
        </inertial>
        <collision name='L_U_6_2_collision'>
          <pose frame=''>0.03 0 0 3.14159 1.57079 3.14159</pose>
          <geometry>
            <cylinder>
              <length>0.036</length>
              <radius>0.003</radius>
            </cylinder>
          </geometry>
          <max_contacts>10</max_contacts>
          <surface>
            <contact>
              <ode/>
            </contact>
            <bounce/>
            <friction>
              <torsional>
                <ode/>
              </torsional>
              <ode/>
            </friction>
          </surface>
        </collision>
        <visual name='L_U_6_2_visual'>
          <pose frame=''>0.03 0 0 3.14159 1.57079 3.14159</pose>
          <geometry>
            <cylinder>
              <length>0.06</length>
              <radius>0.005</radius>
            </cylinder>
          </geometry>
        </visual>
        <self_collide>0</self_collide>
        <enable_wind>0</enable_wind>
        <kinematic>0</kinematic>
      </link>
      <joint name='q_2_6_2' type='revolute'>
        <child>L_U_6_2</child>
        <parent>L_U_6_1</parent>
        <axis>
          <xyz>4.5e-05 1 -0</xyz>
          <limit>
            <lower>-1.57079</lower>
            <upper>1.57079</upper>
            <effort>1.5</effort>
            <velocity>0.04</velocity>
          </limit>
          <dynamics>
            <damping>0.8</damping>
            <friction>0</friction>
            <spring_reference>0</spring_reference>
            <spring_stiffness>0</spring_stiffness>
          </dynamics>
          <use_parent_model_frame>1</use_parent_model_frame>
        </axis>
      </joint>
      <link name='support_c'>
        <pose frame=''>0 0 0.14 0 -0 0</pose>
        <inertial>
          <pose frame=''>0 0 0 0 -0 0</pose>
          <mass>0.001</mass>
          <inertia>
            <ixx>0.001</ixx>
            <ixy>0.001</ixy>
            <ixz>0.001</ixz>
            <iyy>0.001</iyy>
            <iyz>0.001</iyz>
            <izz>0.001</izz>
          </inertia>
        </inertial>
        <collision name='support_c_collision'>
          <pose frame=''>0 0 0 0 -0 0</pose>
          <geometry>
            <cylinder>
              <length>0.001</length>
              <radius>0.001</radius>
            </cylinder>
          </geometry>
          <surface>
            <contact>
              <ode/>
            </contact>
            <friction>
              <ode/>
              <torsional>
                <ode/>
              </torsional>
            </friction>
            <bounce/>
          </surface>
          <max_contacts>10</max_contacts>
        </collision>
        <gravity>1</gravity>
        <velocity_decay/>
        <self_collide>1</self_collide>
        <enable_wind>0</enable_wind>
        <kinematic>0</kinematic>
      </link>
      <joint name='q_c' type='revolute'>
        <child>support_c</child>
        <parent>map</parent>
        <axis>
          <xyz>0 0 1</xyz>
          <limit>
            <lower>0</lower>
            <upper>3.14159</upper>
            <effort>1.5</effort>
            <velocity>0.04</velocity>
          </limit>
          <dynamics>
            <damping>0.8</damping>
            <friction>0</friction>
            <spring_reference>0</spring_reference>
            <spring_stiffness>0</spring_stiffness>
          </dynamics>
          <use_parent_model_frame>1</use_parent_model_frame>
        </axis>
      </joint>
      <static>0</static>
      <plugin name='gazebo_ros_control' filename='libgazebo_ros_control.so'>
        <robotNamespace>/shell_robot_model</robotNamespace>
        <robotSimType>gazebo_ros_control/DefaultRobotHWSim</robotSimType>
      </plugin>
      <pose frame=''>0 0 0 0 -0 0</pose>
    </model>
    <state world_name='default'>
      <sim_time>0 0</sim_time>
      <real_time>0 0</real_time>
      <wall_time>1582564532 587798712</wall_time>
      <iterations>0</iterations>
      <model name='ground_plane'>
        <pose frame=''>0 0 0 0 -0 0</pose>
        <scale>1 1 1</scale>
        <link name='link'>
          <pose frame=''>0 0 0 0 -0 0</pose>
          <velocity>0 0 0 0 -0 0</velocity>
          <acceleration>0 0 0 0 -0 0</acceleration>
          <wrench>0 0 0 0 -0 0</wrench>
        </link>
      </model>
      <model name='shell_robot_model'>
        <pose frame=''>0 0 0 0 -0 0</pose>
        <scale>1 1 1</scale>
        <link name='L_U_1_1'>
          <pose frame=''>0.040001 0.069282 0.23 0 -0 1.04719</pose>
          <velocity>0 0 0 0 -0 0</velocity>
          <acceleration>0 0 0 0 -0 0</acceleration>
          <wrench>0 0 0 0 -0 0</wrench>
        </link>
        <link name='L_U_1_2'>
          <pose frame=''>0.070001 0.121243 0.23 3.14159 -1.57079 -2.0944</pose>
          <velocity>0 0 0 0 -0 0</velocity>
          <acceleration>0 0 0 0 -0 0</acceleration>
          <wrench>0 0 0 0 -0 0</wrench>
        </link>
        <link name='L_U_2_1'>
          <pose frame=''>-0.039999 0.069283 0.23 0 -0 2.09438</pose>
          <velocity>0 0 0 0 -0 0</velocity>
          <acceleration>0 0 0 0 -0 0</acceleration>
          <wrench>0 0 0 0 -0 0</wrench>
        </link>
        <link name='L_U_2_2'>
          <pose frame=''>-0.069998 0.121245 0.23 -3.14159 -1.57079 -1.04721</pose>
          <velocity>0 0 0 0 -0 0</velocity>
          <acceleration>0 0 0 -0 -0 -0</acceleration>
          <wrench>0 0 0 0 -0 0</wrench>
        </link>
        <link name='L_U_3_1'>
          <pose frame=''>-0.08 2e-06 0.23 0 -0 3.14157</pose>
          <velocity>0 0 0 0 -0 0</velocity>
          <acceleration>0 0 0 0 -0 0</acceleration>
          <wrench>0 0 0 0 -0 0</wrench>
        </link>
        <link name='L_U_3_2'>
          <pose frame=''>-0.14 3e-06 0.23 3.14159 -1.57079 -2.3e-05</pose>
          <velocity>0 0 0 0 -0 0</velocity>
          <acceleration>0 0 0 0 -0 0</acceleration>
          <wrench>0 0 0 0 -0 0</wrench>
        </link>
        <link name='L_U_4_1'>
          <pose frame=''>-0.040002 -0.069281 0.23 0 0 -2.09443</pose>
          <velocity>0 0 0 0 -0 0</velocity>
          <acceleration>0 0 0 0 -0 0</acceleration>
          <wrench>0 0 0 0 -0 0</wrench>
        </link>
        <link name='L_U_4_2'>
          <pose frame=''>-0.070004 -0.121241 0.23 0 -1.57079 -2.09443</pose>
          <velocity>0 0 0 0 -0 0</velocity>
          <acceleration>0 0 0 0 -0 0</acceleration>
          <wrench>0 0 0 0 -0 0</wrench>
        </link>
        <link name='L_U_5_1'>
          <pose frame=''>0.039997 -0.069284 0.23 0 0 -1.04724</pose>
          <velocity>0 0 0 0 -0 0</velocity>
          <acceleration>0 0 0 -0 -0 -0</acceleration>
          <wrench>0 0 0 0 -0 0</wrench>
        </link>
        <link name='L_U_5_2'>
          <pose frame=''>0.069995 -0.121246 0.23 0 -1.57079 -1.04724</pose>
          <velocity>0 0 0 0 -0 0</velocity>
          <acceleration>0 0 0 0 -0 0</acceleration>
          <wrench>0 0 0 0 -0 0</wrench>
        </link>
        <link name='L_U_6_1'>
          <pose frame=''>0.08 -4e-06 0.23 0 0 -4.5e-05</pose>
          <velocity>0 0 0 0 -0 0</velocity>
          <acceleration>0 0 0 0 -0 0</acceleration>
          <wrench>0 0 0 0 -0 0</wrench>
        </link>
        <link name='L_U_6_2'>
          <pose frame=''>0.14 -6e-06 0.23 3.14159 -1.57079 3.14155</pose>
          <velocity>0 0 0 0 -0 0</velocity>
          <acceleration>0 0 0 0 -0 0</acceleration>
          <wrench>0 0 0 0 -0 0</wrench>
        </link>
        <link name='leg_B_1_2'>
          <pose frame=''>0.0275 0.047631 0.11 0 -0 1.04719</pose>
          <velocity>0 0 0 0 -0 0</velocity>
          <acceleration>0 0 0 0 -0 0</acceleration>
          <wrench>0 0 0 0 -0 0</wrench>
        </link>
        <link name='leg_B_1_3'>
          <pose frame=''>0.067501 0.116913 0.11 0 -0 1.04719</pose>
          <velocity>0 0 0 0 -0 0</velocity>
          <acceleration>0 0 0 0 -0 0</acceleration>
          <wrench>0 0 0 0 -0 0</wrench>
        </link>
        <link name='leg_B_1_4'>
          <pose frame=''>0.097501 0.168874 0.11 3.14159 1.57079 -2.0944</pose>
          <velocity>0 0 0 0 -0 0</velocity>
          <acceleration>0 0 0 0 -0 0</acceleration>
          <wrench>0 0 0 0 -0 0</wrench>
        </link>
        <link name='leg_B_1_5'>
          <pose frame=''>0.097501 0.168874 0.03 1.5708 1.57079 -2.0944</pose>
          <velocity>0 0 0 0 -0 0</velocity>
          <acceleration>0 0 0 0 -0 0</acceleration>
          <wrench>0 0 0 0 -0 0</wrench>
        </link>
        <link name='leg_B_2_2'>
          <pose frame=''>-0.027499 0.047632 0.11 0 -0 2.09438</pose>
          <velocity>0 0 0 0 -0 0</velocity>
          <acceleration>0 0 0 0 -0 0</acceleration>
          <wrench>0 0 0 0 -0 0</wrench>
        </link>
        <link name='leg_B_2_3'>
          <pose frame=''>-0.067498 0.116914 0.11 0 -0 2.09438</pose>
          <velocity>0 0 0 0 -0 0</velocity>
          <acceleration>0 0 0 0 -0 0</acceleration>
          <wrench>0 0 0 0 -0 0</wrench>
        </link>
        <link name='leg_B_2_4'>
          <pose frame=''>-0.097497 0.168876 0.11 3.14159 1.57079 -1.04721</pose>
          <velocity>0 0 0 0 -0 0</velocity>
          <acceleration>0 0 0 -0 -0 -0</acceleration>
          <wrench>0 0 0 0 -0 0</wrench>
        </link>
        <link name='leg_B_2_5'>
          <pose frame=''>-0.097498 0.168877 0.03 1.57079 1.57079 -1.04721</pose>
          <velocity>0 0 0 0 -0 0</velocity>
          <acceleration>0 0 0 0 -0 0</acceleration>
          <wrench>0 0 0 0 -0 0</wrench>
        </link>
        <link name='leg_B_3_2'>
          <pose frame=''>-0.055 1e-06 0.11 0 -0 3.14157</pose>
          <velocity>0 0 0 0 -0 0</velocity>
          <acceleration>0 0 0 0 -0 0</acceleration>
          <wrench>0 0 0 0 -0 0</wrench>
        </link>
        <link name='leg_B_3_3'>
          <pose frame=''>-0.135 3e-06 0.11 0 -0 3.14157</pose>
          <velocity>0 0 0 0 -0 0</velocity>
          <acceleration>0 0 0 0 -0 0</acceleration>
          <wrench>0 0 0 0 -0 0</wrench>
        </link>
        <link name='leg_B_3_4'>
          <pose frame=''>-0.195 4e-06 0.11 -3.14159 1.57079 -2.3e-05</pose>
          <velocity>0 0 0 0 -0 0</velocity>
          <acceleration>0 0 0 0 -0 0</acceleration>
          <wrench>0 0 0 0 -0 0</wrench>
        </link>
        <link name='leg_B_3_5'>
          <pose frame=''>-0.195 4e-06 0.03 1.57079 1.57079 -2.3e-05</pose>
          <velocity>0 0 0 0 -0 0</velocity>
          <acceleration>0 0 0 0 -0 0</acceleration>
          <wrench>0 0 0 0 -0 0</wrench>
        </link>
        <link name='leg_B_4_2'>
          <pose frame=''>-0.027501 -0.047631 0.11 0 0 -2.09443</pose>
          <velocity>0 0 0 0 -0 0</velocity>
          <acceleration>0 0 0 0 -0 0</acceleration>
          <wrench>0 0 0 0 -0 0</wrench>
        </link>
        <link name='leg_B_4_3'>
          <pose frame=''>-0.067504 -0.116911 0.11 0 0 -2.09443</pose>
          <velocity>0 0 0 0 -0 0</velocity>
          <acceleration>0 0 0 0 -0 0</acceleration>
          <wrench>0 0 0 0 -0 0</wrench>
        </link>
        <link name='leg_B_4_4'>
          <pose frame=''>-0.097505 -0.168872 0.11 0 1.57079 -2.09443</pose>
          <velocity>0 0 0 0 -0 0</velocity>
          <acceleration>0 0 0 0 -0 0</acceleration>
          <wrench>0 0 0 0 -0 0</wrench>
        </link>
        <link name='leg_B_4_5'>
          <pose frame=''>-0.097505 -0.168872 0.03 1.5708 1.57079 1.04716</pose>
          <velocity>0 0 0 0 -0 0</velocity>
          <acceleration>0 0 0 -0 -0 -0</acceleration>
          <wrench>0 0 0 0 -0 0</wrench>
        </link>
        <link name='leg_B_5_2'>
          <pose frame=''>0.027498 -0.047632 0.11 0 0 -1.04724</pose>
          <velocity>0 0 0 0 -0 0</velocity>
          <acceleration>0 0 0 -0 -0 -0</acceleration>
          <wrench>0 0 0 0 -0 0</wrench>
        </link>
        <link name='leg_B_5_3'>
          <pose frame=''>0.067496 -0.116916 0.11 0 0 -1.04724</pose>
          <velocity>0 0 0 0 -0 0</velocity>
          <acceleration>0 0 0 -0 -0 -0</acceleration>
          <wrench>0 0 0 0 -0 0</wrench>
        </link>
        <link name='leg_B_5_4'>
          <pose frame=''>0.097494 -0.168879 0.11 0 1.57079 -1.04724</pose>
          <velocity>0 0 0 0 -0 0</velocity>
          <acceleration>0 0 0 0 -0 0</acceleration>
          <wrench>0 0 0 0 -0 0</wrench>
        </link>
        <link name='leg_B_5_5'>
          <pose frame=''>0.097494 -0.168879 0.03 -1.57079 1.57079 -1.04724</pose>
          <velocity>0 0 0 0 -0 0</velocity>
          <acceleration>0 0 0 0 -0 0</acceleration>
          <wrench>0 0 0 0 -0 0</wrench>
        </link>
        <link name='leg_B_6_2'>
          <pose frame=''>0.055 -2e-06 0.11 0 0 -4.5e-05</pose>
          <velocity>0 0 0 0 -0 0</velocity>
          <acceleration>0 0 0 0 -0 0</acceleration>
          <wrench>0 0 0 0 -0 0</wrench>
        </link>
        <link name='leg_B_6_3'>
          <pose frame=''>0.135 -6e-06 0.11 0 0 -4.5e-05</pose>
          <velocity>0 0 0 0 -0 0</velocity>
          <acceleration>0 0 0 0 -0 0</acceleration>
          <wrench>0 0 0 0 -0 0</wrench>
        </link>
        <link name='leg_B_6_4'>
          <pose frame=''>0.195 -9e-06 0.11 -3.14159 1.57079 3.14155</pose>
          <velocity>0 0 0 0 -0 0</velocity>
          <acceleration>0 0 0 0 -0 0</acceleration>
          <wrench>0 0 0 0 -0 0</wrench>
        </link>
        <link name='leg_B_6_5'>
          <pose frame=''>0.195 -9e-06 0.03 1.57079 1.57079 3.14155</pose>
          <velocity>0 0 0 0 -0 0</velocity>
          <acceleration>0 0 0 0 -0 0</acceleration>
          <wrench>0 0 0 0 -0 0</wrench>
        </link>
        <link name='map'>
          <pose frame=''>0 0 0 0 -0 0</pose>
          <velocity>0 0 0 0 -0 0</velocity>
          <acceleration>0 0 0 0 -0 0</acceleration>
          <wrench>0 0 0 0 -0 0</wrench>
        </link>
        <link name='support_c'>
          <pose frame=''>0 0 0.14 0 -0 0</pose>
          <velocity>0 0 0 0 -0 0</velocity>
          <acceleration>0 0 0 0 -0 0</acceleration>
          <wrench>0 0 0 0 -0 0</wrench>
        </link>
      </model>
      <light name='sun'>
        <pose frame=''>0 0 10 0 -0 0</pose>
      </light>
    </state>
    <gui fullscreen='0'>
      <camera name='user_camera'>
        <pose frame=''>5 -5 2 0 0.275643 2.35619</pose>
        <view_controller>orbit</view_controller>
        <projection_type>perspective</projection_type>
      </camera>
    </gui>
  </world>
</sdf>
